File: Data_Alu 6082 für NiGü/6082Alu_Zugprüfung.is_tens_RawData.csv/Specimen_RawData_1.csv
Prüflosbezeichnung;"Redux 312_quer+längs_alte Proben"
Proben-Nr;"1"
Prüfer;"JuBr"
Werkstoff;"6082"
Prüfnorm;"DIN EN ISO 527"
Prüfgeschwindigkeit;3,6;mm/min
Prüfklima;"23 °C / 50 % rF"
Bemerkungen;""

Zeit;Traversenweg;Last;Dehnung 1;Zugdehnung;Zugspannung;Axiale Dehnung (Video);Zugverformung;Transversale Dehnung (Video);Transversale Verformung 1
(sec);(mm);(N);(%);(mm/mm);(MPa);(%);(mm);(%);(mm)
0,00000;0,00000;245,84186;0,09209;-0,00003;3,07687;-0,00316;-0,00091;0,00273;-0,00029
0,26000;0,01548;518,03933;0,09222;0,00007;6,48360;0,00680;0,00195;-0,00780;0,00082
0,53200;0,03171;823,59435;0,09267;0,00011;10,30781;0,01121;0,00322;-0,02675;0,00280
0,83200;0,05004;1127,17520;0,09271;0,00022;14,10732;0,02244;0,00645;-0,04144;0,00433
1,14800;0,06889;1430,86921;0,09313;0,00028;17,90825;0,02815;0,00809;-0,02610;0,00273
1,47600;0,08850;1735,42991;0,09215;0,00031;21,72002;0,03149;0,00905;-0,02070;0,00216
1,82200;0,10929;2039,60091;0,09177;0,00043;25,52692;0,04251;0,01222;-0,02042;0,00214
2,18200;0,13104;2342,90175;0,09221;0,00048;29,32293;0,04802;0,01380;-0,02185;0,00228
2,55400;0,15321;2646,03026;0,09241;0,00063;33,11677;0,06257;0,01798;-0,02569;0,00269
2,95000;0,17684;2947,72312;0,09268;0,00064;36,89265;0,06382;0,01834;-0,03681;0,00385
3,34800;0,20089;3242,56897;0,09282;0,00061;40,58284;0,06086;0,01749;-0,03276;0,00343
3,74800;0,22484;3532,27481;0,09266;0,00073;44,20870;0,07262;0,02087;-0,05713;0,00597
4,14800;0,24879;3811,74266;0,09285;0,00081;47,70642;0,08064;0,02317;-0,07750;0,00810
4,54800;0,27295;4092,23780;0,09293;0,00083;51,21699;0,08257;0,02373;-0,08348;0,00873
4,94800;0,29673;4368,53841;0,09275;0,00086;54,67507;0,08557;0,02459;-0,07578;0,00792
5,34800;0,32079;4637,24568;0,09292;0,00096;58,03812;0,09573;0,02751;-0,03727;0,00390
5,74800;0,34495;4908,44831;0,09309;0,00120;61,43239;0,12024;0,03456;0,00666;-0,00070
6,14800;0,36873;5174,44611;0,09268;0,00127;64,76153;0,12664;0,03640;0,00492;-0,00051
6,54800;0,39284;5433,31414;0,09265;0,00136;68,00143;0,13638;0,03920;-0,00255;0,00027
6,94800;0,41700;5695,07718;0,09299;0,00145;71,27756;0,14530;0,04176;-0,00824;0,00086
7,34800;0,44068;5949,68274;0,09285;0,00151;74,46411;0,15052;0,04326;-0,01236;0,00129
7,74800;0,46484;6201,32670;0,09302;0,00146;77,61360;0,14611;0,04199;-0,05256;0,00550
8,14800;0,48900;6453,19104;0,09297;0,00155;80,76585;0,15512;0,04458;-0,04515;0,00472
8,54800;0,51268;6696,15895;0,09281;0,00161;83,80675;0,16148;0,04641;-0,03615;0,00378
8,94800;0,53684;6939,17960;0,09272;0,00168;86,84831;0,16760;0,04817;-0,04635;0,00485
9,34800;0,56095;7182,30218;0,09271;0,00170;89,89114;0,17022;0,04892;-0,03054;0,00319
9,74800;0,58473;7415,16307;0,09322;0,00164;92,80555;0,16398;0,04713;-0,03876;0,00405
10,14800;0,60884;7651,81035;0,09326;0,00162;95,76734;0,16179;0,04650;-0,03359;0,00351
10,54800;0,63289;7884,82994;0,09225;0,00160;98,68373;0,15993;0,04596;-0,03580;0,00374
10,94800;0,65684;8109,97546;0,09266;0,00168;101,50157;0,16821;0,04834;-0,04263;0,00446
11,34800;0,68084;8337,71735;0,09261;0,00186;104,35191;0,18567;0,05336;-0,02616;0,00274
11,74800;0,70479;8562,28262;0,09262;0,00186;107,16249;0,18648;0,05359;0,02126;-0,00222
12,14800;0,72884;8778,09763;0,09287;0,00197;109,86355;0,19699;0,05661;0,01236;-0,00129
12,54800;0,75295;8997,77323;0,09257;0,00205;112,61293;0,20462;0,05881;0,01420;-0,00148
12,94800;0,77673;9209,10090;0,09230;0,00211;115,25783;0,21061;0,06053;0,00569;-0,00060
13,34800;0,80084;9412,82719;0,09234;0,00215;117,80760;0,21476;0,06172;0,00382;-0,00040
13,74800;0,82495;9619,26699;0,09296;0,00220;120,39133;0,22049;0,06337;-0,01757;0,00184
14,14800;0,84868;9818,02136;0,09261;0,00224;122,87887;0,22363;0,06427;-0,02408;0,00252
14,54800;0,87284;10017,56877;0,09230;0,00222;125,37633;0,22250;0,06395;-0,02311;0,00242
14,94800;0,89700;10219,50245;0,09250;0,00225;127,90366;0,22524;0,06473;-0,02336;0,00244
15,34800;0,92068;10419,81608;0,09248;0,00221;130,41071;0,22055;0,06338;-0,01710;0,00179
15,74800;0,94484;10621,80519;0,09306;0,00221;132,93874;0,22116;0,06356;-0,02315;0,00242
16,14800;0,96900;10828,51768;0,09270;0,00216;135,52588;0,21630;0,06217;-0,03422;0,00358
16,54800;0,99268;11026,50851;0,09238;0,00215;138,00386;0,21506;0,06181;-0,04050;0,00423
16,94800;1,01684;11230,35192;0,09250;0,00221;140,55509;0,22129;0,06360;-0,06363;0,00665
17,34800;1,04089;11436,51098;0,09264;0,00228;143,13531;0,22769;0,06544;-0,03762;0,00393
17,74800;1,06479;11639,65255;0,09285;0,00229;145,67775;0,22941;0,06593;0,01539;-0,00161
18,14800;1,08889;11862,87671;0,09279;0,00230;148,47155;0,23003;0,06611;0,01989;-0,00208
18,54800;1,11284;12092,45771;0,09247;0,00238;151,34490;0,23823;0,06847;0,00778;-0,00081
18,94800;1,13684;12318,58581;0,09283;0,00247;154,17504;0,24673;0,07091;0,02037;-0,00213
19,34800;1,16089;12551,43374;0,09266;0,00256;157,08928;0,25612;0,07361;0,01769;-0,00185
19,74800;1,18473;12783,59771;0,09242;0,00260;159,99497;0,25961;0,07461;0,02416;-0,00253
20,14800;1,20878;13009,50944;0,09233;0,00275;162,82240;0,27524;0,07910;0,00894;-0,00093
20,54800;1,23295;13245,58496;0,09253;0,00285;165,77703;0,28457;0,08179;0,01534;-0,00160
20,94800;1,25673;13477,86695;0,09279;0,00287;168,68419;0,28714;0,08252;0,00931;-0,00097
21,34800;1,28089;13707,23963;0,09268;0,00293;171,55494;0,29291;0,08418;0,01169;-0,00122
21,74800;1,30495;13944,29415;0,09278;0,00302;174,52183;0,30208;0,08682;0,01450;-0,00152
22,14800;1,32862;14177,22166;0,09306;0,00303;177,43707;0,30342;0,08720;0,02298;-0,00240
22,54800;1,35289;14413,99634;0,09286;0,00305;180,40045;0,30535;0,08776;0,01107;-0,00116
22,94800;1,37695;14649,12057;0,09242;0,00306;183,34319;0,30607;0,08796;0,01525;-0,00159
23,34800;1,40073;14884,65607;0,09242;0,00308;186,29106;0,30760;0,08840;0,01570;-0,00164
23,74800;1,42489;15121,10353;0,09322;0,00303;189,25036;0,30279;0,08702;0,01710;-0,00179
24,14800;1,44895;15358,64532;0,09246;0,00310;192,22335;0,30990;0,08907;0,01829;-0,00191
24,54800;1,47273;15589,03635;0,09239;0,00316;195,10684;0,31597;0,09081;0,06263;-0,00655
24,94800;1,49689;15828,12309;0,09285;0,00318;198,09916;0,31791;0,09137;0,05512;-0,00576
25,34800;1,52078;16067,18123;0,09338;0,00321;201,09113;0,32124;0,09232;0,05174;-0,00541
25,74800;1,54478;16302,87230;0,09257;0,00323;204,04095;0,32297;0,09282;0,05013;-0,00524
26,14800;1,56889;16546,12899;0,09277;0,00325;207,08547;0,32457;0,09328;0,05430;-0,00568
26,54800;1,59278;16787,03070;0,09261;0,00327;210,10051;0,32682;0,09393;0,05127;-0,00536
26,94800;1,61684;17024,15764;0,09282;0,00332;213,06831;0,33179;0,09536;0,02146;-0,00224
27,34800;1,64095;17269,23108;0,09238;0,00339;216,13556;0,33949;0,09757;0,01972;-0,00206
27,74800;1,66473;17511,58655;0,09290;0,00343;219,16879;0,34268;0,09848;0,00945;-0,00099
28,14800;1,68884;17751,20795;0,09257;0,00355;222,16781;0,35459;0,10191;0,01335;-0,00140
28,54800;1,71289;17996,22416;0,09221;0,00359;225,23434;0,35920;0,10323;0,01767;-0,00185
28,94800;1,73668;18239,99226;0,09279;0,00366;228,28526;0,36582;0,10513;0,02560;-0,00268
29,34800;1,76095;18485,28206;0,09299;0,00367;231,35522;0,36749;0,10562;0,02419;-0,00253
29,74800;1,78495;18730,58081;0,09219;0,00366;234,42529;0,36594;0,10517;0,02148;-0,00225
30,14800;1,80873;18972,96131;0,09200;0,00361;237,45884;0,36135;0,10385;0,00675;-0,00071
30,54800;1,83289;19215,89077;0,09268;0,00357;240,49926;0,35715;0,10264;0,00807;-0,00084
30,94800;1,85695;19462,46445;0,09254;0,00361;243,58529;0,36114;0,10379;0,01523;-0,00159
31,34800;1,88073;19700,73044;0,09241;0,00366;246,56734;0,36555;0,10506;0,02224;-0,00233
31,74800;1,90489;19944,41271;0,09292;0,00368;249,61718;0,36849;0,10590;0,07004;-0,00732
32,14800;1,92884;20186,19955;0,09300;0,00383;252,64330;0,38285;0,11003;0,07204;-0,00753
32,54800;1,95278;20420,46547;0,09229;0,00403;255,57529;0,40259;0,11570;0,06599;-0,00690
32,94800;1,97695;20659,47890;0,09286;0,00416;258,56669;0,41565;0,11946;0,06448;-0,00674
33,34800;2,00078;20889,83774;0,09274;0,00417;261,44978;0,41676;0,11978;0,07196;-0,00753
33,74800;2,02478;21114,61580;0,09255;0,00426;264,26303;0,42558;0,12231;0,06860;-0,00717
34,14800;2,04895;21339,25438;0,09243;0,00430;267,07452;0,42967;0,12349;0,03522;-0,00368
34,54800;2,07273;21555,58884;0,09281;0,00439;269,78209;0,43900;0,12617;0,04338;-0,00454
34,94800;2,09678;21759,51362;0,09231;0,00449;272,33434;0,44886;0,12900;0,03714;-0,00388
35,34800;2,12100;21964,52379;0,09280;0,00457;274,90017;0,45721;0,13140;0,04668;-0,00488
35,74800;2,14468;22154,45995;0,09250;0,00467;277,27735;0,46658;0,13409;0,06086;-0,00636
36,14800;2,16884;22335,71470;0,09277;0,00478;279,54587;0,47785;0,13733;0,06224;-0,00651
36,54800;2,19300;22513,01229;0,09247;0,00492;281,76486;0,49217;0,14145;0,06392;-0,00668
36,94800;2,21673;22672,60373;0,09226;0,00506;283,76225;0,50632;0,14551;0,04656;-0,00487
37,34800;2,24089;22828,87816;0,09238;0,00521;285,71812;0,52066;0,14964;0,04161;-0,00435
37,74800;2,26494;22975,88468;0,09264;0,00532;287,55801;0,53162;0,15279;0,05163;-0,00540
38,14800;2,28878;23106,20427;0,09283;0,00548;289,18904;0,54761;0,15738;0,05416;-0,00566
38,54800;2,31284;23231,81033;0,09209;0,00563;290,76108;0,56280;0,16175;0,11977;-0,01252
38,94800;2,33689;23350,68047;0,09212;0,00577;292,24882;0,57718;0,16588;0,12639;-0,01322
39,34800;2,36084;23451,09880;0,09281;0,00595;293,50562;0,59469;0,17091;0,11491;-0,01202
39,74800;2,38484;23551,15771;0,09285;0,00620;294,75792;0,62029;0,17827;0,13574;-0,01419
40,14800;2,40878;23641,93976;0,09269;0,00639;295,89411;0,63881;0,18359;0,13033;-0,01363
40,54800;2,43289;23718,10377;0,09258;0,00659;296,84736;0,65890;0,18937;0,12778;-0,01336
40,94800;2,45694;23795,16184;0,09261;0,00688;297,81179;0,68781;0,19767;0,11716;-0,01225
41,34800;2,48073;23862,58900;0,09193;0,00714;298,65568;0,71426;0,20528;0,12051;-0,01260
41,74800;2,50484;23922,18947;0,09234;0,00747;299,40162;0,74745;0,21482;0,13973;-0,01461
42,14800;2,52905;23980,81720;0,09254;0,00779;300,13538;0,77950;0,22403;0,13833;-0,01447
42,54800;2,55268;24032,54449;0,09230;0,00812;300,78278;0,81204;0,23338;0,13986;-0,01463
42,94800;2,57689;24079,34725;0,09274;0,00842;301,36855;0,84224;0,24206;0,14920;-0,01560
43,34800;2,60100;24124,72665;0,09204;0,00872;301,93650;0,87212;0,25064;0,14462;-0,01512
43,74800;2,62462;24161,40318;0,09225;0,00904;302,39553;0,90395;0,25979;0,15947;-0,01668
44,14800;2,64884;24200,98007;0,09233;0,00932;302,89086;0,93242;0,26797;0,17490;-0,01829
44,54800;2,67300;24238,19125;0,09215;0,00970;303,35659;0,96952;0,27864;0,16651;-0,01741
44,94800;2,69668;24266,15596;0,09243;0,01005;303,70658;1,00468;0,28874;0,16940;-0,01771
45,34800;2,72084;24297,29462;0,09215;0,01032;304,09630;1,03245;0,29672;0,17253;-0,01804
45,74800;2,74500;24329,80835;0,09241;0,01066;304,50323;1,06573;0,30629;0,18096;-0,01892
46,14800;2,76878;24350,21639;0,09252;0,01102;304,75865;1,10150;0,31657;0,23544;-0,02462
46,54800;2,79284;24379,69565;0,09180;0,01136;305,12761;1,13552;0,32634;0,25765;-0,02694
46,94800;2,81678;24403,87845;0,09191;0,01163;305,43027;1,16340;0,33436;0,25179;-0,02633
47,34800;2,84089;24421,52202;0,09253;0,01200;305,65109;1,19984;0,34483;0,25983;-0,02717
47,74800;2,86489;24446,94400;0,09228;0,01232;305,96926;1,23240;0,35419;0,23637;-0,02472
48,14800;2,88873;24467,55052;0,09243;0,01266;306,22717;1,26616;0,36389;0,25370;-0,02653
48,54800;2,91289;24483,63304;0,09213;0,01297;306,42845;1,29653;0,37262;0,25479;-0,02664
48,94800;2,93700;24505,21052;0,09223;0,01337;306,69850;1,33672;0,38417;0,26369;-0,02757
49,34800;2,96073;24523,71061;0,09265;0,01375;306,93005;1,37489;0,39514;0,27396;-0,02865
49,74800;2,98489;24537,91916;0,09220;0,01406;307,10787;1,40580;0,40402;0,27139;-0,02838
50,14800;3,00900;24558,47204;0,09256;0,01443;307,36511;1,44344;0,41484;0,27880;-0,02915
50,54800;3,03268;24572,72172;0,09196;0,01477;307,54345;1,47740;0,42460;0,29249;-0,03059
50,94800;3,05694;24589,19406;0,09190;0,01506;307,74961;1,50571;0,43274;0,29334;-0,03068
51,34800;3,08094;24604,77054;0,09213;0,01543;307,94456;1,54323;0,44352;0,29966;-0,03134
51,74800;3,10468;24618,12079;0,09231;0,01574;308,11165;1,57352;0,45223;0,30189;-0,03157
52,14800;3,12889;24634,69684;0,09221;0,01604;308,31911;1,60362;0,46088;0,30211;-0,03159
52,54800;3,15294;24650,60949;0,09223;0,01644;308,51827;1,64427;0,47256;0,31777;-0,03323
52,94800;3,17668;24661,04329;0,09252;0,01675;308,64885;1,67497;0,48138;0,33026;-0,03454
53,34800;3,20089;24678,58672;0,09236;0,01709;308,86842;1,70928;0,49124;0,38458;-0,04022
53,74800;3,22484;24693,71080;0,09232;0,01743;309,05771;1,74271;0,50085;0,39161;-0,04095
54,14800;3,24884;24703,65822;0,09224;0,01778;309,18221;1,77776;0,51092;0,40093;-0,04193
54,54800;3,27294;24721,41087;0,09235;0,01822;309,40439;1,82230;0,52372;0,40910;-0,04278
54,94800;3,29678;24733,84380;0,09227;0,01852;309,56000;1,85174;0,53218;0,38005;-0,03974
55,34800;3,32089;24744,53330;0,09238;0,01894;309,69378;1,89357;0,54421;0,39891;-0,04171
55,74800;3,34494;24760,72490;0,09201;0,01929;309,89643;1,92931;0,55448;0,39837;-0,04166
56,14800;3,36884;24773,95356;0,09240;0,01967;310,06200;1,96680;0,56525;0,40259;-0,04210
56,54800;3,39278;24782,25589;0,09236;0,02003;310,16591;2,00346;0,57579;0,41498;-0,04340
56,94800;3,41700;24799,37375;0,09206;0,02038;310,38015;2,03770;0,58563;0,42252;-0,04418
57,34800;3,44073;24812,80088;0,09255;0,02074;310,54820;2,07399;0,59606;0,43756;-0,04576
57,74800;3,46489;24823,92132;0,09211;0,02108;310,68738;2,10785;0,60579;0,44542;-0,04658
58,14800;3,48894;24839,59258;0,09205;0,02139;310,88351;2,13855;0,61461;0,45159;-0,04722
58,54800;3,51273;24848,57261;0,09222;0,02170;310,99590;2,16955;0,62352;0,44577;-0,04662
58,94800;3,53689;24863,31046;0,09255;0,02206;311,18036;2,20612;0,63403;0,45471;-0,04755
59,34800;3,56094;24877,68173;0,09233;0,02239;311,36022;2,23919;0,64354;0,45214;-0,04728
59,74800;3,58478;24887,23576;0,09221;0,02272;311,47980;2,27198;0,65296;0,46908;-0,04905
60,14800;3,60889;24900,91145;0,09229;0,02309;311,65096;2,30857;0,66348;0,49258;-0,05151
60,54800;3,63289;24915,75658;0,09214;0,02346;311,83675;2,34588;0,67420;0,52709;-0,05512
60,94800;3,65684;24925,30167;0,09226;0,02379;311,95622;2,37900;0,68372;0,54067;-0,05654
61,34800;3,68089;24939,49771;0,09205;0,02417;312,13389;2,41657;0,69452;0,55015;-0,05753
61,74800;3,70478;24952,80325;0,09241;0,02450;312,30042;2,45024;0,70419;0,53267;-0,05570
62,14800;3,72884;24961,38990;0,09245;0,02484;312,40788;2,48374;0,71382;0,53575;-0,05602
62,54800;3,75294;24971,58587;0,09242;0,02522;312,53549;2,52162;0,72471;0,52817;-0,05523
62,94800;3,77673;24989,24017;0,09216;0,02550;312,75645;2,55014;0,73290;0,55024;-0,05754
63,34800;3,80078;24999,69006;0,09274;0,02587;312,88723;2,58671;0,74341;0,55871;-0,05843
63,74800;3,82500;25014,33671;0,09265;0,02617;313,07055;2,61744;0,75224;0,57344;-0,05997
64,14800;3,84873;25026,11876;0,09249;0,02652;313,21801;2,65178;0,76211;0,57805;-0,06045
64,54800;3,87289;25037,14442;0,09259;0,02686;313,35600;2,68623;0,77201;0,57835;-0,06048
64,94800;3,89705;25053,04635;0,09256;0,02718;313,55502;2,71832;0,78124;0,58175;-0,06083
65,34800;3,92068;25061,26463;0,09224;0,02756;313,65788;2,75573;0,79199;0,59253;-0,06196
65,74800;3,94489;25075,11020;0,09236;0,02785;313,83117;2,78486;0,80036;0,59602;-0,06233
66,14800;3,96894;25090,16454;0,09278;0,02817;314,01958;2,81710;0,80963;0,60583;-0,06335
66,54800;3,99278;25098,14858;0,09240;0,02851;314,11951;2,85079;0,81931;0,61002;-0,06379
66,94800;4,01684;25111,36293;0,09244;0,02884;314,28489;2,88385;0,82881;0,62976;-0,06585
67,34800;4,04094;25125,77176;0,09261;0,02915;314,46523;2,91463;0,83766;0,67537;-0,07062
67,74800;4,06484;25133,16929;0,09261;0,02946;314,55781;2,94556;0,84654;0,69219;-0,07238
68,14800;4,08894;25148,79405;0,09256;0,02979;314,75337;2,97949;0,85630;0,69064;-0,07222
68,54800;4,11278;25162,96864;0,09258;0,03010;314,93077;3,00999;0,86506;0,68717;-0,07186
68,94800;4,13689;25170,48419;0,09297;0,03044;315,02483;3,04354;0,87470;0,67088;-0,07016
69,34800;4,16089;25185,74953;0,09236;0,03077;315,21589;3,07737;0,88443;0,68099;-0,07121
69,74800;4,18473;25198,04120;0,09259;0,03116;315,36973;3,11632;0,89562;0,68462;-0,07159
70,14800;4,20889;25206,81381;0,09254;0,03148;315,47952;3,14771;0,90464;0,68955;-0,07211
70,54800;4,23294;25220,60037;0,09265;0,03179;315,65207;3,17921;0,91370;0,70460;-0,07368
70,94800;4,25673;25233,73604;0,09293;0,03217;315,81647;3,21653;0,92442;0,70666;-0,07390
71,34800;4,28089;25244,38620;0,09298;0,03249;315,94976;3,24888;0,93372;0,71856;-0,07514
71,74800;4,30505;25258,45349;0,09271;0,03285;316,12583;3,28520;0,94416;0,72215;-0,07552
72,14800;4,32862;25268,00573;0,09275;0,03318;316,24538;3,31791;0,95356;0,73869;-0,07725
72,54800;4,35294;25280,46012;0,09282;0,03350;316,40125;3,34982;0,96273;0,74550;-0,07796
72,94800;4,37700;25293,80679;0,09281;0,03385;316,56830;3,38499;0,97283;0,74868;-0,07829
73,34800;4,40068;25300,43006;0,09283;0,03421;316,65119;3,42127;0,98326;0,74889;-0,07831
73,74800;4,42494;25316,09416;0,09299;0,03455;316,84724;3,45539;0,99307;0,76749;-0,08026
74,14800;4,44894;25328,99737;0,09340;0,03493;317,00873;3,49310;1,00391;0,81643;-0,08538
74,54800;4,47278;25336,47001;0,09260;0,03521;317,10225;3,52083;1,01188;0,81673;-0,08541
74,94800;4,49684;25351,77648;0,09294;0,03556;317,29382;3,55565;1,02188;0,82487;-0,08626
75,34800;4,52084;25364,00735;0,09319;0,03584;317,44690;3,58400;1,03003;0,82798;-0,08658
75,74800;4,54484;25370,48578;0,09336;0,03617;317,52798;3,61732;1,03961;0,81971;-0,08572
76,14800;4,56889;25386,88838;0,09318;0,03651;317,73327;3,65140;1,04940;0,81106;-0,08481
76,54800;4,59278;25397,55642;0,09296;0,03681;317,86679;3,68147;1,05804;0,81499;-0,08522
76,94800;4,61689;25405,08807;0,09308;0,03710;317,96105;3,71015;1,06629;0,81799;-0,08554
77,34800;4,64089;25418,99443;0,09292;0,03743;318,13510;3,74265;1,07563;0,83496;-0,08731
77,74800;4,66478;25430,71568;0,09316;0,03778;318,28180;3,77795;1,08577;0,84406;-0,08826
78,14800;4,68884;25439,73327;0,09296;0,03808;318,39466;3,80763;1,09430;0,85987;-0,08992
78,54800;4,71300;25452,79384;0,09336;0,03838;318,55812;3,83766;1,10293;0,85949;-0,08988
78,94800;4,73662;25461,79712;0,09329;0,03873;318,67080;3,87264;1,11298;0,87252;-0,09124
79,34800;4,76094;25474,60198;0,09351;0,03904;318,83106;3,90389;1,12197;0,88286;-0,09232
79,74800;4,78494;25487,48910;0,09332;0,03936;318,99235;3,93556;1,13107;0,87848;-0,09186
80,14800;4,80868;25495,68951;0,09325;0,03970;319,09499;3,97011;1,14100;0,88754;-0,09281
80,54800;4,83300;25508,24940;0,09351;0,04001;319,25218;4,00066;1,14978;0,90261;-0,09439
80,94800;4,85694;25519,11235;0,09323;0,04035;319,38814;4,03488;1,15961;0,94847;-0,09918
81,34800;4,88078;25528,36776;0,09362;0,04066;319,50398;4,06596;1,16854;0,94813;-0,09915
81,74800;4,90489;25540,22849;0,09318;0,04100;319,65242;4,09966;1,17823;0,95369;-0,09973
82,14800;4,92889;25552,89567;0,09374;0,04137;319,81096;4,13658;1,18884;0,95785;-0,10016
82,54800;4,95278;25558,76076;0,09342;0,04170;319,88436;4,17010;1,19847;0,95979;-0,10037
82,94800;4,97694;25574,42307;0,09361;0,04207;320,08039;4,20709;1,20911;0,93576;-0,09785
83,34800;5,00073;25584,29182;0,09357;0,04243;320,20390;4,24284;1,21938;0,94946;-0,09929
83,74800;5,02484;25591,11714;0,09362;0,04277;320,28933;4,27654;1,22906;0,95919;-0,10030
84,14800;5,04900;25605,27921;0,09342;0,04306;320,46657;4,30642;1,23765;0,96708;-0,10113
84,54800;5,07273;25613,64949;0,09330;0,04339;320,57133;4,33893;1,24700;0,98925;-0,10345
84,94800;5,09684;25622,95139;0,09336;0,04372;320,68775;4,37214;1,25654;0,99417;-0,10396
85,34800;5,12100;25636,73615;0,09279;0,04407;320,86028;4,40654;1,26643;1,00309;-0,10489
85,74800;5,14473;25645,62500;0,09298;0,04435;320,97153;4,43529;1,27469;1,00617;-0,10522
86,14800;5,16884;25654,71768;0,09328;0,04472;321,08533;4,47152;1,28510;1,01836;-0,10649
86,54800;5,19300;25668,85293;0,09287;0,04502;321,26224;4,50211;1,29389;1,01655;-0,10630
86,94800;5,21668;25673,98310;0,09306;0,04538;321,32645;4,53828;1,30429;1,01423;-0,10606
87,34800;5,24094;25685,93144;0,09253;0,04570;321,47599;4,56957;1,31328;1,01864;-0,10652
87,74800;5,26489;25697,44349;0,09312;0,04600;321,62007;4,60047;1,32216;1,07716;-0,11264
88,14800;5,28884;25703,41408;0,09301;0,04635;321,69479;4,63548;1,33222;1,08422;-0,11338
88,54800;5,31284;25713,99450;0,09291;0,04664;321,82722;4,66355;1,34029;1,09039;-0,11402
88,94800;5,33689;25727,08726;0,09263;0,04693;321,99108;4,69296;1,34874;1,08400;-0,11336
89,34800;5,36084;25732,60903;0,09290;0,04725;322,06019;4,72503;1,35796;1,09693;-0,11471
89,74800;5,38489;25745,51046;0,09310;0,04757;322,22166;4,75717;1,36720;1,07651;-0,11257
90,14800;5,40873;25755,21827;0,09221;0,04787;322,34316;4,78674;1,37570;1,07444;-0,11236
90,54800;5,43289;25760,78117;0,09297;0,04818;322,41278;4,81779;1,38462;1,08308;-0,11326
90,94800;5,45700;25774,24407;0,09252;0,04855;322,58128;4,85471;1,39523;1,09485;-0,11449
91,34800;5,48073;25782,80032;0,09208;0,04890;322,68836;4,88998;1,40537;1,10695;-0,11576
91,74800;5,50489;25790,86661;0,09232;0,04921;322,78932;4,92075;1,41421;1,12572;-0,11772
92,14800;5,52900;25800,57979;0,09250;0,04957;322,91089;4,95683;1,42458;1,12748;-0,11790
92,54800;5,55273;25810,40919;0,09224;0,04992;323,03391;4,99163;1,43458;1,13684;-0,11888
92,94800;5,57689;25818,41469;0,09220;0,05025;323,13410;5,02542;1,44429;1,14654;-0,11990
93,34800;5,60105;25829,40102;0,09236;0,05062;323,27160;5,06208;1,45483;1,14589;-0,11983
93,74800;5,62462;25836,01713;0,09275;0,05094;323,35441;5,09376;1,46393;1,13204;-0,11838
94,14800;5,64889;25845,92879;0,09217;0,05128;323,47846;5,12794;1,47375;1,14971;-0,12023
94,54800;5,67300;25856,99022;0,09221;0,05157;323,61690;5,15674;1,48203;1,20572;-0,12608
94,94800;5,69667;25860,87048;0,09260;0,05188;323,66546;5,18850;1,49116;1,20813;-0,12634
95,34800;5,72084;25872,80452;0,09205;0,05224;323,81483;5,22416;1,50141;1,21805;-0,12737
95,74800;5,74500;25883,60667;0,09167;0,05260;323,95002;5,25983;1,51166;1,22201;-0,12779
96,14800;5,76878;25886,97910;0,09226;0,05294;323,99223;5,29427;1,52156;1,22233;-0,12782
96,54800;5,79284;25898,82374;0,09191;0,05328;324,14047;5,32818;1,53130;1,22985;-0,12861
96,94800;5,81684;25908,61917;0,09227;0,05363;324,26307;5,36281;1,54126;1,21173;-0,12671
97,34800;5,84084;25911,69477;0,09185;0,05396;324,30156;5,39596;1,55078;1,21926;-0,12750
97,74800;5,86494;25925,08793;0,09246;0,05430;324,46919;5,42960;1,56045;1,23537;-0,12918
98,14800;5,88878;25933,71570;0,09235;0,05455;324,57717;5,45538;1,56786;1,24744;-0,13045
98,54800;5,91289;25937,89458;0,09196;0,05489;324,62947;5,48880;1,57746;1,25625;-0,13137
98,94800;5,93689;25947,48795;0,09257;0,05521;324,74954;5,52076;1,58665;1,25906;-0,13166
99,34800;5,96073;25956,63965;0,09226;0,05550;324,86408;5,55009;1,59508;1,27656;-0,13349
99,74800;5,98489;25962,70144;0,09203;0,05583;324,93994;5,58270;1,60445;1,28164;-0,13402
100,14800;6,00900;25973,41418;0,09142;0,05618;325,07402;5,61765;1,61450;1,27768;-0,13361
100,54800;6,03262;25980,09288;0,09174;0,05647;325,15761;5,64743;1,62305;1,27686;-0,13352
100,94800;6,05700;25988,73317;0,09206;0,05687;325,26575;5,68741;1,63454;1,28590;-0,13447
101,34800;6,08100;25997,78473;0,09175;0,05724;325,37903;5,72367;1,64497;1,33653;-0,13976
101,74800;6,10462;26000,64576;0,09212;0,05757;325,41484;5,75682;1,65449;1,34984;-0,14116
102,14800;6,12894;26011,58202;0,09177;0,05787;325,55171;5,78714;1,66321;1,35153;-0,14133
102,54800;6,15300;26020,41900;0,09159;0,05819;325,66232;5,81858;1,67224;1,35791;-0,14200
102,94800;6,17673;26023,93806;0,09154;0,05850;325,70636;5,85018;1,68132;1,36650;-0,14290
103,34800;6,20089;26034,42192;0,09162;0,05882;325,83757;5,88211;1,69050;1,37371;-0,14365
103,74800;6,22489;26043,17665;0,09162;0,05916;325,94714;5,91580;1,70018;1,34624;-0,14078
104,14800;6,24878;26045,66574;0,09231;0,05948;325,97829;5,94786;1,70940;1,36708;-0,14296
104,54800;6,27294;26058,41696;0,09150;0,05982;326,13788;5,98200;1,71921;1,37398;-0,14368
104,94800;6,29678;26063,61866;0,09186;0,06019;326,20299;6,01899;1,72984;1,38120;-0,14443
105,34801;6,32084;26066,22934;0,09160;0,06057;326,23566;6,05666;1,74067;1,40089;-0,14649
105,74801;6,34489;26078,35472;0,09132;0,06095;326,38742;6,09452;1,75155;1,39561;-0,14594
106,14801;6,36884;26085,22654;0,09161;0,06130;326,47342;6,12969;1,76165;1,39920;-0,14632
106,54801;6,39284;26087,79609;0,09151;0,06159;326,50558;6,15892;1,77005;1,40331;-0,14675
106,94801;6,41694;26098,33896;0,09163;0,06189;326,63753;6,18878;1,77864;1,41801;-0,14828
107,34801;6,44078;26105,57020;0,09209;0,06214;326,72804;6,21405;1,78590;1,41771;-0,14825
107,74801;6,46489;26110,20505;0,09150;0,06252;326,78605;6,25231;1,79690;1,42207;-0,14871
108,14801;6,48900;26120,46003;0,09153;0,06282;326,91439;6,28195;1,80541;1,48024;-0,15479
108,54801;6,51267;26123,59822;0,09182;0,06316;326,95367;6,31617;1,81525;1,48873;-0,15568
108,94801;6,53694;26131,04761;0,09178;0,06347;327,04690;6,34738;1,82422;1,50505;-0,15739
109,34801;6,56094;26138,37183;0,09189;0,06383;327,13857;6,38324;1,83452;1,50584;-0,15747
109,74801;6,58478;26142,53461;0,09178;0,06420;327,19067;6,41984;1,84504;1,51127;-0,15804
110,14801;6,60883;26150,05016;0,09229;0,06457;327,28473;6,45680;1,85566;1,52125;-0,15908
110,54801;6,63289;26157,43876;0,09226;0,06497;327,37721;6,49695;1,86720;1,51143;-0,15805
110,94801;6,65684;26160,58588;0,09241;0,06529;327,41659;6,52888;1,87638;1,51128;-0,15804
111,34801;6,68089;26168,71119;0,09201;0,06559;327,51829;6,55873;1,88496;1,51203;-0,15812
111,74801;6,70478;26177,09041;0,09220;0,06592;327,62316;6,59206;1,89454;1,52683;-0,15966
112,14801;6,72889;26178,33138;0,09226;0,06625;327,63869;6,62471;1,90392;1,53013;-0,16001
112,54801;6,75300;26188,18402;0,09204;0,06660;327,76200;6,65989;1,91403;1,53824;-0,16086
112,94801;6,77673;26193,02094;0,09211;0,06693;327,82254;6,69259;1,92343;1,56160;-0,16330
113,34801;6,80083;26196,99776;0,09164;0,06726;327,87231;6,72551;1,93289;1,56032;-0,16317
113,74801;6,82494;26204,28085;0,09255;0,06763;327,96346;6,76288;1,94363;1,56942;-0,16412
114,14801;6,84873;26210,64126;0,09221;0,06799;328,04307;6,79926;1,95409;1,56238;-0,16338
114,54801;6,87283;26215,35659;0,09229;0,06837;328,10208;6,83665;1,96483;1,57721;-0,16493
114,94801;6,89705;26223,00088;0,09239;0,06873;328,19776;6,87286;1,97524;1,57781;-0,16499
115,34801;6,92067;26226,00496;0,09199;0,06905;328,23536;6,90490;1,98445;1,63523;-0,17100
115,74801;6,94489;26232,65326;0,09222;0,06937;328,31856;6,93675;1,99360;1,64367;-0,17188
116,14801;6,96894;26240,09907;0,09230;0,06967;328,41175;6,96688;2,00226;1,65908;-0,17349
116,54801;6,99278;26241,34541;0,09237;0,06998;328,42735;6,99768;2,01111;1,66278;-0,17388
116,94801;7,01684;26246,75632;0,09236;0,07032;328,49507;7,03225;2,02105;1,66260;-0,17386
117,34801;7,04094;26255,38766;0,09219;0,07066;328,60310;7,06559;2,03063;1,67595;-0,17526
117,74801;7,06483;26255,88834;0,09243;0,07098;328,60937;7,09804;2,03995;1,65255;-0,17281
118,14801;7,08889;26264,58406;0,09223;0,07128;328,71820;7,12812;2,04860;1,66852;-0,17448
118,54801;7,11278;26271,12865;0,09263;0,07167;328,80011;7,16713;2,05981;1,66126;-0,17372
118,94801;7,13689;26271,44694;0,09262;0,07203;328,80409;7,20268;2,07003;1,66506;-0,17412
119,34801;7,16094;26279,60086;0,09239;0,07237;328,90614;7,23729;2,07997;1,69171;-0,17691
119,74801;7,18473;26285,10654;0,09260;0,07270;328,97505;7,27047;2,08951;1,69893;-0,17766
120,14801;7,20894;26286,79276;0,09276;0,07302;328,99615;7,30214;2,09861;1,70313;-0,17810
120,54801;7,23289;26292,18936;0,09267;0,07337;329,06370;7,33742;2,10875;1,71132;-0,17896
120,94801;7,25673;26298,15817;0,09263;0,07370;329,13840;7,37027;2,11819;1,71258;-0,17909
121,34801;7,28089;26301,50020;0,09270;0,07405;329,18023;7,40513;2,12821;1,71882;-0,17974
121,74801;7,30500;26307,29198;0,09258;0,07444;329,25272;7,44387;2,13935;1,72924;-0,18083
122,14801;7,32862;26310,22990;0,09298;0,07478;329,28949;7,47807;2,14918;1,78332;-0,18649
122,54801;7,35294;26315,83571;0,09252;0,07512;329,35965;7,51207;2,15895;1,79609;-0,18782
122,94801;7,37694;26320,88900;0,09287;0,07555;329,42289;7,55455;2,17115;1,79369;-0,18757
123,34801;7,40067;26321,10357;0,09294;0,07590;329,42558;7,58999;2,18134;1,80265;-0,18851
123,74801;7,42489;26328,84979;0,09289;0,07624;329,52253;7,62380;2,19106;1,81712;-0,19002
124,14801;7,44894;26332,03447;0,09284;0,07663;329,56238;7,66262;2,20221;1,80933;-0,18921
124,54801;7,47278;26334,11050;0,09272;0,07698;329,58837;7,69824;2,21245;1,81649;-0,18995
124,94801;7,49683;26341,08961;0,09278;0,07731;329,67571;7,73133;2,22196;1,78102;-0,18624
125,34801;7,52083;26346,78125;0,09294;0,07769;329,74695;7,76947;2,23292;1,80604;-0,18886
125,74801;7,54483;26345,77453;0,09294;0,07802;329,73435;7,80203;2,24228;1,82773;-0,19113
126,14801;7,56889;26353,78897;0,09290;0,07834;329,83466;7,83438;2,25158;1,83161;-0,19153
126,54801;7,59273;26357,54585;0,09297;0,07868;329,88168;7,86809;2,26127;1,84778;-0,19323
126,94801;7,61689;26357,07378;0,09319;0,07906;329,87577;7,90600;2,27216;1,85450;-0,19393
127,34801;7,64089;26363,81149;0,09335;0,07940;329,96009;7,94018;2,28198;1,85177;-0,19364
127,74801;7,66473;26367,62917;0,09319;0,07973;330,00787;7,97341;2,29153;1,85979;-0,19448
128,14801;7,68889;26369,04180;0,09303;0,08007;330,02555;8,00675;2,30112;1,86513;-0,19504
128,54801;7,71294;26373,67487;0,09281;0,08044;330,08354;8,04388;2,31178;1,87379;-0,19595
128,94801;7,73667;26378,11124;0,09311;0,08072;330,13906;8,07174;2,31979;1,89609;-0,19828
129,34801;7,76094;26380,85067;0,09335;0,08104;330,17335;8,10382;2,32901;1,93486;-0,20233
129,74801;7,78500;26385,81634;0,09318;0,08136;330,23550;8,13552;2,33812;1,95413;-0,20435
130,14801;7,80867;26385,90395;0,09326;0,08172;330,23660;8,17190;2,34858;1,94424;-0,20331
130,54801;7,83300;26391,42573;0,09313;0,08203;330,30570;8,20302;2,35752;1,95259;-0,20419
130,94801;7,85689;26395,25771;0,09337;0,08236;330,35366;8,23594;2,36698;1,95049;-0,20397
131,34801;7,88078;26395,41149;0,09326;0,08275;330,35559;8,27540;2,37833;1,95403;-0,20434
131,74801;7,90483;26399,86575;0,09312;0,08311;330,41134;8,31056;2,38843;1,94771;-0,20368
132,14801;7,92889;26405,38752;0,09331;0,08350;330,48044;8,34999;2,39976;1,95822;-0,20477
132,54801;7,95278;26405,07460;0,09310;0,08387;330,47653;8,38692;2,41038;1,97173;-0,20619
132,94801;7,97694;26412,16636;0,09339;0,08424;330,56529;8,42425;2,42110;1,97716;-0,20676
133,34801;8,00078;26414,36934;0,09292;0,08462;330,59286;8,46229;2,43204;1,99119;-0,20822
133,74801;8,02489;26412,88877;0,09322;0,08498;330,57433;8,49762;2,44219;1,98536;-0,20761
134,14801;8,04905;26420,20404;0,09305;0,08534;330,66588;8,53350;2,45250;1,99389;-0,20851
134,54801;8,07278;26421,15712;0,09323;0,08572;330,67781;8,57237;2,46367;1,99963;-0,20910
134,94801;8,09683;26422,12093;0,09326;0,08607;330,68987;8,60676;2,47356;2,00798;-0,20998
135,34801;8,12094;26426,88990;0,09295;0,08646;330,74956;8,64622;2,48490;2,01427;-0,21064
135,74801;8,14478;26429,28243;0,09346;0,08688;330,77950;8,68814;2,49695;2,03114;-0,21240
136,14801;8,16883;26430,40717;0,09322;0,08722;330,79358;8,72227;2,50675;2,06990;-0,21645
136,54801;8,19299;26437,12342;0,09313;0,08759;330,87764;8,75930;2,51740;2,08229;-0,21775
136,94801;8,21667;26434,34465;0,09327;0,08792;330,84286;8,79205;2,52681;2,08391;-0,21792
137,34801;8,24089;26437,85655;0,09305;0,08830;330,88682;8,83015;2,53776;2,08673;-0,21821
137,74801;8,26489;26443,46774;0,09335;0,08868;330,95704;8,86765;2,54854;2,10410;-0,22003
138,14801;8,28883;26441,16282;0,09335;0,08903;330,92820;8,90284;2,55865;2,11714;-0,22139
138,54801;8,31289;26445,07706;0,09327;0,08941;330,97718;8,94147;2,56975;2,11582;-0,22126
138,94801;8,33683;26447,32118;0,09302;0,08976;331,00527;8,97612;2,57971;2,10598;-0,22023
139,34801;8,36089;26448,63546;0,09294;0,09011;331,02172;9,01089;2,58970;2,11078;-0,22073
139,74801;8,38483;26451,75755;0,09314;0,09044;331,06080;9,04446;2,59935;2,11454;-0,22112
140,14801;8,40878;26455,55556;0,09303;0,09074;331,10833;9,07444;2,60797;2,12210;-0,22191
140,54801;8,43283;26453,12369;0,09315;0,09113;331,07789;9,11346;2,61918;2,13907;-0,22369
140,94801;8,45700;26459,23376;0,09294;0,09146;331,15436;9,14554;2,62840;2,13969;-0,22375
141,34801;8,48067;26460,12425;0,09292;0,09177;331,16551;9,17670;2,63736;2,13999;-0,22378
141,74801;8,50489;26459,65040;0,09292;0,09215;331,15958;9,21502;2,64837;2,14702;-0,22452
142,14801;8,52894;26461,99644;0,09276;0,09242;331,18894;9,24248;2,65626;2,15879;-0,22575
142,54801;8,55273;26464,50520;0,09283;0,09280;331,22034;9,28019;2,66710;2,15972;-0,22585
142,94801;8,57683;26466,01617;0,09309;0,09318;331,23925;9,31755;2,67784;2,17640;-0,22759
143,34801;8,60105;26469,42079;0,09255;0,09356;331,28186;9,35599;2,68888;2,18664;-0,22866
143,74801;8,62462;26468,84859;0,09272;0,09394;331,27470;9,39356;2,69968;2,23434;-0,23365
144,14801;8,64883;26469,82312;0,09291;0,09429;331,28690;9,42869;2,70978;2,24219;-0,23447
144,54801;8,67299;26475,41642;0,09254;0,09468;331,35690;9,46768;2,72098;2,25229;-0,23553
144,94801;8,69673;26471,18390;0,09262;0,09501;331,30393;9,50051;2,73042;2,24932;-0,23522
145,34801;8,72089;26475,00515;0,09230;0,09541;331,35175;9,54097;2,74205;2,25861;-0,23619
145,74801;8,74494;26479,07317;0,09299;0,09583;331,40267;9,58305;2,75414;2,27325;-0,23772
146,14801;8,76883;26475,14641;0,09272;0,09619;331,35352;9,61910;2,76450;2,24628;-0,23490
146,54801;8,79278;26479,67577;0,09280;0,09659;331,41021;9,65911;2,77600;2,25048;-0,23534
146,94801;8,81689;26483,17158;0,09299;0,09697;331,45396;9,69708;2,78691;2,26477;-0,23683
147,34801;8,84083;26477,97346;0,09263;0,09735;331,38890;9,73466;2,79771;2,26556;-0,23691
147,74801;8,86489;26482,67806;0,09239;0,09771;331,44779;9,77081;2,80810;2,27874;-0,23829
148,14801;8,88873;26484,50017;0,09281;0,09810;331,47059;9,81033;2,81946;2,28142;-0,23857
148,54801;8,91289;26481,60517;0,09242;0,09846;331,43436;9,84647;2,82985;2,30094;-0,24061
148,94801;8,93694;26485,14926;0,09229;0,09885;331,47871;9,88485;2,84088;2,31150;-0,24172
149,34801;8,96073;26487,49888;0,09281;0,09925;331,50812;9,92545;2,85254;2,30583;-0,24113
149,74801;8,98494;26486,47428;0,09276;0,09961;331,49530;9,96052;2,86262;2,30943;-0,24150
150,14801;9,00894;26487,00356;0,09302;0,10000;331,50192;10,00049;2,87411;2,32973;-0,24362
150,54801;9,03273;26490,58521;0,09246;0,10037;331,54675;10,03739;2,88471;2,37381;-0,24823
150,94801;9,05694;26489,18688;0,09244;0,10073;331,52925;10,07269;2,89486;2,39282;-0,25022
151,34801;9,08099;26492,05148;0,09260;0,10113;331,56510;10,11334;2,90654;2,39292;-0,25023
151,74801;9,10462;26488,54852;0,09249;0,10148;331,52126;10,14789;2,91647;2,40132;-0,25111
152,14801;9,12894;26492,01393;0,09238;0,10182;331,56463;10,18154;2,92614;2,39829;-0,25079
152,54801;9,15294;26492,59865;0,09272;0,10220;331,57195;10,21980;2,93714;2,41344;-0,25238
152,94801;9,17678;26490,57627;0,09261;0,10256;331,54664;10,25600;2,94754;2,41031;-0,25205
153,34801;9,20078;26492,75422;0,09232;0,10292;331,57390;10,29181;2,95783;2,40308;-0,25130
153,74801;9,22489;26495,44716;0,09216;0,10331;331,60760;10,33098;2,96909;2,40337;-0,25133
154,14801;9,24878;26491,47570;0,09245;0,10366;331,55789;10,36562;2,97905;2,41654;-0,25270
154,54801;9,27289;26495,51868;0,09228;0,10399;331,60849;10,39939;2,98875;2,43286;-0,25441
154,94801;9,29678;26496,75608;0,09268;0,10440;331,62398;10,44021;3,00049;2,43977;-0,25513
155,34801;9,32083;26491,76896;0,09259;0,10476;331,56156;10,47551;3,01063;2,43899;-0,25505
155,74801;9,34494;26496,91880;0,09221;0,10514;331,62602;10,51414;3,02173;2,44528;-0,25571
156,14801;9,36878;26496,12844;0,09230;0,10551;331,61613;10,55130;3,03241;2,45285;-0,25650
156,54801;9,39289;26493,73233;0,09213;0,10586;331,58614;10,58644;3,04251;2,45523;-0,25675
156,94801;9,41694;26495,55802;0,09211;0,10630;331,60899;10,62991;3,05500;2,46171;-0,25743
157,34801;9,44073;26495,79942;0,09252;0,10665;331,61201;10,66533;3,06518;2,47796;-0,25913
157,74801;9,46483;26494,20261;0,09230;0,10704;331,59202;10,70443;3,07642;2,52734;-0,26429
158,14801;9,48899;26497,89691;0,09204;0,10744;331,63826;10,74386;3,08775;2,53665;-0,26526
158,54801;9,51267;26493,29960;0,09250;0,10784;331,58072;10,78438;3,09940;2,53965;-0,26558
158,94801;9,53694;26493,98804;0,09243;0,10819;331,58934;10,81917;3,10940;2,55209;-0,26688
159,34801;9,56089;26496,06943;0,09206;0,10858;331,61539;10,85840;3,12067;2,56022;-0,26773
159,74801;9,58483;26492,83648;0,09233;0,10901;331,57492;10,90122;3,13298;2,56110;-0,26782
160,14801;9,60889;26494,87853;0,09180;0,10941;331,60048;10,94072;3,14433;2,57660;-0,26944
160,54801;9,63289;26496,47534;0,09275;0,10978;331,62047;10,97800;3,15504;2,55850;-0,26755
160,94801;9,65683;26493,00635;0,09236;0,11018;331,57705;11,01826;3,16662;2,55987;-0,26769
161,34801;9,68089;26493,74664;0,09305;0,11063;331,58632;11,06314;3,17951;2,56114;-0,26782
161,74801;9,70483;26495,75830;0,09223;0,11101;331,61149;11,10098;3,19039;2,56672;-0,26841
162,14801;9,72883;26489,92896;0,09206;0,11141;331,53854;11,14147;3,20202;2,57304;-0,26907
162,54801;9,75305;26494,37070;0,09333;0,11180;331,59413;11,17990;3,21307;2,59778;-0,27166
162,94801;9,77667;26491,41848;0,09234;0,11212;331,55718;11,21194;3,22228;2,59944;-0,27183
163,34801;9,80083;26489,66432;0,09220;0,11250;331,53522;11,25001;3,23322;2,59457;-0,27132
163,74801;9,82489;26490,23652;0,09217;0,11288;331,54238;11,28823;3,24420;2,61058;-0,27299
164,14801;9,84873;26489,79485;0,09233;0,11324;331,53686;11,32354;3,25435;2,62073;-0,27405
164,54801;9,87283;26489,10463;0,09218;0,11374;331,52822;11,37440;3,26897;2,66958;-0,27916
164,94801;9,89705;26489,39431;0,09245;0,11409;331,53184;11,40854;3,27878;2,67636;-0,27987
165,34801;9,92073;26486,98390;0,09232;0,11442;331,50168;11,44235;3,28850;2,70067;-0,28241
165,74801;9,94489;26486,26328;0,09298;0,11481;331,49266;11,48140;3,29972;2,69196;-0,28150
166,14801;9,96899;26489,54988;0,09244;0,11521;331,53379;11,52061;3,31099;2,71032;-0,28342
166,54801;9,99273;26481,79293;0,09284;0,11556;331,43671;11,55635;3,32126;2,71636;-0,28405
166,94801;10,01694;26484,55203;0,09217;0,11595;331,47124;11,59501;3,33237;2,71648;-0,28407
167,34801;10,04089;26484,32672;0,09230;0,11633;331,46842;11,63325;3,34336;2,71758;-0,28418
167,74801;10,06489;26481,07052;0,09260;0,11674;331,42767;11,67412;3,35510;2,69923;-0,28226
168,14801;10,08883;26481,12237;0,09266;0,11715;331,42832;11,71487;3,36682;2,70351;-0,28271
168,54801;10,11283;26482,37765;0,09350;0,11757;331,44403;11,75675;3,37885;2,72787;-0,28526
168,94801;10,13689;26476,42493;0,09237;0,11804;331,36952;11,80399;3,39243;2,73438;-0,28594
169,34801;10,16094;26478,25241;0,09318;0,11835;331,39240;11,83542;3,40146;2,74266;-0,28681
169,74801;10,18473;26477,86081;0,09323;0,11880;331,38749;11,87999;3,41427;2,74213;-0,28675
170,14801;10,20889;26472,80753;0,09241;0,11926;331,32425;11,92629;3,42758;2,75040;-0,28761
170,54801;10,23294;26473,63186;0,09288;0,11960;331,33457;11,95979;3,43721;2,75671;-0,28827
170,94801;10,25667;26471,58086;0,09297;0,12005;331,30890;12,00536;3,45030;2,76299;-0,28893
171,34801;10,28089;26471,29297;0,09289;0,12045;331,30529;12,04493;3,46167;2,77710;-0,29041
171,74801;10,30499;26469,31350;0,09237;0,12081;331,28052;12,08075;3,47197;2,81604;-0,29448
172,14801;10,32867;26468,25492;0,09226;0,12121;331,26727;12,12122;3,48360;2,83106;-0,29605
172,54801;10,35294;26466,92276;0,09237;0,12162;331,25060;12,16183;3,49527;2,84384;-0,29739
172,94801;10,37699;26466,50791;0,09253;0,12205;331,24541;12,20455;3,50755;2,85648;-0,29871
172,97401;10,37839;26466,45069;0,09198;0,12207;331,24469;12,20728;3,50833;2,85775;-0,29884