File: Data_Alu 6082 für NiGü/6082Alu_Zugprüfung.is_tens_RawData.csv/Specimen_RawData_2.csv
Prüflosbezeichnung;"Redux 312_quer+längs_alte Proben"
Proben-Nr;"1_2"
Prüfer;"JuBr"
Werkstoff;"6082"
Prüfnorm;"DIN EN ISO 527                                                   "
Prüfgeschwindigkeit;3,6;mm/min
Prüfklima;"23 °C / 50 % rF"
Bemerkungen;""

Zeit;Traversenweg;Last;Dehnung 1;Zugdehnung;Zugspannung;Axiale Dehnung (Video);Zugverformung;Transversale Dehnung (Video);Transversale Verformung 1
(sec);(mm);(N);(%);(mm/mm);(MPa);(%);(mm);(%);(mm)
0,00000;-0,00337;248,40357;-0,00371;-0,00004;3,10504;-0,00064;-0,00186;0,00901;-0,00092
0,15200;0,00461;338,40504;-0,00192;-0,00002;4,23006;0,00030;-0,00096;-0,00094;0,00010
0,25800;0,01189;491,50195;0,00076;0,00001;6,14377;0,00599;0,00038;-0,00525;0,00053
0,39200;0,01993;644,08975;0,00378;0,00004;8,05112;0,00910;0,00189;0,00269;-0,00027
0,53000;0,02834;795,83639;0,00674;0,00007;9,94795;0,01551;0,00337;0,00637;-0,00065
0,67400;0,03718;947,78873;0,00956;0,00010;11,84736;0,01650;0,00478;0,00655;-0,00067
0,82200;0,04596;1100,24102;0,01238;0,00012;13,75301;0,01860;0,00619;0,00329;-0,00033
0,97200;0,05491;1253,13241;0,01527;0,00015;15,66416;0,02395;0,00764;-0,00121;0,00012
1,12400;0,06402;1406,29962;0,01836;0,00018;17,57875;0,02497;0,00918;0,00449;-0,00046
1,27600;0,07307;1556,78630;0,02126;0,00021;19,45983;0,02974;0,01063;0,00093;-0,00009
1,43000;0,08229;1707,77243;0,02413;0,00024;21,34716;0,03212;0,01206;0,00437;-0,00044
1,58600;0,09161;1859,26918;0,02700;0,00027;23,24086;0,03582;0,01350;0,00553;-0,00056
1,74400;0,10109;2010,56890;0,02999;0,00030;25,13211;0,03856;0,01499;0,00262;-0,00027
1,90600;0,11084;2163,49125;0,03276;0,00033;27,04364;0,04552;0,01638;0,00649;-0,00066
2,07000;0,12070;2315,63352;0,03580;0,00036;28,94542;0,05234;0,01790;0,01110;-0,00113
2,23400;0,13061;2465,90696;0,03880;0,00039;30,82384;0,07073;0,01940;0,01441;-0,00147
2,40400;0,14079;2618,43413;0,04157;0,00042;32,73043;0,07222;0,02078;0,00990;-0,00101
2,57600;0,15107;2769,72435;0,04452;0,00045;34,62155;0,07672;0,02226;0,02528;-0,00257
2,75200;0,16162;2920,61985;0,04752;0,00048;36,50775;0,08181;0,02376;0,03188;-0,00324
2,93400;0,17250;3072,71183;0,05051;0,00051;38,40890;0,08212;0,02526;0,03147;-0,00320
3,12200;0,18380;3224,82593;0,05316;0,00053;40,31032;0,08269;0,02658;0,06506;-0,00662
3,31200;0,19527;3377,19396;0,05609;0,00056;42,21492;0,08511;0,02805;0,07099;-0,00722
3,50000;0,20657;3528,74637;0,05912;0,00059;44,10933;0,08632;0,02956;0,07850;-0,00799
3,69000;0,21798;3680,22546;0,06210;0,00062;46,00282;0,08690;0,03105;0,06871;-0,00699
3,88400;0,22971;3831,79531;0,06501;0,00065;47,89744;0,08998;0,03251;0,06978;-0,00710
4,07800;0,24139;3982,61815;0,06797;0,00068;49,78273;0,09087;0,03398;0,07388;-0,00752
4,27200;0,25291;4131,74629;0,07073;0,00071;51,64683;0,08941;0,03536;0,06647;-0,00676
4,47200;0,26475;4280,31653;0,07353;0,00074;53,50396;0,08818;0,03677;0,07194;-0,00732
4,67200;0,27686;4425,92382;0,07645;0,00076;55,32405;0,08848;0,03822;0,06655;-0,00677
4,87200;0,28891;4571,23831;0,07923;0,00079;57,14048;0,08723;0,03962;0,07422;-0,00755
5,07200;0,30096;4714,99801;0,08210;0,00082;58,93748;0,09131;0,04105;0,06176;-0,00628
5,27200;0,31302;4858,45640;0,08476;0,00085;60,73071;0,09466;0,04238;0,06969;-0,00709
5,47200;0,32486;4999,70958;0,08755;0,00088;62,49637;0,09733;0,04377;0,04894;-0,00498
5,67200;0,33680;5138,27518;0,09044;0,00090;64,22844;0,10251;0,04522;0,05983;-0,00609
5,87200;0,34886;5276,94717;0,09310;0,00093;65,96184;0,10718;0,04655;0,06535;-0,00665
6,07200;0,36096;5416,36616;0,09580;0,00096;67,70458;0,10675;0,04790;0,06607;-0,00672
6,27200;0,37302;5554,27283;0,09848;0,00098;69,42841;0,11537;0,04924;0,06869;-0,00699
6,47200;0,38502;5693,16119;0,10120;0,00101;71,16451;0,12001;0,05060;0,07589;-0,00772
6,67200;0,39680;5829,40310;0,10398;0,00104;72,86754;0,12359;0,05199;0,06660;-0,00678
6,87200;0,40880;5965,24715;0,10653;0,00107;74,56559;0,12284;0,05327;0,07849;-0,00798
7,07200;0,42091;6104,04074;0,10940;0,00109;76,30051;0,12326;0,05470;0,07087;-0,00721
7,27200;0,43296;6244,65957;0,11210;0,00112;78,05824;0,12516;0,05605;0,07133;-0,00726
7,47200;0,44507;6383,86354;0,11466;0,00115;79,79829;0,12826;0,05733;0,06436;-0,00655
7,67200;0,45686;6523,26018;0,11754;0,00118;81,54075;0,13257;0,05877;0,07389;-0,00752
7,87200;0,46875;6660,31793;0,12026;0,00120;83,25397;0,13437;0,06013;0,06402;-0,00651
8,07200;0,48086;6798,21610;0,12296;0,00123;84,97770;0,13633;0,06148;0,07855;-0,00799
8,27200;0,49291;6938,76252;0,12568;0,00126;86,73453;0,13828;0,06284;0,07386;-0,00751
8,47200;0,50502;7078,61379;0,12833;0,00128;88,48267;0,13886;0,06417;0,07070;-0,00719
8,67200;0,51702;7218,98586;0,13125;0,00131;90,23732;0,14125;0,06562;0,07666;-0,00780
8,87200;0,52886;7358,17418;0,13386;0,00134;91,97718;0,14449;0,06693;0,06479;-0,00659
9,07200;0,54080;7494,53589;0,13657;0,00137;93,68170;0,14441;0,06828;0,07258;-0,00738
9,27200;0,55286;7631,68395;0,13944;0,00139;95,39605;0,14948;0,06972;0,07088;-0,00721
9,47200;0,56496;7772,05914;0,14216;0,00142;97,15074;0,14554;0,07108;0,06899;-0,00702
9,67200;0,57702;7910,87687;0,14484;0,00145;98,88596;0,14498;0,07242;0,06381;-0,00649
9,87200;0,58896;8048,32041;0,14756;0,00148;100,60401;0,14161;0,07378;0,06531;-0,00664
10,07200;0,60080;8183,18993;0,15023;0,00150;102,28987;0,14533;0,07512;0,08255;-0,00840
10,27200;0,61286;8317,38889;0,15292;0,00153;103,96736;0,14658;0,07646;0,06094;-0,00620
10,47200;0,62491;8453,49580;0,15562;0,00156;105,66870;0,14779;0,07781;0,05588;-0,00568
10,67200;0,63691;8590,69616;0,15831;0,00158;107,38370;0,14875;0,07915;0,05475;-0,00557
10,87200;0,64907;8727,15443;0,16104;0,00161;109,08943;0,15546;0,08052;0,05714;-0,00581
11,07200;0,66091;8863,96229;0,16374;0,00164;110,79953;0,15259;0,08187;0,08970;-0,00912
11,27200;0,67275;8996,38385;0,16624;0,00166;112,45480;0,15712;0,08312;0,08264;-0,00841
11,47200;0,68486;9128,52556;0,16878;0,00169;114,10657;0,16193;0,08439;0,10284;-0,01046
11,67200;0,69691;9264,30792;0,17169;0,00172;115,80385;0,16360;0,08585;0,09803;-0,00997
11,87200;0,70896;9399,12736;0,17430;0,00174;117,48909;0,16790;0,08715;0,10196;-0,01037
12,07200;0,72107;9534,41352;0,17681;0,00177;119,18017;0,17419;0,08841;0,10845;-0,01103
12,27200;0,73280;9668,08319;0,17953;0,00180;120,85104;0,17434;0,08977;0,11650;-0,01185
12,47200;0,74480;9798,82926;0,18220;0,00182;122,48537;0,18919;0,09110;0,11963;-0,01217
12,67200;0,75691;9932,16187;0,18470;0,00185;124,15202;0,19321;0,09235;0,13688;-0,01392
12,87200;0,76891;10066,67823;0,18760;0,00188;125,83348;0,20186;0,09380;0,13622;-0,01386
13,07200;0,78107;10201,65771;0,19001;0,00190;127,52072;0,20607;0,09501;0,13880;-0,01412
13,27200;0,79296;10335,35421;0,19285;0,00193;129,19193;0,20481;0,09642;0,14669;-0,01492
13,47200;0,80480;10467,10432;0,19548;0,00195;130,83880;0,20561;0,09774;0,14525;-0,01478
13,67200;0,81686;10597,32199;0,19794;0,00198;132,46652;0,20493;0,09897;0,11716;-0,01192
13,87200;0,82891;10731,15617;0,20073;0,00201;134,13945;0,20811;0,10037;0,11666;-0,01187
14,07200;0,84086;10865,32831;0,20348;0,00203;135,81660;0,20610;0,10174;0,11262;-0,01146
14,27200;0,85307;10999,62920;0,20594;0,00206;137,49536;0,20969;0,10297;0,11207;-0,01140
14,47200;0,86491;11134,50855;0,20868;0,00209;139,18136;0,21562;0,10434;0,11098;-0,01129
14,67200;0,87675;11266,32124;0,21128;0,00211;140,82902;0,21468;0,10564;0,12171;-0,01238
14,87200;0,88891;11398,88406;0,21401;0,00214;142,48605;0,22102;0,10700;0,11228;-0,01142
15,07200;0,90091;11533,93954;0,21670;0,00217;144,17424;0,22360;0,10835;0,11717;-0,01192
15,27200;0,91291;11668,37722;0,21931;0,00219;145,85472;0,22481;0,10966;0,12009;-0,01222
15,47200;0,92507;11805,85563;0,22205;0,00222;147,57320;0,22955;0,11102;0,11504;-0,01170
15,67200;0,93686;11940,86462;0,22475;0,00225;149,26081;0,23148;0,11237;0,12515;-0,01273
15,87200;0,94875;12072,06309;0,22735;0,00227;150,90079;0,23743;0,11367;0,12542;-0,01276
16,07200;0,96091;12207,80432;0,23017;0,00230;152,59755;0,23532;0,11509;0,12541;-0,01276
16,27200;0,97296;12345,58135;0,23291;0,00233;154,31977;0,23982;0,11646;0,11553;-0,01175
16,47200;0,98502;12481,65876;0,23558;0,00236;156,02073;0,24138;0,11779;0,11222;-0,01142
16,67200;0,99696;12618,64364;0,23821;0,00238;157,73305;0,24237;0,11911;0,11055;-0,01125
16,87200;1,00880;12754,69154;0,24099;0,00241;159,43364;0,24690;0,12049;0,12004;-0,01221
17,07200;1,02086;12888,13412;0,24390;0,00244;161,10168;0,24859;0,12195;0,11788;-0,01199
17,27200;1,03291;13025,21914;0,24647;0,00246;162,81524;0,25103;0,12324;0,10962;-0,01115
17,47200;1,04486;13162,96667;0,24933;0,00249;164,53708;0,25266;0,12467;0,11769;-0,01197
17,67200;1,05707;13301,21219;0,25200;0,00252;166,26515;0,25307;0,12600;0,11315;-0,01151
17,87200;1,06891;13439,97717;0,25491;0,00255;167,99971;0,25428;0,12745;0,11584;-0,01178
18,07200;1,08075;13575,28210;0,25766;0,00258;169,69103;0,25802;0,12883;0,11515;-0,01171
18,27200;1,09291;13710,64156;0,26027;0,00260;171,38302;0,25627;0,13014;0,11295;-0,01149
18,47200;1,10496;13851,01676;0,26327;0,00263;173,13771;0,25500;0,13164;0,15361;-0,01563
18,67200;1,11691;13989,14158;0,26597;0,00266;174,86427;0,25664;0,13298;0,15337;-0,01560
18,87200;1,12907;14128,22664;0,26861;0,00269;176,60283;0,25862;0,13431;0,15361;-0,01563
19,07200;1,14086;14268,33540;0,27164;0,00272;178,35419;0,25835;0,13582;0,15106;-0,01537
19,27200;1,15275;14404,00779;0,27435;0,00274;180,05010;0,26590;0,13717;0,14549;-0,01480
19,47200;1,16496;14541,93234;0,27716;0,00277;181,77415;0,26323;0,13858;0,15986;-0,01626
19,67200;1,17691;14682,48188;0,28012;0,00280;183,53102;0,27033;0,14006;0,15391;-0,01566
19,87200;1,18902;14822,53432;0,28271;0,00283;185,28168;0,27626;0,14136;0,14517;-0,01477
20,07200;1,20102;14963,21350;0,28592;0,00286;187,04017;0,27722;0,14296;0,14513;-0,01476
20,27200;1,21275;15101,83454;0,28856;0,00289;188,77293;0,28078;0,14428;0,15099;-0,01536
20,47200;1,22480;15238,78813;0,29143;0,00291;190,48485;0,28546;0,14571;0,15640;-0,01591
20,67200;1,23696;15380,39088;0,29439;0,00294;192,25489;0,28714;0,14719;0,13104;-0,01333
20,87200;1,24891;15519,99807;0,29707;0,00297;193,99998;0,29088;0,14853;0,13362;-0,01359
21,07200;1,26102;15660,09164;0,30003;0,00300;195,75115;0,29492;0,15002;0,14051;-0,01429
21,27200;1,27296;15803,22325;0,30283;0,00303;197,54029;0,29836;0,15141;0,14341;-0,01459
21,47200;1,28475;15942,56938;0,30583;0,00306;199,28212;0,30474;0,15291;0,14629;-0,01488
21,67200;1,29686;16080,58155;0,30860;0,00309;201,00727;0,30719;0,15430;0,15115;-0,01538
21,87200;1,30896;16223,81687;0,31160;0,00312;202,79771;0,31197;0,15580;0,15037;-0,01530
22,07200;1,32091;16366,30833;0,31440;0,00314;204,57885;0,31382;0,15720;0,15613;-0,01588
22,27200;1,33307;16507,63392;0,31746;0,00317;206,34542;0,31641;0,15873;0,15056;-0,01532
22,47200;1,34486;16651,14462;0,32034;0,00320;208,13931;0,31974;0,16017;0,15076;-0,01534
22,67200;1,35675;16789,80231;0,32315;0,00323;209,87253;0,32114;0,16158;0,15653;-0,01592
22,87200;1,36896;16931,53381;0,32622;0,00326;211,64417;0,32422;0,16311;0,14693;-0,01495
23,07200;1,38096;17074,83172;0,32906;0,00329;213,43540;0,33495;0,16453;0,15231;-0,01549
23,27200;1,39291;17216,04109;0,33197;0,00332;215,20051;0,33980;0,16598;0,15003;-0,01526
23,47200;1,40507;17361,10389;0,33499;0,00335;217,01380;0,34339;0,16749;0,15756;-0,01603
23,67200;1,41680;17503,36111;0,33794;0,00338;218,79201;0,34352;0,16897;0,14798;-0,01505
23,87200;1,42880;17641,71839;0,34095;0,00341;220,52148;0,34832;0,17047;0,14629;-0,01488
24,07200;1,44091;17785,06637;0,34363;0,00344;222,31333;0,34717;0,17182;0,15304;-0,01557
24,27200;1,45291;17929,81267;0,34698;0,00347;224,12266;0,35263;0,17349;0,14557;-0,01481
24,47200;1,46502;18072,30949;0,34976;0,00350;225,90387;0,35885;0,17488;0,15295;-0,01556
24,67200;1,47696;18217,47243;0,35298;0,00353;227,71841;0,36288;0,17649;0,14984;-0,01524
24,87200;1,48875;18359,73501;0,35592;0,00356;229,49669;0,36500;0,17796;0,15228;-0,01549
25,07200;1,50086;18499,84109;0,35865;0,00359;231,24801;0,36592;0,17932;0,16447;-0,01673
25,27200;1,51302;18644,91642;0,36190;0,00362;233,06146;0,36809;0,18095;0,15927;-0,01620
25,47200;1,52486;18789,41417;0,36478;0,00365;234,86768;0,37086;0,18239;0,16968;-0,01726
25,67200;1,53702;18933,52211;0,36793;0,00368;236,66903;0,37221;0,18397;0,18323;-0,01864
25,87200;1,54891;19079,06592;0,37102;0,00371;238,48832;0,37417;0,18551;0,19692;-0,02003
26,07200;1,56075;19219,62440;0,37381;0,00374;240,24531;0,37905;0,18691;0,20056;-0,02040
26,27200;1,57291;19361,90844;0,37692;0,00377;242,02386;0,38123;0,18846;0,19173;-0,01950
26,47000;1,58486;19507,40933;0,37985;0,00380;243,84262;0,38671;0,18992;0,18987;-0,01931
26,67000;1,59686;19651,55482;0,38309;0,00383;245,64444;0,38789;0,19155;0,20912;-0,02127
26,87000;1,60891;19795,43924;0,38602;0,00386;247,44299;0,39332;0,19301;0,19821;-0,02016
27,07000;1,62064;19939,96382;0,38917;0,00389;249,24955;0,39514;0,19458;0,19931;-0,02027
27,27000;1,63264;20081,33769;0,39217;0,00392;251,01672;0,39602;0,19609;0,20215;-0,02056
27,47000;1,64486;20225,56365;0,39525;0,00395;252,81955;0,39974;0,19762;0,18955;-0,01928
27,67000;1,65680;20370,46015;0,39848;0,00398;254,63075;0,39984;0,19924;0,19294;-0,01963
27,87000;1,66886;20515,18857;0,40144;0,00401;256,43986;0,40195;0,20072;0,19246;-0,01958
28,07000;1,68091;20661,35645;0,40463;0,00405;258,26696;0,40689;0,20232;0,15158;-0,01542
28,27000;1,69270;20804,57926;0,40763;0,00408;260,05724;0,40816;0,20382;0,16491;-0,01678
28,47000;1,70470;20944,40639;0,41076;0,00411;261,80508;0,41140;0,20538;0,17638;-0,01794
28,67000;1,71686;21090,63864;0,41382;0,00414;263,63298;0,41523;0,20691;0,17853;-0,01816
28,87000;1,72880;21236,62412;0,41712;0,00417;265,45780;0,41897;0,20856;0,17226;-0,01752
29,07000;1,74091;21379,54116;0,42020;0,00420;267,24426;0,41883;0,21010;0,17405;-0,01770
29,27000;1,75270;21523,89586;0,42328;0,00423;269,04870;0,42079;0,21164;0,17400;-0,01770
29,47000;1,76464;21668,08963;0,42651;0,00427;270,85112;0,42511;0,21325;0,17210;-0,01751
29,67000;1,77680;21809,89802;0,42962;0,00430;272,62373;0,41773;0,21481;0,17378;-0,01768
29,87000;1,78886;21956,16066;0,43287;0,00433;274,45201;0,42118;0,21643;0,17752;-0,01806
30,07000;1,80075;22101,47381;0,43596;0,00436;276,26842;0,42193;0,21798;0,17603;-0,01791
30,27000;1,81291;22246,18256;0,43936;0,00439;278,07728;0,42592;0,21968;0,17419;-0,01772
30,47000;1,82475;22390,45501;0,44223;0,00442;279,88069;0,43085;0,22111;0,16876;-0,01717
30,67000;1,83664;22531,20661;0,44585;0,00446;281,64008;0,43683;0,22293;0,17694;-0,01800
30,87000;1,84880;22674,18802;0,44880;0,00449;283,42735;0,43721;0,22440;0,18221;-0,01854
31,07000;1,86091;22819,46540;0,45201;0,00452;285,24332;0,44250;0,22600;0,18251;-0,01857
31,27000;1,87286;22961,85315;0,45541;0,00455;287,02316;0,44486;0,22770;0,16734;-0,01702
31,47000;1,88486;23104,96867;0,45845;0,00458;288,81211;0,44535;0,22922;0,17384;-0,01768
31,67000;1,89670;23248,59738;0,46197;0,00462;290,60747;0,45251;0,23098;0,17308;-0,01761
31,87000;1,90875;23387,89344;0,46502;0,00465;292,34867;0,45358;0,23251;0,18396;-0,01871
32,07000;1,92080;23530,04873;0,46824;0,00468;294,12561;0,45530;0,23412;0,17731;-0,01804
32,27000;1,93275;23674,02434;0,47171;0,00472;295,92530;0,46028;0,23585;0,18902;-0,01923
32,47000;1,94491;23815,51266;0,47515;0,00475;297,69391;0,46321;0,23757;0,21147;-0,02151
32,67000;1,95686;23957,75378;0,47846;0,00478;299,47192;0,46933;0,23923;0,21314;-0,02168
32,87000;1,96859;24095,51561;0,48174;0,00482;301,19395;0,47074;0,24087;0,21066;-0,02143
33,07000;1,98075;24234,85994;0,48510;0,00485;302,93575;0,47439;0,24255;0,21949;-0,02233
33,27000;1,99291;24377,19405;0,48861;0,00489;304,71493;0,47428;0,24430;0,23255;-0,02366
33,47000;2,00480;24517,51292;0,49224;0,00492;306,46891;0,48286;0,24612;0,23482;-0,02389
33,67000;2,01686;24654,69897;0,49555;0,00496;308,18374;0,48745;0,24777;0,22749;-0,02314
33,87000;2,02870;24793,24937;0,49903;0,00499;309,91562;0,48955;0,24952;0,23963;-0,02438
34,07000;2,04069;24927,92487;0,50280;0,00503;311,59906;0,49213;0,25140;0,23858;-0,02427
34,27000;2,05280;25062,08181;0,50624;0,00506;313,27602;0,49519;0,25312;0,24383;-0,02480
34,47000;2,06480;25198,18068;0,50997;0,00510;314,97726;0,50261;0,25498;0,24191;-0,02461
34,67000;2,07686;25333,28533;0,51365;0,00514;316,66607;0,50958;0,25683;0,22792;-0,02318
34,87000;2,08891;25465,24465;0,51782;0,00518;318,31556;0,51426;0,25891;0,22034;-0,02241
35,07000;2,10069;25594,67554;0,52156;0,00522;319,93344;0,51600;0,26078;0,22317;-0,02270
35,27000;2,11270;25718,58466;0,52540;0,00525;321,48231;0,52248;0,26270;0,23169;-0,02357
35,47000;2,12480;25844,44463;0,52977;0,00530;323,05556;0,52299;0,26488;0,23229;-0,02363
35,67000;2,13680;25968,85443;0,53410;0,00534;324,61068;0,52823;0,26705;0,23613;-0,02402
35,87000;2,14891;26087,74245;0,53886;0,00539;326,09678;0,53304;0,26943;0,23572;-0,02398
36,07000;2,16080;26203,79627;0,54361;0,00544;327,54745;0,53754;0,27181;0,23503;-0,02391
36,27000;2,17275;26313,27510;0,54876;0,00549;328,91594;0,54549;0,27438;0,23982;-0,02440
36,47000;2,18475;26414,02423;0,55420;0,00554;330,17530;0,55673;0,27710;0,23726;-0,02413
36,67000;2,19680;26512,30574;0,56023;0,00560;331,40382;0,56391;0,28011;0,23833;-0,02424
36,87000;2,20886;26602,29921;0,56692;0,00567;332,52874;0,57016;0,28346;0,24541;-0,02496
37,07000;2,22091;26677,77658;0,57451;0,00575;333,47221;0,58747;0,28725;0,24153;-0,02457
37,27000;2,23269;26739,57646;0,58285;0,00583;334,24471;0,59756;0,29143;0,23268;-0,02367
37,47000;2,24464;26784,93977;0,59252;0,00593;334,81175;0,60790;0,29626;0,23631;-0,02404
37,67000;2,25686;26813,83789;0,60340;0,00603;335,17297;0,62121;0,30170;0,23455;-0,02386
37,87000;2,26886;26825,63961;0,61594;0,00616;335,32050;0,63184;0,30797;0,24367;-0,02479
38,07000;2,28091;26820,39678;0,62946;0,00629;335,25496;0,64965;0,31473;0,23388;-0,02379
38,27000;2,29286;26801,69284;0,64396;0,00644;335,02116;0,66316;0,32198;0,23525;-0,02393
38,47000;2,30475;26772,59982;0,65860;0,00659;334,65750;0,67483;0,32930;0,23515;-0,02392
38,67000;2,31680;26737,04088;0,67348;0,00673;334,21301;0,68631;0,33674;0,23717;-0,02413
38,87000;2,32880;26700,74522;0,68819;0,00688;333,75932;0,70524;0,34410;0,23802;-0,02421
39,07000;2,34080;26663,67352;0,70261;0,00703;333,29592;0,72426;0,35131;0,24188;-0,02460
39,27000;2,35296;26625,31972;0,71652;0,00717;332,81650;0,74036;0,35826;0,24954;-0,02538
39,47000;2,36480;26587,92436;0,72982;0,00730;332,34905;0,75172;0,36491;0,24533;-0,02496
39,67000;2,37664;26552,95908;0,74279;0,00743;331,91199;0,76689;0,37140;0,25986;-0,02643
39,87000;2,38886;26522,56429;0,75526;0,00755;331,53205;0,78863;0,37763;0,27976;-0,02846
40,07000;2,40086;26495,44358;0,76726;0,00767;331,19304;0,80582;0,38363;0,29170;-0,02967
40,27000;2,41275;26473,06144;0,77893;0,00779;330,91327;0,81787;0,38946;0,29288;-0,02979
40,47000;2,42491;26455,67179;0,79025;0,00790;330,69590;0,83257;0,39512;0,30387;-0,03091
40,67000;2,43680;26439,06713;0,80128;0,00801;330,48834;0,84735;0,40064;0,30437;-0,03096
40,87000;2,44869;26420,94612;0,81214;0,00812;330,26183;0,86236;0,40607;0,30230;-0,03075
41,07000;2,46080;26407,10413;0,82260;0,00823;330,08880;0,86849;0,41130;0,30668;-0,03120
41,27000;2,47286;26400,23053;0,83318;0,00833;330,00288;0,88095;0,41659;0,31336;-0,03188
41,47000;2,48496;26391,22188;0,84332;0,00843;329,89027;0,88996;0,42166;0,30936;-0,03147
41,67000;2,49691;26381,70719;0,85355;0,00854;329,77134;0,89938;0,42678;0,31158;-0,03170
41,87000;2,50869;26373,23320;0,86334;0,00863;329,66541;0,91808;0,43167;0,31374;-0,03191
42,07000;2,52080;26364,26389;0,87283;0,00873;329,55330;0,92317;0,43641;0,32014;-0,03257
42,27000;2,53280;26358,21462;0,88237;0,00882;329,47768;0,93522;0,44119;0,31645;-0,03219
42,47000;2,54486;26352,87166;0,89177;0,00892;329,41090;0,94568;0,44589;0,31824;-0,03237
42,67000;2,55686;26347,11564;0,90104;0,00901;329,33895;0,95284;0,45052;0,32224;-0,03278
42,87000;2,56880;26344,41197;0,91052;0,00911;329,30515;0,96438;0,45526;0,32929;-0,03350
43,07000;2,58069;26337,11100;0,91967;0,00920;329,21389;0,97377;0,45983;0,31759;-0,03231
43,27000;2,59280;26329,29862;0,92875;0,00929;329,11623;0,98694;0,46437;0,32352;-0,03291
43,47000;2,60480;26327,38352;0,93822;0,00938;329,09229;0,99834;0,46911;0,32403;-0,03296
43,67000;2,61686;26323,97711;0,94748;0,00947;329,04971;1,00752;0,47374;0,30994;-0,03153
43,87000;2,62902;26319,88227;0,95675;0,00957;328,99853;1,01629;0,47838;0,30202;-0,03072
44,07000;2,64069;26315,14013;0,96613;0,00966;328,93925;1,02745;0,48306;0,29253;-0,02976
44,27000;2,65264;26309,27324;0,97539;0,00975;328,86592;1,03814;0,48770;0,30226;-0,03075
44,47000;2,66486;26305,71663;0,98499;0,00985;328,82146;1,04863;0,49249;0,30932;-0,03147
44,67000;2,67680;26302,66428;0,99450;0,00994;328,78330;1,06235;0,49725;0,30578;-0,03111
44,87000;2,68886;26299,37410;1,00374;0,01004;328,74218;1,06877;0,50187;0,30984;-0,03152
45,07000;2,70091;26297,38748;1,01318;0,01013;328,71734;1,08071;0,50659;0,31035;-0,03157
45,27000;2,71269;26292,04631;1,02263;0,01023;328,65058;1,09246;0,51131;0,31090;-0,03163
45,47000;2,72475;26284,85799;1,03200;0,01032;328,56072;1,10032;0,51600;0,30877;-0,03141
45,67000;2,73680;26283,06091;1,04144;0,01041;328,53826;1,11639;0,52072;0,31241;-0,03178
45,87000;2,74875;26280,39300;1,05077;0,01051;328,50491;1,12133;0,52538;0,31176;-0,03171
46,07000;2,76096;26277,27449;1,06011;0,01060;328,46593;1,13248;0,53006;0,31365;-0,03191
46,27000;2,77286;26274,68884;1,06974;0,01070;328,43361;1,14693;0,53487;0,32038;-0,03259
46,47000;2,78464;26269,46926;1,07912;0,01079;328,36837;1,15332;0,53956;0,31961;-0,03251
46,67000;2,79686;26264,40525;1,08853;0,01089;328,30507;1,16329;0,54426;0,31239;-0,03178
46,87000;2,80886;26262,63320;1,09800;0,01098;328,28292;1,17473;0,54900;0,31098;-0,03163
47,07000;2,82075;26258,23438;1,10736;0,01107;328,22793;1,18402;0,55368;0,31084;-0,03162
47,27000;2,83302;26256,44088;1,11671;0,01117;328,20551;1,19511;0,55836;0,31472;-0,03201
47,47000;2,84475;26253,24368;1,12601;0,01126;328,16555;1,20469;0,56300;0,30932;-0,03146
47,67000;2,85664;26243,93642;1,13517;0,01135;328,04921;1,21363;0,56758;0,31287;-0,03183
47,87000;2,86886;26239,46965;1,14437;0,01144;327,99337;1,22401;0,57218;0,31882;-0,03243
48,07000;2,88086;26237,95867;1,15346;0,01153;327,97448;1,22961;0,57673;0,31115;-0,03165
48,27000;2,89286;26232,93757;1,16241;0,01162;327,91172;1,24114;0,58121;0,31369;-0,03191
48,47000;2,90491;26230,40557;1,17148;0,01171;327,88007;1,25120;0,58574;0,32270;-0,03283
48,67000;2,91664;26225,13056;1,18026;0,01180;327,81413;1,26011;0,59013;0,31090;-0,03163
48,87000;2,92875;26218,17470;1,18909;0,01189;327,72718;1,26997;0,59455;0,31566;-0,03211
49,07000;2,94086;26212,90147;1,19765;0,01198;327,66127;1,28102;0,59883;0,31278;-0,03182
49,27000;2,95280;26209,24652;1,20622;0,01206;327,61558;1,28722;0,60311;0,32487;-0,03305
49,47000;2,96491;26204,95498;1,21473;0,01215;327,56194;1,29691;0,60737;0,31673;-0,03222
49,67000;2,97691;26202,08144;1,22316;0,01223;327,52602;1,30461;0,61158;0,32343;-0,03290
49,87000;2,98864;26194,27621;1,23141;0,01231;327,42845;1,31870;0,61570;0,31857;-0,03241
50,07000;3,00069;26185,71103;1,23929;0,01239;327,32139;1,32558;0,61965;0,31711;-0,03226
50,27000;3,01286;26185,20319;1,24727;0,01247;327,31504;1,33310;0,62363;0,32692;-0,03326
50,47000;3,02480;26180,27508;1,25507;0,01255;327,25344;1,34438;0,62754;0,31348;-0,03189
50,67000;3,03691;26173,09034;1,26292;0,01263;327,16363;1,35112;0,63146;0,32528;-0,03309
50,87000;3,04875;26168,84172;1,27045;0,01270;327,11052;1,35858;0,63523;0,33046;-0,03362
51,07000;3,06059;26160,01189;1,27779;0,01278;327,00015;1,36414;0,63890;0,32778;-0,03334
51,27000;3,07286;26151,51823;1,28512;0,01285;326,89398;1,37513;0,64256;0,32597;-0,03316
51,47000;3,08485;26146,87800;1,29211;0,01292;326,83598;1,37968;0,64605;0,32920;-0,03349
51,67000;3,09675;26140,68747;1,29919;0,01299;326,75859;1,38549;0,64959;0,32645;-0,03321
51,87000;3,10896;26134,98867;1,30594;0,01306;326,68736;1,39211;0,65297;0,34091;-0,03468
52,07000;3,12075;26128,35288;1,31251;0,01313;326,60441;1,40123;0,65626;0,33858;-0,03444
52,27000;3,13269;26117,22887;1,31888;0,01319;326,46536;1,40212;0,65944;0,34880;-0,03548
52,47000;3,14486;26109,33065;1,32538;0,01325;326,36663;1,41038;0,66269;0,33810;-0,03439
52,67000;3,15691;26104,34175;1,33124;0,01331;326,30427;1,41701;0,66562;0,33941;-0,03453
52,87000;3,16886;26095,24012;1,33717;0,01337;326,19050;1,42363;0,66858;0,35326;-0,03594
53,07000;3,18091;26087,90517;1,34312;0,01343;326,09881;1,42706;0,67156;0,36014;-0,03664
53,27000;3,19269;26079,96941;1,34865;0,01349;325,99962;1,43092;0,67432;0,35884;-0,03650
53,47000;3,20480;26067,47031;1,35398;0,01354;325,84338;1,43736;0,67699;0,35990;-0,03661
53,67000;3,21686;26059,36110;1,35905;0,01359;325,74201;1,43972;0,67952;0,36629;-0,03726
53,87000;3,22869;26051,50580;1,36431;0,01364;325,64382;1,44492;0,68216;0,36663;-0,03730
54,07000;3,24096;26041,72647;1,36922;0,01369;325,52158;1,44760;0,68461;0,37469;-0,03811
54,27000;3,25280;26033,00035;1,37402;0,01374;325,41250;1,45013;0,68701;0,36781;-0,03741
54,47000;3,26464;26020,48159;1,37840;0,01378;325,25602;1,45648;0,68920;0,38846;-0,03952
54,67000;3,27680;26007,74288;1,38290;0,01383;325,09679;1,45950;0,69145;0,40529;-0,04123
54,87000;3,28896;26000,32389;1,38731;0,01387;325,00405;1,46163;0,69366;0,39762;-0,04045
55,07000;3,30080;25988,76536;1,39120;0,01391;324,85957;1,46713;0,69560;0,40441;-0,04114
55,27000;3,31285;25976,67396;1,39518;0,01395;324,70842;1,47047;0,69759;0,40744;-0,04145
55,47000;3,32475;25966,45653;1,39907;0,01399;324,58071;1,47386;0,69954;0,40085;-0,04078
55,67000;3,33664;25950,52600;1,40259;0,01403;324,38157;1,47571;0,70130;0,40442;-0,04114
55,87000;3,34885;25937,96253;1,40601;0,01406;324,22453;1,47890;0,70300;0,40775;-0,04148
56,07000;3,36080;25926,23055;1,40929;0,01409;324,07788;1,47883;0,70465;0,40940;-0,04165
56,27000;3,37285;25914,02471;1,41256;0,01413;323,92531;1,48105;0,70628;0,40933;-0,04164
56,47000;3,38496;25902,14789;1,41552;0,01416;323,77685;1,48562;0,70776;0,41109;-0,04182
56,67000;3,39669;25887,90715;1,41860;0,01419;323,59884;1,48735;0,70930;0,41034;-0,04174
56,87000;3,40869;25870,61763;1,42103;0,01421;323,38272;1,48849;0,71051;0,41647;-0,04237
57,07000;3,42085;25857,06174;1,42374;0,01424;323,21327;1,49061;0,71187;0,40505;-0,04120
57,27000;3,43275;25842,60643;1,42631;0,01426;323,03258;1,49056;0,71316;0,41694;-0,04241
57,47000;3,44486;25825,98388;1,42874;0,01429;322,82480;1,49365;0,71437;0,40818;-0,04152
57,67000;3,45685;25813,90321;1,43088;0,01431;322,67379;1,49440;0,71544;0,41869;-0,04259
57,87000;3,46864;25794,52693;1,43292;0,01433;322,43159;1,49773;0,71646;0,40982;-0,04169
58,07000;3,48080;25776,69740;1,43480;0,01435;322,20872;1,49522;0,71740;0,41722;-0,04244
58,27000;3,49285;25761,79147;1,43670;0,01437;322,02239;1,49654;0,71835;0,40910;-0,04162
58,47000;3,50485;25745,81087;1,43857;0,01439;321,82264;1,49917;0,71929;0,41545;-0,04226
58,67000;3,51691;25726,76003;1,44018;0,01440;321,58450;1,50141;0,72009;0,40786;-0,04149
58,87000;3,52875;25708,17411;1,44164;0,01442;321,35218;1,50042;0,72082;0,41638;-0,04236
59,07000;3,54064;25687,30652;1,44302;0,01443;321,09133;1,50543;0,72151;0,41103;-0,04181
59,27000;3,55285;25667,17029;1,44429;0,01444;320,83963;1,50366;0,72215;0,41231;-0,04194
59,47000;3,56496;25649,66440;1,44553;0,01446;320,62081;1,50573;0,72277;0,40643;-0,04134
59,67000;3,57685;25628,84152;1,44679;0,01447;320,36052;1,50330;0,72339;0,41258;-0,04197
59,87000;3,58886;25608,20818;1,44790;0,01448;320,10260;1,50495;0,72395;0,41887;-0,04261
60,07000;3,60080;25586,79342;1,44893;0,01449;319,83492;1,50677;0,72446;0,42037;-0,04276
60,27000;3,61275;25561,17117;1,44972;0,01450;319,51464;1,50656;0,72486;0,40900;-0,04160
60,47000;3,62480;25538,69069;1,45039;0,01450;319,23363;1,50914;0,72519;0,40449;-0,04115
60,67000;3,63685;25517,01128;1,45104;0,01451;318,96264;1,50608;0,72552;0,41330;-0,04204
60,87000;3,64896;25491,75560;1,45146;0,01451;318,64695;1,50175;0,72573;0,41210;-0,04192
61,07000;3,66080;25465,36982;1,45200;0,01452;318,31712;1,50211;0,72600;0,41183;-0,04189
61,27000;3,67269;25436,47885;1,45243;0,01452;317,95599;1,50785;0,72622;0,40933;-0,04164
61,47000;3,68480;25402,72772;1,45271;0,01453;317,53410;1,50937;0,72635;0,40892;-0,04160
61,67000;3,69685;25366,52148;1,45256;0,01453;317,08152;1,50311;0,72628;0,40683;-0,04138
61,87000;3,70891;25296,51046;1,45111;0,01451;316,20638;1,50235;0,72556;0,41108;-0,04182
62,07000;3,72096;25204,00643;1,44977;0,01450;315,05008;1,50007;0,72489;0,41499;-0,04221
62,27000;3,73275;25085,00397;1,44678;0,01447;313,56255;1,49720;0,72339;0,38743;-0,03941
62,45000;3,74352;24935,85527;1,44314;0,01443;311,69819;1,49275;0,72157;0,37318;-0,03796
62,57600;3,75139;24785,06327;1,43933;0,01439;309,81329;1,48690;0,71967;0,36484;-0,03711
62,61600;3,75369;24508,04293;1,44365;0,01444;306,35054;1,35752;0,72183;0,37693;-0,03834
62,62000;3,75477;23405,09534;1,51433;0,01514;292,56369;1,31229;0,75717;0,37844;-0,03850
62,62400;3,75605;21345,21246;1,68406;0,01684;266,81516;1,25446;0,84203;0,37899;-0,03855
62,62800;3,75734;18784,36625;1,91564;0,01916;234,80458;1,19663;0,95782;0,37955;-0,03861
62,63200;3,75862;15983,31392;2,19988;0,02200;199,79142;1,13881;1,09994;0,38011;-0,03867
62,63400;3,75921;14571,04951;2,35529;0,02355;182,13812;1,10194;1,17764;0,38046;-0,03870