File: Data_Alu 6082 für NiGü/6082Alu_Zugprüfung.is_tens_RawData.csv/Specimen_RawData_3.csv
Prüflosbezeichnung;"Redux 312_quer+längs_alte Proben"
Proben-Nr;"I10_1"
Prüfer;"JuBr"
Werkstoff;"6082"
Prüfnorm;"DIN EN ISO 527                                                   "
Prüfgeschwindigkeit;3,6;mm/min
Prüfklima;"23 °C / 50 % rF"
Bemerkungen;""

Zeit;Traversenweg;Last;Dehnung 1;Zugdehnung;Zugspannung;Axiale Dehnung (Video);Zugverformung;Transversale Dehnung (Video);Transversale Verformung 1
(sec);(mm);(N);(%);(mm/mm);(MPa);(%);(mm);(%);(mm)
0,00000;-0,00043;248,87455;1,26639;0,00001;3,11093;0,00066;0,00022;0,00513;-0,00053
0,25400;0,01468;500,12190;1,26619;-0,00001;6,25152;-0,00114;-0,00037;0,01455;-0,00149
0,52000;0,03064;802,16646;1,26635;0,00000;10,02708;-0,00001;0,00000;0,02270;-0,00233
0,80400;0,04795;1109,15165;1,26644;0,00005;13,86440;0,00520;0,00171;-0,02614;0,00268
1,09400;0,06520;1411,86934;1,26670;0,00004;17,64837;0,00355;0,00116;-0,01905;0,00195
1,39200;0,08293;1714,11943;1,26690;0,00004;21,42649;0,00438;0,00144;-0,01902;0,00195
1,69800;0,10136;2018,80395;1,26713;0,00004;25,23505;0,00370;0,00122;-0,02683;0,00275
2,01600;0,12059;2322,40297;1,26703;0,00002;29,03004;0,00248;0,00082;-0,01517;0,00155
2,34800;0,14062;2626,01875;1,26702;0,00006;32,82523;0,00603;0,00198;-0,04362;0,00447
2,70200;0,16173;2929,36563;1,26695;0,00014;36,61707;0,01437;0,00472;-0,02548;0,00261
3,06600;0,18343;3230,70846;1,26704;0,00023;40,38386;0,02256;0,00741;-0,03508;0,00360
3,43000;0,20523;3531,90288;1,26711;0,00021;44,14879;0,02123;0,00697;-0,02117;0,00217
3,79400;0,22714;3834,43058;1,26699;0,00030;47,93038;0,03044;0,01000;-0,00242;0,00025
4,15400;0,24879;4137,67084;1,26734;0,00035;51,72089;0,03512;0,01154;0,01587;-0,00163
4,51800;0,27064;4440,81500;1,26739;0,00040;55,51019;0,04004;0,01315;0,01632;-0,00167
4,88600;0,29287;4742,46874;1,26764;0,00044;59,28086;0,04439;0,01458;0,01790;-0,00184
5,28000;0,31618;5032,42314;1,26770;0,00049;62,90529;0,04887;0,01605;0,01934;-0,00198
5,68000;0,34034;5275,36780;1,26773;0,00056;65,94210;0,05573;0,01831;0,02656;-0,00272
6,08000;0,36455;5514,95165;1,26797;0,00059;68,93690;0,05851;0,01922;0,03598;-0,00369
6,48000;0,38818;5746,84292;1,26751;0,00062;71,83554;0,06160;0,02023;0,04805;-0,00493
6,88000;0,41234;5975,47889;1,26767;0,00065;74,69349;0,06492;0,02133;0,04156;-0,00426
7,28000;0,43655;6204,84933;1,26782;0,00070;77,56062;0,07000;0,02299;0,03285;-0,00337
7,68000;0,46023;6424,22676;1,26789;0,00073;80,30283;0,07289;0,02394;0,04604;-0,00472
8,08000;0,48439;6644,09325;1,26802;0,00072;83,05117;0,07242;0,02379;-0,01492;0,00153
8,48000;0,50845;6864,37637;1,26796;0,00067;85,80470;0,06700;0,02201;-0,01127;0,00116
8,88000;0,53229;7075,56948;1,26827;0,00069;88,44462;0,06862;0,02254;0,02167;-0,00222
9,28000;0,55639;7291,43634;1,26823;0,00071;91,14295;0,07124;0,02340;0,03367;-0,00345
9,68000;0,58034;7504,00722;1,26843;0,00079;93,80009;0,07950;0,02611;0,03747;-0,00384
10,08000;0,60434;7707,73262;1,26819;0,00085;96,34666;0,08456;0,02778;0,04751;-0,00487
10,48000;0,62839;7914,65521;1,26840;0,00090;98,93319;0,09001;0,02957;0,04513;-0,00463
10,88000;0,65234;8118,33143;1,26854;0,00104;101,47914;0,10418;0,03422;0,03885;-0,00398
11,28000;0,67634;8309,16166;1,26824;0,00114;103,86452;0,11390;0,03741;0,03384;-0,00347
11,68000;0,70045;8502,58648;1,26892;0,00117;106,28233;0,11748;0,03859;0,05305;-0,00544
12,08000;0,72423;8689,85206;1,26889;0,00108;108,62315;0,10796;0,03546;0,05282;-0,00542
12,48000;0,74839;8875,42605;1,26914;0,00117;110,94283;0,11660;0,03830;0,07396;-0,00758
12,88000;0,77255;9067,32738;1,26926;0,00122;113,34159;0,12242;0,04021;0,07861;-0,00806
13,28000;0,79623;9255,86969;1,26919;0,00125;115,69837;0,12548;0,04122;0,09575;-0,00982
13,68000;0,82039;9445,50365;1,26893;0,00119;118,06880;0,11886;0,03904;0,05858;-0,00601
14,08000;0,84455;9638,04066;1,26898;0,00118;120,47551;0,11824;0,03884;0,04475;-0,00459
14,48000;0,86818;9828,93080;1,26911;0,00118;122,86163;0,11832;0,03887;0,01971;-0,00202
14,88000;0,89239;10024,77318;1,26922;0,00120;125,30966;0,11950;0,03925;0,00469;-0,00048
15,28000;0,91650;10221,88783;1,26933;0,00120;127,77360;0,12018;0,03948;0,03014;-0,00309
15,68000;0,94023;10414,08420;1,26967;0,00127;130,17605;0,12674;0,04163;0,04439;-0,00455
16,08000;0,96439;10614,40140;1,26958;0,00132;132,68002;0,13157;0,04322;0,03487;-0,00358
16,48000;0,98839;10816,24389;1,26972;0,00138;135,20305;0,13780;0,04527;0,04198;-0,00430
16,88000;1,01228;11024,12313;1,26971;0,00146;137,80154;0,14601;0,04796;0,04500;-0,00461
17,28000;1,03639;11252,16275;1,26972;0,00149;140,65203;0,14903;0,04895;0,05878;-0,00603
17,68000;1,06034;11479,63732;1,26973;0,00155;143,49547;0,15490;0,05088;0,06539;-0,00670
18,08000;1,08434;11701,29150;1,26973;0,00159;146,26614;0,15887;0,05219;0,07528;-0,00772
18,48000;1,10845;11930,86803;1,27032;0,00170;149,13585;0,16990;0,05581;0,06292;-0,00645
18,88000;1,13229;12159,79546;1,27038;0,00176;151,99744;0,17616;0,05786;0,07211;-0,00739
19,28000;1,15639;12384,65041;1,27032;0,00185;154,80813;0,18501;0,06077;0,08853;-0,00908
19,68000;1,18050;12616,84477;1,27036;0,00188;157,71056;0,18789;0,06172;0,09770;-0,01002
20,08000;1,20418;12846,28451;1,27062;0,00195;160,57856;0,19482;0,06400;0,11290;-0,01157
20,48000;1,22839;13076,18380;1,27070;0,00198;163,45230;0,19821;0,06511;0,05983;-0,00613
20,88000;1,25250;13308,83324;1,27048;0,00190;166,36042;0,18968;0,06231;0,07195;-0,00738
21,28000;1,27618;13540,39907;1,27064;0,00191;169,25499;0,19084;0,06269;0,07512;-0,00770
21,68000;1,30034;13772,44860;1,27057;0,00184;172,15561;0,18425;0,06052;0,06894;-0,00707
22,08000;1,32450;14007,04443;1,27082;0,00185;175,08806;0,18495;0,06075;0,08736;-0,00896
22,48000;1,34823;14235,51500;1,27109;0,00186;177,94394;0,18594;0,06108;0,08254;-0,00846
22,88000;1,37245;14471,29905;1,27110;0,00193;180,89124;0,19290;0,06337;0,08582;-0,00880
23,28000;1,39639;14707,65799;1,27125;0,00197;183,84572;0,19652;0,06455;0,08534;-0,00875
23,68000;1,42023;14939,34542;1,27137;0,00197;186,74182;0,19683;0,06465;0,08040;-0,00824
24,08000;1,44445;15181,16891;1,27146;0,00204;189,76461;0,20397;0,06700;0,08258;-0,00847
24,48000;1,46834;15420,15195;1,27160;0,00209;192,75190;0,20934;0,06876;0,08922;-0,00915
24,88000;1,49234;15655,85196;1,27138;0,00222;195,69815;0,22183;0,07287;0,10211;-0,01047
25,28000;1,51645;15899,22309;1,27156;0,00230;198,74029;0,22983;0,07550;0,11033;-0,01131
25,68000;1,54028;16140,60938;1,27171;0,00237;201,75762;0,23659;0,07771;0,11078;-0,01136
26,08000;1,56428;16376,55973;1,27202;0,00242;204,70700;0,24159;0,07936;0,11486;-0,01178
26,48000;1,58855;16621,94431;1,27237;0,00246;207,77430;0,24646;0,08096;0,10755;-0,01103
26,88000;1,61223;16861,20450;1,27213;0,00254;210,76506;0,25364;0,08332;0,08032;-0,00823
27,28000;1,63639;17102,64981;1,27255;0,00259;213,78312;0,25866;0,08496;0,05918;-0,00607
27,68000;1,66050;17348,95527;1,27232;0,00263;216,86194;0,26297;0,08638;0,04704;-0,00482
28,08000;1,68423;17590,86549;1,27227;0,00263;219,88582;0,26344;0,08654;0,04058;-0,00416
28,48000;1,70839;17834,32424;1,27243;0,00262;222,92905;0,26215;0,08611;0,04441;-0,00455
28,88000;1,73250;18079,99492;1,27248;0,00259;225,99994;0,25860;0,08495;0,08830;-0,00905
29,28000;1,75623;18320,31369;1,27281;0,00260;229,00392;0,25968;0,08530;0,09469;-0,00971
29,68000;1,78039;18565,67860;1,27296;0,00260;232,07098;0,25965;0,08529;0,09989;-0,01024
30,08000;1,80439;18812,91032;1,27306;0,00270;235,16138;0,26954;0,08854;0,11808;-0,01211
30,48000;1,82823;19053,22909;1,27333;0,00278;238,16536;0,27812;0,09136;0,11713;-0,01201
30,88000;1,85245;19301,17428;1,27317;0,00290;241,26468;0,28997;0,09525;0,11897;-0,01220
31,28000;1,87634;19543,62988;1,27354;0,00295;244,29537;0,29527;0,09699;0,12852;-0,01318
31,68000;1,90034;19782,35185;1,27330;0,00305;247,27940;0,30520;0,10025;0,11487;-0,01178
32,08000;1,92450;20027,73821;1,27346;0,00317;250,34673;0,31737;0,10425;0,12485;-0,01280
32,48000;1,94828;20268,27335;1,27331;0,00328;253,35342;0,32824;0,10782;0,14375;-0,01474
32,88000;1,97234;20501,50394;1,27322;0,00326;256,26880;0,32628;0,10718;0,14702;-0,01507
33,28000;1,99650;20739,52675;1,27366;0,00332;259,24408;0,33224;0,10914;0,15070;-0,01545
33,68000;2,02023;20970,53111;1,27356;0,00337;262,13164;0,33686;0,11065;0,12366;-0,01268
34,08000;2,04439;21194,80312;1,27386;0,00344;264,93504;0,34358;0,11286;0,12980;-0,01331
34,48000;2,06855;21419,21461;1,27373;0,00352;267,74018;0,35206;0,11565;0,12111;-0,01242
34,88000;2,09223;21631,51860;1,27389;0,00357;270,39398;0,35675;0,11719;0,10242;-0,01050
35,28000;2,11639;21838,00757;1,27392;0,00366;272,97509;0,36571;0,12013;0,08768;-0,00899
35,68000;2,14050;22038,82635;1,27353;0,00376;275,48533;0,37618;0,12357;0,07745;-0,00794
36,08000;2,16423;22224,20275;1,27410;0,00386;277,80253;0,38573;0,12671;0,11496;-0,01179
36,48000;2,18839;22404,91033;1,27410;0,00392;280,06138;0,39214;0,12881;0,12213;-0,01252
36,88000;2,21245;22578,73893;1,27408;0,00404;282,23424;0,40427;0,13279;0,11928;-0,01223
37,28000;2,23628;22734,83276;1,27441;0,00421;284,18541;0,42066;0,13818;0,13282;-0,01362
37,68000;2,26039;22887,91358;1,27446;0,00438;286,09892;0,43784;0,14382;0,14247;-0,01461
38,08000;2,28434;23030,11179;1,27456;0,00453;287,87640;0,45292;0,14878;0,16564;-0,01698
38,48000;2,30839;23155,27260;1,27437;0,00475;289,44091;0,47536;0,15615;0,17245;-0,01768
38,88000;2,33245;23277,67789;1,27449;0,00494;290,97097;0,49422;0,16234;0,16983;-0,01741
39,28000;2,35628;23388,44061;1,27469;0,00519;292,35551;0,51893;0,17046;0,18004;-0,01846
39,68000;2,38039;23485,52585;1,27465;0,00545;293,56907;0,54497;0,17901;0,18228;-0,01869
40,08000;2,40444;23578,18186;1,27482;0,00567;294,72727;0,56726;0,18634;0,19634;-0,02013
40,48000;2,42818;23661,43227;1,27455;0,00594;295,76790;0,59412;0,19516;0,20739;-0,02126
40,88000;2,45239;23735,18407;1,27475;0,00621;296,68980;0,62076;0,20391;0,14841;-0,01522
41,28000;2,47650;23807,21748;1,27467;0,00647;297,59022;0,64673;0,21244;0,15087;-0,01547
41,68000;2,50018;23867,56718;1,27464;0,00676;298,34459;0,67630;0,22215;0,16240;-0,01665
42,08000;2,52439;23925,98212;1,27493;0,00705;299,07478;0,70462;0,23146;0,17891;-0,01834
42,48000;2,54855;23980,48639;1,27484;0,00735;299,75608;0,73461;0,24131;0,18992;-0,01947
42,88000;2,57218;24024,91808;1,27491;0,00766;300,31148;0,76566;0,25151;0,22782;-0,02336
43,28000;2,59634;24070,97340;1,27480;0,00796;300,88717;0,79616;0,26152;0,24206;-0,02482
43,68000;2,62055;24113,53469;1,27490;0,00828;301,41918;0,82806;0,27200;0,25265;-0,02590
44,08000;2,64423;24146,50977;1,27494;0,00857;301,83137;0,85713;0,28155;0,27732;-0,02843
44,48000;2,66839;24185,02450;1,27509;0,00889;302,31281;0,88902;0,29203;0,29319;-0,03006
44,88000;2,69244;24219,30850;1,27536;0,00917;302,74136;0,91685;0,30117;0,29470;-0,03021
45,28000;2,71628;24244,30668;1,27525;0,00949;303,05383;0,94879;0,31166;0,30066;-0,03083
45,68000;2,74044;24276,92413;1,27532;0,00978;303,46155;0,97782;0,32120;0,29737;-0,03049
46,08000;2,76434;24301,11229;1,27533;0,01011;303,76390;1,01094;0,33208;0,31529;-0,03232
46,48000;2,78839;24324,48685;1,27506;0,01037;304,05609;1,03718;0,34070;0,32484;-0,03330
46,88000;2,81239;24351,50564;1,27517;0,01070;304,39382;1,06985;0,35143;0,33866;-0,03472
47,28000;2,83628;24376,02818;1,27526;0,01104;304,70035;1,10390;0,36261;0,28816;-0,02954
47,68000;2,86039;24393,21041;1,27531;0,01133;304,91513;1,13258;0,37203;0,28844;-0,02957
48,08000;2,88450;24416,91935;1,27554;0,01170;305,21149;1,17041;0,38446;0,30104;-0,03086
48,48000;2,90818;24435,53567;1,27518;0,01198;305,44420;1,19762;0,39340;0,31558;-0,03235
48,88000;2,93250;24453,79794;1,27552;0,01232;305,67247;1,23208;0,40472;0,32318;-0,03313
49,28000;2,95650;24473,93596;1,27537;0,01267;305,92420;1,26689;0,41615;0,33019;-0,03385
49,68000;2,98018;24489,35151;1,27527;0,01299;306,11689;1,29927;0,42679;0,38477;-0,03945
50,08000;3,00444;24507,65848;1,27528;0,01332;306,34573;1,33223;0,43761;0,40309;-0,04133
50,48000;3,02850;24525,59710;1,27529;0,01373;306,56996;1,37254;0,45086;0,41273;-0,04232
50,88000;3,05223;24539,33001;1,27570;0,01409;306,74163;1,40890;0,46280;0,42207;-0,04327
51,28000;3,07639;24556,17785;1,27536;0,01442;306,95222;1,44228;0,47377;0,43057;-0,04414
51,68000;3,10044;24573,61579;1,27558;0,01484;307,17020;1,48360;0,48734;0,44554;-0,04568
52,08000;3,12423;24584,03170;1,27552;0,01519;307,30040;1,51919;0,49903;0,44800;-0,04593
52,48000;3,14850;24603,89793;1,27533;0,01553;307,54872;1,55291;0,51010;0,45921;-0,04708
52,88000;3,17234;24617,76316;1,27560;0,01590;307,72204;1,58999;0,52229;0,46728;-0,04791
53,28000;3,19639;24628,34537;1,27538;0,01621;307,85432;1,62050;0,53231;0,41156;-0,04220
53,68000;3,22050;24646,43061;1,27539;0,01656;308,08038;1,65567;0,54386;0,42701;-0,04378
54,08000;3,24434;24660,56406;1,27534;0,01691;308,25705;1,69075;0,55538;0,43967;-0,04508
54,48000;3,26834;24670,16101;1,27537;0,01735;308,37701;1,73474;0,56983;0,44068;-0,04518
54,88000;3,29244;24687,51490;1,27542;0,01770;308,59394;1,76967;0,58131;0,45349;-0,04649
55,28000;3,31628;24700,91164;1,27523;0,01802;308,76140;1,80186;0,59188;0,47937;-0,04915
55,68000;3,34039;24711,89797;1,27561;0,01839;308,89872;1,83917;0,60414;0,48018;-0,04923
56,08000;3,36455;24730,20315;1,27550;0,01872;309,12754;1,87230;0,61502;0,50574;-0,05185
56,48000;3,38823;24740,11838;1,27558;0,01902;309,25148;1,90168;0,62467;0,55177;-0,05657
56,88000;3,41244;24753,18968;1,27529;0,01941;309,41487;1,94091;0,63756;0,56765;-0,05820
57,28000;3,43650;24768,67318;1,27515;0,01966;309,60841;1,96631;0,64590;0,57577;-0,05903
57,68000;3,46028;24778,16820;1,27547;0,01990;309,72710;1,99008;0,65371;0,58270;-0,05974
58,08000;3,48439;24792,35530;1,27548;0,02023;309,90444;2,02316;0,66458;0,59580;-0,06109
58,48000;3,50844;24808,23398;1,27550;0,02062;310,10292;2,06165;0,67722;0,60472;-0,06200
58,88000;3,53228;24817,20865;1,27563;0,02099;310,21511;2,09851;0,68932;0,60997;-0,06254
59,28000;3,55644;24833,17494;1,27532;0,02132;310,41469;2,13249;0,70049;0,56428;-0,05785
59,68000;3,58034;24847,09740;1,27550;0,02170;310,58872;2,16976;0,71273;0,56813;-0,05825
60,08000;3,60434;24855,05819;1,27515;0,02208;310,68823;2,20782;0,72523;0,57232;-0,05868
60,48000;3,62850;24871,93644;1,27521;0,02243;310,89921;2,24305;0,73680;0,58576;-0,06006
60,88000;3,65228;24884,04036;1,27525;0,02271;311,05050;2,27087;0,74594;0,60340;-0,06186
61,28000;3,67639;24894,44375;1,27528;0,02304;311,18055;2,30362;0,75670;0,61960;-0,06352
61,68000;3,70050;24909,33359;1,27535;0,02336;311,36667;2,33626;0,76742;0,62456;-0,06403
62,08000;3,72428;24922,27435;1,27506;0,02368;311,52843;2,36839;0,77798;0,64274;-0,06590
62,48000;3,74839;24933,94017;1,27538;0,02405;311,67425;2,40459;0,78987;0,65178;-0,06682
62,88000;3,77260;24948,58503;1,27547;0,02443;311,85731;2,44309;0,80251;0,68446;-0,07017
63,28000;3,79618;24958,66299;1,27510;0,02474;311,98329;2,47428;0,81276;0,72018;-0,07384
63,68000;3,82039;24971,89343;1,27511;0,02511;312,14867;2,51113;0,82487;0,72540;-0,07437
64,08000;3,84450;24986,40776;1,27508;0,02548;312,33010;2,54828;0,83707;0,72626;-0,07446
64,48000;3,86823;24994,82095;1,27530;0,02583;312,43526;2,58343;0,84861;0,73333;-0,07519
64,88000;3,89234;25008,90613;1,27516;0,02616;312,61133;2,61649;0,85947;0,70767;-0,07255
65,28000;3,91650;25023,21839;1,27515;0,02649;312,79023;2,64858;0,87001;0,68452;-0,07018
65,68000;3,94028;25033,48231;1,27536;0,02679;312,91853;2,67881;0,87994;0,69627;-0,07139
66,08000;3,96444;25048,51878;1,27566;0,02714;313,10648;2,71412;0,89154;0,70435;-0,07221
66,48000;3,98839;25062,50918;1,27496;0,02744;313,28136;2,74447;0,90151;0,71749;-0,07356
66,88000;4,01239;25069,43822;1,27530;0,02780;313,36798;2,78006;0,91320;0,72259;-0,07408
67,28000;4,03644;25085,53326;1,27524;0,02816;313,56917;2,81636;0,92513;0,73704;-0,07556
67,68000;4,06028;25098,37568;1,27514;0,02853;313,72970;2,85258;0,93702;0,75596;-0,07750
68,08000;4,08444;25106,56357;1,27543;0,02887;313,83204;2,88696;0,94832;0,76693;-0,07863
68,48000;4,10839;25121,40691;1,27501;0,02923;314,01759;2,92343;0,96030;0,78452;-0,08043
68,88000;4,13228;25134,41026;1,27464;0,02961;314,18013;2,96065;0,97252;0,78629;-0,08061
69,28000;4,15639;25143,95356;1,27527;0,02988;314,29942;2,98788;0,98147;0,80976;-0,08302
69,68000;4,18055;25159,46746;1,27518;0,03020;314,49334;3,02047;0,99217;0,85099;-0,08725
70,08000;4,20418;25170,56108;1,27488;0,03045;314,63201;3,04518;1,00029;0,86135;-0,08831
70,48000;4,22850;25182,42896;1,27511;0,03074;314,78036;3,07373;1,00967;0,87478;-0,08969
70,88000;4,25250;25195,63794;1,27480;0,03109;314,94547;3,10873;1,02117;0,82246;-0,08432
71,28000;4,27618;25205,31893;1,27491;0,03140;315,06649;3,14012;1,03148;0,81751;-0,08382
71,68000;4,30044;25219,48457;1,27493;0,03178;315,24356;3,17780;1,04385;0,82013;-0,08408
72,08000;4,32450;25231,46331;1,27488;0,03212;315,39329;3,21165;1,05497;0,82597;-0,08468
72,48000;4,34823;25240,52739;1,27492;0,03247;315,50659;3,24662;1,06646;0,83636;-0,08575
72,88000;4,37239;25255,29027;1,27469;0,03286;315,69113;3,28600;1,07939;0,85571;-0,08773
73,28000;4,39644;25268,90159;1,27490;0,03315;315,86127;3,31528;1,08901;0,86801;-0,08899
73,68000;4,42028;25275,17617;1,27462;0,03355;315,93970;3,35463;1,10194;0,87966;-0,09019
74,08000;4,44444;25291,69142;1,27447;0,03386;316,14614;3,38576;1,11217;0,89103;-0,09135
74,48000;4,46834;25303,37512;1,27491;0,03417;316,29219;3,41698;1,12242;0,89645;-0,09191
74,88000;4,49239;25310,49013;1,27470;0,03449;316,38113;3,44921;1,13301;0,91024;-0,09332
75,28000;4,51639;25326,55120;1,27480;0,03480;316,58189;3,47973;1,14303;0,92690;-0,09503
75,68000;4,54034;25337,68058;1,27474;0,03516;316,72101;3,51597;1,15494;0,94357;-0,09674
76,08000;4,56439;25345,58594;1,27452;0,03548;316,81982;3,54803;1,16547;0,95697;-0,09811
76,48000;4,58844;25359,89463;1,27492;0,03585;316,99868;3,58451;1,17745;0,99480;-0,10199
76,88000;4,61223;25371,86444;1,27427;0,03616;317,14831;3,61599;1,18779;0,94338;-0,09672
77,28000;4,63650;25382,67374;1,27485;0,03654;317,28342;3,65431;1,20038;0,94313;-0,09669
77,68000;4,66050;25396,76607;1,27433;0,03686;317,45958;3,68624;1,21087;0,94205;-0,09658
78,08000;4,68418;25404,61600;1,27450;0,03714;317,55770;3,71382;1,21993;0,95499;-0,09791
78,48000;4,70850;25417,36901;1,27452;0,03747;317,71711;3,74657;1,23068;0,96843;-0,09929
78,88000;4,73244;25429,31557;1,27392;0,03777;317,86644;3,77663;1,24056;0,98341;-0,10082
79,28000;4,75628;25438,15613;1,27449;0,03806;317,97695;3,80599;1,25020;0,98813;-0,10131
79,68000;4,78044;25450,38342;1,27442;0,03839;318,12979;3,83934;1,26116;1,00698;-0,10324
80,08000;4,80444;25463,21869;1,27461;0,03873;318,29023;3,87269;1,27211;1,01990;-0,10457
80,48000;4,82823;25470,04402;1,27447;0,03903;318,37555;3,90258;1,28193;1,02834;-0,10543
80,88000;4,85250;25486,04429;1,27444;0,03936;318,57555;3,93608;1,29293;1,03727;-0,10635
81,28000;4,87639;25496,52278;1,27434;0,03968;318,70653;3,96790;1,30339;1,05483;-0,10815
81,68000;4,90034;25503,49295;1,27464;0,04000;318,79366;4,00040;1,31406;1,06245;-0,10893
82,08000;4,92455;25518,19324;1,27397;0,04032;318,97742;4,03206;1,32446;1,07597;-0,11031
82,48000;4,94828;25528,76651;1,27456;0,04066;319,10958;4,06579;1,33554;1,09063;-0,11182
82,88000;4,97239;25536,72731;1,27440;0,04097;319,20909;4,09727;1,34588;1,04390;-0,10703
83,28000;4,99650;25550,28856;1,27452;0,04129;319,37861;4,12904;1,35632;1,08244;-0,11098
83,68000;5,02023;25559,90875;1,27411;0,04157;319,49886;4,15745;1,36565;1,08849;-0,11160
84,08000;5,04439;25568,45427;1,27446;0,04195;319,60568;4,19460;1,37785;1,07843;-0,11057
84,48000;5,06855;25582,48401;1,27415;0,04231;319,78105;4,23055;1,38966;1,09584;-0,11235
84,88000;5,09223;25590,69872;1,27430;0,04263;319,88373;4,26328;1,40041;1,10559;-0,11335
85,28000;5,11644;25601,89605;1,27438;0,04298;320,02370;4,29846;1,41197;1,12353;-0,11519
85,68000;5,14050;25613,91592;1,27425;0,04334;320,17395;4,33443;1,42379;1,13135;-0,11599
86,08000;5,16428;25619,95447;1,27413;0,04372;320,24943;4,37236;1,43624;1,13955;-0,11683
86,48000;5,18839;25631,66142;1,27426;0,04403;320,39577;4,40289;1,44627;1,15518;-0,11844
86,88000;5,21244;25643,52572;1,27399;0,04440;320,54407;4,44010;1,45850;1,17182;-0,12014
87,28000;5,23634;25650,01488;1,27417;0,04467;320,62519;4,46692;1,46731;1,18537;-0,12153
87,68000;5,26039;25662,12595;1,27410;0,04500;320,77657;4,49975;1,47809;1,19246;-0,12226
88,08000;5,28434;25675,43864;1,27434;0,04537;320,94298;4,53679;1,49026;1,19438;-0,12245
88,48000;5,30839;25680,66180;1,27408;0,04566;321,00827;4,56585;1,49980;1,21174;-0,12423
88,88000;5,33255;25693,79747;1,27422;0,04600;321,17247;4,60034;1,51113;1,17302;-0,12026
89,28000;5,35628;25703,29964;1,27440;0,04635;321,29125;4,63473;1,52243;1,17342;-0,12030
89,68000;5,38039;25710,30200;1,27410;0,04668;321,37877;4,66838;1,53348;1,20892;-0,12394
90,08000;5,40444;25721,41349;1,27466;0,04702;321,51767;4,70233;1,54464;1,20576;-0,12362
90,48000;5,42823;25731,21786;1,27422;0,04731;321,64022;4,73084;1,55400;1,22436;-0,12553
90,88000;5,45239;25739,74013;1,27416;0,04763;321,74675;4,76262;1,56444;1,22812;-0,12591
91,28000;5,47655;25751,24860;1,27463;0,04790;321,89061;4,79015;1,57348;1,25430;-0,12860
91,68000;5,50018;25758,42798;1,27417;0,04823;321,98035;4,82295;1,58426;1,25564;-0,12873
92,08000;5,52439;25768,83852;1,27472;0,04846;322,11048;4,84619;1,59189;1,26707;-0,12991
92,48000;5,54855;25780,69925;1,27432;0,04884;322,25874;4,88360;1,60418;1,27252;-0,13047
92,88000;5,57218;25784,79409;1,27449;0,04911;322,30993;4,91149;1,61334;1,29206;-0,13247
93,28000;5,59639;25796,47958;1,27431;0,04945;322,45599;4,94517;1,62440;1,30325;-0,13362
93,68000;5,62055;25807,19054;1,27422;0,04977;322,58988;4,97704;1,63487;1,30825;-0,13413
94,08000;5,64428;25812,04534;1,27469;0,05012;322,65057;5,01183;1,64630;1,32453;-0,13580
94,48000;5,66839;25824,99146;1,27406;0,05049;322,81239;5,04887;1,65847;1,32040;-0,13537
94,88000;5,69244;25835,62553;1,27442;0,05081;322,94532;5,08064;1,66890;1,29244;-0,13251
95,28000;5,71628;25838,33098;1,27468;0,05116;322,97914;5,11624;1,68060;1,29124;-0,13239
95,68000;5,74044;25850,80147;1,27453;0,05150;323,13502;5,14993;1,69166;1,30597;-0,13390
96,08000;5,76434;25860,73816;1,27491;0,05184;323,25923;5,18432;1,70296;1,30429;-0,13372
96,48000;5,78839;25864,26258;1,27465;0,05215;323,30328;5,21492;1,71301;1,34554;-0,13795
96,88000;5,81239;25876,50239;1,27453;0,05254;323,45628;5,25370;1,72575;1,36079;-0,13952
97,28000;5,83628;25885,59151;1,27443;0,05281;323,56989;5,28107;1,73474;1,37747;-0,14123
97,68000;5,86039;25891,34216;1,27469;0,05319;323,64178;5,31852;1,74704;1,38666;-0,14217
98,08000;5,88444;25901,13580;1,27435;0,05358;323,76420;5,35805;1,76003;1,38979;-0,14249
98,48000;5,90823;25910,82573;1,27454;0,05390;323,88532;5,39026;1,77061;1,39958;-0,14349
98,88000;5,93244;25915,62867;1,27510;0,05427;323,94536;5,42737;1,78280;1,41192;-0,14476
99,28000;5,95650;25926,91898;1,27435;0,05458;324,08649;5,45788;1,79282;1,42850;-0,14646
99,68000;5,98012;25934,04293;1,27475;0,05491;324,17554;5,49148;1,80386;1,43717;-0,14735
100,08000;6,00444;25941,78557;1,27445;0,05525;324,27232;5,52466;1,81476;1,44266;-0,14791
100,48000;6,02844;25950,81389;1,27424;0,05553;324,38517;5,55341;1,82420;1,44910;-0,14857
100,88000;6,05223;25955,62935;1,27482;0,05586;324,44537;5,58644;1,83505;1,41715;-0,14529
101,28000;6,07639;25966,30454;1,27460;0,05622;324,57881;5,62172;1,84664;1,42157;-0,14575
101,68000;6,10050;25975,49021;1,27488;0,05656;324,69363;5,65565;1,85779;1,43916;-0,14755
102,08000;6,12423;25978,52468;1,27482;0,05684;324,73156;5,68399;1,86709;1,44105;-0,14774
102,48000;6,14850;25990,63933;1,27470;0,05716;324,88299;5,71646;1,87776;1,44705;-0,14836
102,88000;6,17239;25997,80977;1,27478;0,05755;324,97262;5,75485;1,89037;1,46232;-0,14992
103,28000;6,19628;26000,27025;1,27451;0,05781;325,00338;5,78064;1,89884;1,49644;-0,15342
103,68000;6,22050;26013,64911;1,27485;0,05811;325,17061;5,81074;1,90873;1,50823;-0,15463
104,08000;6,24434;26020,32959;1,27483;0,05843;325,25412;5,84310;1,91936;1,51640;-0,15547
104,48000;6,26839;26024,10614;1,27472;0,05873;325,30133;5,87253;1,92903;1,54202;-0,15810
104,88000;6,29244;26035,33924;1,27503;0,05905;325,44174;5,90539;1,93982;1,54375;-0,15827
105,28001;6,31634;26042,04118;1,27449;0,05936;325,52551;5,93553;1,94972;1,55769;-0,15970
105,68001;6,34039;26046,27550;1,27482;0,05971;325,57844;5,97099;1,96137;1,55912;-0,15985
106,08001;6,36455;26057,44421;1,27460;0,06005;325,71805;6,00460;1,97241;1,57475;-0,16145
106,48001;6,38817;26060,89890;1,27474;0,06038;325,76124;6,03764;1,98326;1,58099;-0,16209
106,88001;6,41244;26068,25531;1,27490;0,06075;325,85319;6,07500;1,99553;1,55218;-0,15914
107,28001;6,43650;26077,84510;1,27479;0,06114;325,97306;6,11375;2,00826;1,55809;-0,15974
107,68001;6,46028;26080,98865;1,27488;0,06146;326,01236;6,14626;2,01894;1,56832;-0,16079
108,08001;6,48444;26089,18905;1,27487;0,06180;326,11486;6,18001;2,03003;1,57390;-0,16136
108,48001;6,50844;26096,83692;1,27487;0,06215;326,21046;6,21473;2,04143;1,58841;-0,16285
108,88001;6,53233;26100,85487;1,27501;0,06249;326,26069;6,24899;2,05269;1,59018;-0,16303
109,28001;6,55644;26110,73971;1,27459;0,06285;326,38425;6,28469;2,06442;1,59907;-0,16395
109,68001;6,58033;26117,98346;1,27520;0,06321;326,47479;6,32082;2,07628;1,64966;-0,16913
110,08001;6,60433;26119,54093;1,27492;0,06359;326,49426;6,35900;2,08882;1,65776;-0,16996
110,48001;6,62855;26129,26662;1,27500;0,06392;326,61583;6,39178;2,09959;1,66416;-0,17062
110,88001;6,65228;26135,52868;1,27484;0,06427;326,69411;6,42663;2,11104;1,68074;-0,17232
111,28001;6,67639;26139,62531;1,27491;0,06462;326,74532;6,46231;2,12276;1,70251;-0,17455
111,68001;6,70044;26147,46094;1,27508;0,06494;326,84326;6,49447;2,13332;1,70720;-0,17503
112,08001;6,72428;26153,69618;1,27482;0,06528;326,92120;6,52783;2,14428;1,72833;-0,17720
112,48001;6,74839;26158,38289;1,27512;0,06560;326,97979;6,56025;2,15493;1,72481;-0,17684
112,88001;6,77260;26167,14478;1,27503;0,06594;327,08931;6,59433;2,16613;1,73318;-0,17769
113,28001;6,79617;26170,69066;1,27506;0,06629;327,13363;6,62914;2,17756;1,70373;-0,17467
113,68001;6,82039;26176,79894;1,27498;0,06665;327,20999;6,66492;2,18931;1,70963;-0,17528
114,08001;6,84455;26184,62563;1,27495;0,06697;327,30782;6,69661;2,19972;1,72047;-0,17639
114,48001;6,86817;26185,99355;1,27510;0,06732;327,32492;6,73210;2,21138;1,72848;-0,17721
114,88001;6,89239;26192,57569;1,27506;0,06762;327,40720;6,76194;2,22118;1,74128;-0,17853
115,28001;6,91650;26201,34830;1,27508;0,06794;327,51685;6,79371;2,23162;1,74615;-0,17902
115,68001;6,94033;26203,67825;1,27528;0,06828;327,54598;6,82842;2,24302;1,76641;-0,18110
116,08001;6,96439;26210,38020;1,27515;0,06856;327,62975;6,85613;2,25212;1,79861;-0,18440
116,48001;6,98839;26218,90068;1,27534;0,06891;327,73626;6,89091;2,26355;1,82001;-0,18660
116,88001;7,01228;26217,45408;1,27503;0,06920;327,71818;6,92034;2,27321;1,82488;-0,18710
117,28001;7,03644;26227,22268;1,27545;0,06957;327,84028;6,95654;2,28511;1,84303;-0,18896
117,68001;7,06028;26232,73551;1,27541;0,06994;327,90919;6,99427;2,29750;1,85687;-0,19038
118,08001;7,08444;26233,52408;1,27517;0,07030;327,91905;7,03044;2,30938;1,87237;-0,19197
118,48001;7,10839;26241,30785;1,27552;0,07063;328,01635;7,06341;2,32021;1,87030;-0,19175
118,88001;7,13228;26248,01338;1,27517;0,07101;328,10017;7,10059;2,33242;1,88278;-0,19303
119,28001;7,15644;26250,99421;1,27537;0,07134;328,13743;7,13408;2,34342;1,85650;-0,19034
119,68001;7,18055;26257,39574;1,27550;0,07172;328,21745;7,17229;2,35597;1,86510;-0,19122
120,08001;7,20423;26262,07352;1,27542;0,07206;328,27592;7,20607;2,36707;1,86387;-0,19109
120,48001;7,22839;26264,16206;1,27559;0,07238;328,30203;7,23787;2,37752;1,87539;-0,19227
120,88001;7,25255;26273,13137;1,27538;0,07272;328,41414;7,27232;2,38883;1,88738;-0,19350
121,28001;7,27612;26273,78225;1,27560;0,07308;328,42228;7,30835;2,40067;1,89935;-0,19473
121,68001;7,30044;26278,88024;1,27537;0,07343;328,48600;7,34269;2,41195;1,90455;-0,19526
122,08001;7,32450;26285,51602;1,27546;0,07381;328,56895;7,38144;2,42468;1,91688;-0,19653
122,48001;7,34828;26286,08823;1,27567;0,07417;328,57610;7,41738;2,43648;1,93600;-0,19849
122,88001;7,37239;26293,64669;1,27561;0,07456;328,67058;7,45642;2,44931;1,97626;-0,20262
123,28001;7,39644;26299,67451;1,27581;0,07493;328,74593;7,49290;2,46129;1,99862;-0,20491
123,68001;7,42028;26298,91098;1,27574;0,07528;328,73639;7,52796;2,47281;2,00471;-0,20553
124,08001;7,44444;26307,32596;1,27587;0,07561;328,84157;7,56086;2,48361;2,01537;-0,20663
124,48001;7,46844;26312,61528;1,27585;0,07596;328,90769;7,59593;2,49513;2,02925;-0,20805
124,88001;7,49233;26309,94380;1,27573;0,07628;328,87430;7,62816;2,50572;2,03899;-0,20905
125,28001;7,51644;26319,34941;1,27584;0,07662;328,99187;7,66174;2,51675;1,99825;-0,20487
125,68001;7,54033;26322,76654;1,27579;0,07695;329,03458;7,69460;2,52755;2,00345;-0,20540
126,08001;7,56439;26322,36242;1,27581;0,07733;329,02953;7,73276;2,54008;2,02321;-0,20743
126,48001;7,58839;26330,45554;1,27609;0,07764;329,13069;7,76433;2,55045;2,02913;-0,20804
126,88001;7,61223;26335,14583;1,27597;0,07799;329,18932;7,79913;2,56188;2,02102;-0,20721
127,28001;7,63644;26335,80208;1,27587;0,07834;329,19753;7,83385;2,57329;2,04587;-0,20975
127,68001;7,66050;26342,49330;1,27554;0,07868;329,28117;7,86765;2,58439;2,04641;-0,20981
128,08001;7,68417;26343,58227;1,27579;0,07901;329,29478;7,90146;2,59550;2,06038;-0,21124
128,48001;7,70850;26347,74506;1,27565;0,07934;329,34681;7,93401;2,60619;2,07761;-0,21301
128,88001;7,73244;26352,66244;1,27562;0,07967;329,40828;7,96674;2,61694;2,09386;-0,21467
129,28001;7,75623;26353,70314;1,27586;0,07999;329,42129;7,99890;2,62750;2,12023;-0,21738
129,68001;7,78044;26358,44171;1,27602;0,08033;329,48052;8,03256;2,63856;2,14867;-0,22029
130,08001;7,80444;26362,70106;1,27573;0,08071;329,53376;8,07068;2,65108;2,16278;-0,22174
130,48001;7,82833;26363,42168;1,27576;0,08109;329,54277;8,10910;2,66370;2,16549;-0,22202
130,88001;7,85244;26369,09902;1,27568;0,08147;329,61374;8,14713;2,67619;2,17421;-0,22291
131,28001;7,87639;26373,31188;1,27584;0,08183;329,66640;8,18257;2,68784;2,14766;-0,22019
131,68001;7,90033;26371,04094;1,27575;0,08221;329,63801;8,22142;2,70060;2,15717;-0,22116
132,08001;7,92455;26378,13985;1,27599;0,08260;329,72675;8,25981;2,71321;2,15777;-0,22123
132,48001;7,94828;26380,27489;1,27556;0,08295;329,75344;8,29486;2,72472;2,16502;-0,22197
132,88001;7,97239;26380,93114;1,27543;0,08326;329,76164;8,32611;2,73499;2,18271;-0,22378
133,28001;7,99644;26387,40957;1,27567;0,08360;329,84262;8,36018;2,74618;2,18885;-0,22441
133,68001;8,02028;26389,84680;1,27543;0,08396;329,87309;8,39585;2,75789;2,19652;-0,22520
134,08001;8,04439;26390,30278;1,27574;0,08430;329,87878;8,43017;2,76917;2,20663;-0,22624
134,48001;8,06855;26397,31944;1,27557;0,08465;329,96649;8,46487;2,78057;2,22058;-0,22767
134,88001;8,09223;26397,68422;1,27559;0,08505;329,97105;8,50502;2,79375;2,24389;-0,23006
135,28001;8,11639;26399,10221;1,27569;0,08545;329,98878;8,54486;2,80684;2,24985;-0,23067
135,68001;8,14049;26406,02589;1,27530;0,08581;330,07532;8,58060;2,81858;2,26076;-0,23179
136,08001;8,16428;26402,61590;1,27547;0,08620;330,03270;8,62017;2,83158;2,28523;-0,23429
136,48001;8,18844;26407,17030;1,27551;0,08654;330,08963;8,65395;2,84267;2,31091;-0,23693
136,88001;8,21239;26411,23116;1,27556;0,08689;330,14039;8,68936;2,85431;2,33142;-0,23903
137,28001;8,23639;26411,50296;1,27545;0,08720;330,14379;8,71985;2,86432;2,29340;-0,23513
137,68001;8,26033;26415,49945;1,27548;0,08753;330,19374;8,75348;2,87537;2,30714;-0,23654
138,08001;8,28433;26419,05785;1,27532;0,08789;330,23822;8,78937;2,88716;2,31585;-0,23743
138,48001;8,30839;26417,86337;1,27520;0,08820;330,22329;8,81981;2,89716;2,31942;-0,23780
138,88001;8,33249;26422,06192;1,27542;0,08856;330,27577;8,85560;2,90891;2,31939;-0,23780
139,28001;8,35623;26424,33465;1,27520;0,08891;330,30418;8,89090;2,92051;2,33342;-0,23923
139,68001;8,38044;26422,60194;1,27531;0,08931;330,28252;8,93117;2,93374;2,33941;-0,23985
140,08001;8,40449;26427,97530;1,27531;0,08967;330,34969;8,96660;2,94537;2,35606;-0,24156
140,48001;8,42823;26429,26633;1,27511;0,09005;330,36583;9,00465;2,95787;2,37308;-0,24330
140,88001;8,45244;26430,76837;1,27530;0,09039;330,38460;9,03895;2,96914;2,39117;-0,24516
141,28001;8,47649;26433,74741;1,27512;0,09074;330,42184;9,07440;2,98079;2,40177;-0,24624
141,68001;8,50017;26434,00669;1,27499;0,09105;330,42508;9,10524;2,99092;2,41496;-0,24759
142,08001;8,52433;26435,78589;1,27517;0,09144;330,44732;9,14425;3,00373;2,42268;-0,24839
142,48001;8,54860;26440,78553;1,27497;0,09177;330,50982;9,17728;3,01458;2,43219;-0,24936
142,88001;8,57217;26437,40058;1,27507;0,09214;330,46751;9,21359;3,02651;2,44514;-0,25069
143,28001;8,59639;26440,65678;1,27480;0,09256;330,50821;9,25570;3,04034;2,48036;-0,25430
143,68001;8,62044;26442,48426;1,27478;0,09292;330,53105;9,29204;3,05228;2,45617;-0,25182
144,08001;8,64428;26440,75871;1,27507;0,09333;330,50948;9,33265;3,06562;2,46080;-0,25229
144,48001;8,66839;26447,46959;1,27472;0,09373;330,59337;9,37294;3,07885;2,47540;-0,25379
144,88001;8,69244;26448,21525;1,27508;0,09397;330,60269;9,39732;3,08686;2,48022;-0,25429
145,28001;8,71633;26445,89961;1,27478;0,09446;330,57375;9,44551;3,10269;2,49191;-0,25548
145,68001;8,74039;26449,59748;1,27480;0,09482;330,61997;9,48153;3,11452;2,49641;-0,25594
146,08001;8,76444;26455,56986;1,27476;0,09518;330,69462;9,51768;3,12640;2,50348;-0,25667
146,48001;8,78833;26448,36903;1,27456;0,09549;330,60461;9,54946;3,13683;2,52361;-0,25873
146,88001;8,81249;26454,30028;1,27473;0,09589;330,67875;9,58858;3,14968;2,53032;-0,25942
147,28001;8,83628;26455,40714;1,27479;0,09625;330,69259;9,62465;3,16153;2,55126;-0,26157
147,68001;8,86044;26453,35793;1,27482;0,09662;330,66697;9,66171;3,17371;2,56832;-0,26332
148,08001;8,88439;26456,18141;1,27474;0,09703;330,70227;9,70252;3,18711;2,58128;-0,26465
148,48001;8,90828;26457,83722;1,27458;0,09742;330,72297;9,74202;3,20009;2,57951;-0,26446
148,88001;8,93244;26457,23999;1,27465;0,09778;330,71550;9,77810;3,21194;2,59157;-0,26570
149,28001;8,95655;26460,70540;1,27447;0,09801;330,75882;9,80124;3,21954;2,60082;-0,26665
149,68001;8,98017;26458,85825;1,27447;0,09849;330,73573;9,84855;3,23508;2,57291;-0,26379
150,08001;9,00444;26460,19578;1,27455;0,09883;330,75245;9,88327;3,24649;2,57335;-0,26383
150,48001;9,02849;26462,55970;1,27442;0,09916;330,78200;9,91616;3,25729;2,60985;-0,26758
150,88001;9,05217;26459,37860;1,27464;0,09951;330,74223;9,95148;3,26889;2,62235;-0,26886
151,28001;9,07644;26463,91332;1,27437;0,09990;330,79892;9,98973;3,28146;2,64108;-0,27078
151,68001;9,10044;26464,60354;1,27456;0,10021;330,80754;10,02130;3,29183;2,64973;-0,27166
152,08001;9,12433;26462,96918;1,27440;0,10064;330,78711;10,06365;3,30574;2,64943;-0,27163
152,48001;9,14844;26466,22896;1,27446;0,10101;330,82786;10,10088;3,31797;2,67401;-0,27415
152,88001;9,17239;26467,55576;1,27463;0,10134;330,84445;10,13372;3,32875;2,68007;-0,27477
153,28001;9,19628;26461,97855;1,27409;0,10165;330,77473;10,16487;3,33899;2,70183;-0,27701
153,68001;9,22049;26467,04257;1,27451;0,10201;330,83803;10,20132;3,35096;2,71448;-0,27830
154,08001;9,24428;26466,48109;1,27419;0,10241;330,83101;10,24091;3,36397;2,73101;-0,28000
154,48001;9,26839;26462,94773;1,27419;0,10280;330,78685;10,27987;3,37676;2,75136;-0,28208
154,88001;9,29239;26466,54904;1,27412;0,10321;330,83186;10,32057;3,39013;2,74946;-0,28189
155,28001;9,31633;26467,52357;1,27416;0,10356;330,84404;10,35604;3,40178;2,76095;-0,28307
155,68001;9,34044;26466,12167;1,27427;0,10395;330,82652;10,39507;3,41460;2,74515;-0,28145
156,08001;9,36449;26469,26343;1,27415;0,10434;330,86579;10,43429;3,42749;2,73129;-0,28003
156,48001;9,38823;26466,67421;1,27405;0,10475;330,83343;10,47483;3,44080;2,73270;-0,28017
156,88001;9,41233;26464,75732;1,27414;0,10513;330,80947;10,51347;3,45350;2,73845;-0,28076
157,28001;9,43649;26468,97018;1,27339;0,10546;330,86213;10,54634;3,46429;2,76022;-0,28299
157,68001;9,46023;26465,41178;1,27458;0,10582;330,81765;10,58229;3,47610;2,80003;-0,28707
158,08001;9,48444;26465,89816;1,27376;0,10620;330,82373;10,61980;3,48843;2,80612;-0,28770
158,48001;9,50839;26466,71176;1,27419;0,10654;330,83390;10,65436;3,49978;2,82025;-0,28915
158,88001;9,53233;26465,35456;1,27418;0,10707;330,81693;10,70700;3,51707;2,84604;-0,29179
159,28001;9,55633;26466,23611;1,27399;0,10742;330,82795;10,74235;3,52868;2,85721;-0,29294
159,68001;9,58033;26467,28396;1,27401;0,10779;330,84105;10,77864;3,54060;2,87282;-0,29454
160,08001;9,60433;26463,14979;1,27373;0,10821;330,78937;10,82138;3,55464;2,88627;-0,29592
160,48001;9,62849;26465,16860;1,27396;0,10861;330,81461;10,86097;3,56765;2,90352;-0,29768
160,88001;9,65228;26465,31701;1,27391;0,10894;330,81646;10,89382;3,57843;2,90634;-0,29797
161,28001;9,67639;26461,82477;1,27396;0,10934;330,77281;10,93449;3,59179;2,91862;-0,29923
161,68001;9,70049;26464,21731;1,27415;0,10969;330,80272;10,96861;3,60300;2,92572;-0,29996
162,08001;9,72428;26462,97991;1,27385;0,11005;330,78725;11,00532;3,61506;2,90491;-0,29783
162,48001;9,74839;26461,90882;1,27400;0,11042;330,77386;11,04163;3,62699;2,90974;-0,29832
162,88001;9,77260;26463,55033;1,27395;0,11077;330,79438;11,07695;3,63859;2,90982;-0,29833
163,28001;9,79622;26461,00581;1,27402;0,11121;330,76257;11,12097;3,65305;2,90581;-0,29792
163,68001;9,82039;26459,83279;1,27406;0,11164;330,74791;11,16365;3,66707;2,90924;-0,29827
164,08001;9,84455;26461,26330;1,27367;0,11199;330,76579;11,19933;3,67879;2,93504;-0,30092
164,48001;9,86817;26456,89666;1,27402;0,11238;330,71121;11,23850;3,69166;2,94960;-0,30241
164,88001;9,89239;26456,95746;1,27390;0,11281;330,71197;11,28127;3,70570;2,97142;-0,30465
165,28001;9,91644;26457,37410;1,27395;0,11310;330,71718;11,31015;3,71519;3,01675;-0,30929
165,68001;9,94033;26454,28956;1,27398;0,11349;330,67862;11,34898;3,72795;3,03051;-0,31070
166,08001;9,96444;26455,83808;1,27411;0,11384;330,69798;11,38428;3,73954;3,04504;-0,31219
166,48001;9,98839;26456,67493;1,27418;0,11422;330,70844;11,42183;3,75188;3,06759;-0,31451
166,88001;10,01239;26449,94438;1,27403;0,11460;330,62430;11,46007;3,76444;3,09255;-0,31706
167,28001;10,03644;26451,72000;1,27411;0,11498;330,64650;11,49770;3,77680;3,09320;-0,31713
167,68001;10,06033;26452,38519;1,27397;0,11547;330,65481;11,54718;3,79305;3,10380;-0,31822
168,08001;10,08439;26445,50800;1,27372;0,11586;330,56885;11,58550;3,80564;3,11193;-0,31905
168,48001;10,10849;26448,11153;1,27390;0,11624;330,60139;11,62395;3,81827;3,12515;-0,32041
168,88001;10,13222;26446,74718;1,27399;0,11669;330,58434;11,66879;3,83300;3,09860;-0,31768
169,28001;10,15649;26444,67473;1,27407;0,11708;330,55843;11,70828;3,84597;3,09473;-0,31729
169,68001;10,18049;26445,30416;1,27427;0,11744;330,56630;11,74390;3,85767;3,10529;-0,31837
170,08001;10,20423;26442,09802;1,27402;0,11785;330,52623;11,78476;3,87109;3,11684;-0,31955
170,48001;10,22844;26439,72337;1,27407;0,11823;330,49654;11,82308;3,88368;3,11955;-0,31983
170,88001;10,25255;26440,13643;1,27374;0,11869;330,50171;11,86894;3,89875;3,13092;-0,32100
171,28001;10,27612;26435,68218;1,27420;0,11904;330,44603;11,90379;3,91019;3,15062;-0,32302
171,68001;10,30044;26434,46982;1,27407;0,11945;330,43087;11,94490;3,92370;3,16474;-0,32447
172,08001;10,32455;26434,68618;1,27399;0,11994;330,43358;11,99406;3,93984;3,18409;-0,32645
172,48001;10,34823;26428,69234;1,27428;0,12042;330,35865;12,04182;3,95553;3,20810;-0,32891
172,88001;10,37239;26431,26726;1,27382;0,12080;330,39084;12,08042;3,96821;3,23223;-0,33139
173,28001;10,39639;26429,29137;1,27383;0,12119;330,36614;12,11943;3,98103;3,25552;-0,33377
173,68001;10,42033;26424,30782;1,27376;0,12157;330,30385;12,15746;3,99352;3,28754;-0,33706
174,08001;10,44444;26425,43793;1,27400;0,12205;330,31797;12,20535;4,00925;3,30339;-0,33868
174,48001;10,46839;26423,91443;1,27415;0,12242;330,29893;12,24208;4,02131;3,30815;-0,33917
174,88001;10,49233;26416,43822;1,27389;0,12284;330,20548;12,28428;4,03518;3,32866;-0,34127
175,28001;10,51644;26417,74356;1,27419;0,12324;330,22179;12,32402;4,04823;3,34429;-0,34287
175,68001;10,54028;26415,68363;1,27388;0,12365;330,19605;12,36510;4,06172;3,35885;-0,34437
176,08001;10,56444;26410,14934;1,27393;0,12407;330,12687;12,40680;4,07542;3,34654;-0,34311
176,48001;10,58839;26410,32100;1,27414;0,12461;330,12901;12,46120;4,09329;3,33534;-0,34196
176,88001;10,61228;26407,91237;1,27391;0,12506;330,09890;12,50641;4,10814;3,34809;-0,34326
177,28001;10,63644;26404,09827;1,27420;0,12545;330,05123;12,54545;4,12097;3,35079;-0,34354
177,68001;10,66049;26402,86803;1,27399;0,12582;330,03585;12,58219;4,13304;3,35734;-0,34421
178,08001;10,68423;26397,78972;1,27379;0,12623;329,97237;12,62319;4,14650;3,37795;-0,34633
178,48001;10,70844;26394,54246;1,27373;0,12671;329,93178;12,67092;4,16218;3,39056;-0,34762
178,88001;10,73249;26393,36765;1,27393;0,12712;329,91710;12,71193;4,17565;3,41439;-0,35006
179,28001;10,75617;26387,52759;1,27406;0,12755;329,84409;12,75486;4,18976;3,43518;-0,35219
179,68001;10,78049;26386,43861;1,27395;0,12797;329,83048;12,79731;4,20370;3,45271;-0,35399
180,08001;10,80444;26384,60219;1,27421;0,12839;329,80753;12,83933;4,21750;3,46601;-0,35535
180,48001;10,82828;26377,84660;1,27401;0,12885;329,72308;12,88494;4,23248;3,49396;-0,35822
180,88001;10,85244;26376,35350;1,27396;0,12940;329,70442;12,94013;4,25061;3,51854;-0,36074
181,28001;10,87633;26372,68066;1,27403;0,12979;329,65851;12,97878;4,26331;3,53118;-0,36204
181,68001;10,90033;26365,73911;1,27361;0,13022;329,57174;13,02229;4,27760;3,55096;-0,36406
182,08001;10,92455;26365,26704;1,27422;0,13071;329,56584;13,07142;4,29374;3,55947;-0,36494
182,48001;10,94828;26360,14581;1,27421;0,13113;329,50182;13,11333;4,30751;3,58564;-0,36762
182,88001;10,97239;26353,21319;1,27407;0,13163;329,41516;13,16259;4,32369;3,60846;-0,36996
183,28001;10,99649;26352,73933;1,27413;0,13208;329,40924;13,20767;4,33849;3,62273;-0,37142
183,68001;11,02028;26346,07852;1,27390;0,13254;329,32598;13,25369;4,35361;3,66278;-0,37553
184,08001;11,04439;26339,57863;1,27413;0,13302;329,24473;13,30165;4,36937;3,68415;-0,37772
184,48001;11,06849;26338,38594;1,27396;0,13349;329,22982;13,34909;4,38495;3,70426;-0,37978
184,88001;11,09228;26330,21772;1,27401;0,13408;329,12772;13,40845;4,40445;3,67920;-0,37721
185,28001;11,11638;26324,48673;1,27423;0,13449;329,05608;13,44919;4,41783;3,70313;-0,37966
185,68001;11,14055;26321,91360;1,27374;0,13503;329,02392;13,50299;4,43550;3,71535;-0,38092
186,08001;11,16422;26310,68051;1,27400;0,13554;328,88351;13,55441;4,45239;3,73768;-0,38321
186,48001;11,18844;26305,57179;1,27383;0,13606;328,81965;13,60637;4,46946;3,76035;-0,38553
186,88001;11,21239;26300,65620;1,27407;0,13661;328,75820;13,66051;4,48724;3,77706;-0,38724
187,28001;11,23638;26290,79282;1,27402;0,13713;328,63491;13,71316;4,50454;3,80069;-0,38967
187,68001;11,26038;26285,59291;1,27376;0,13765;328,56991;13,76456;4,52142;3,82567;-0,39223
188,08001;11,28433;26278,29373;1,27423;0,13817;328,47867;13,81719;4,53871;3,85946;-0,39569
188,48001;11,30839;26266,63148;1,27408;0,13871;328,33289;13,87058;4,55625;3,87845;-0,39764
188,88001;11,33249;26259,38237;1,27389;0,13946;328,24228;13,94606;4,58104;3,90819;-0,40069
189,28001;11,35633;26251,53065;1,27388;0,13991;328,14413;13,99099;4,59580;3,92750;-0,40267
189,68001;11,38033;26237,87642;1,27387;0,14049;327,97346;14,04872;4,61476;3,95295;-0,40528
190,08001;11,40455;26231,90403;1,27420;0,14105;327,89880;14,10539;4,63338;3,97717;-0,40776
190,48001;11,42817;26218,96863;1,27409;0,14171;327,73711;14,17073;4,65484;3,99422;-0,40951
190,88001;11,45249;26207,77488;1,27420;0,14228;327,59719;14,22810;4,67369;4,02245;-0,41240
191,28001;11,47649;26195,49572;1,27391;0,14289;327,44370;14,28890;4,69366;4,04244;-0,41445
191,68001;11,50017;26181,05114;1,27417;0,14350;327,26314;14,34983;4,71368;4,06650;-0,41692
192,08001;11,52439;26167,83500;1,27435;0,14412;327,09794;14,41215;4,73415;4,10453;-0,42082
192,48001;11,54860;26156,18706;1,27419;0,14489;326,95234;14,48904;4,75940;4,12349;-0,42276
192,88001;11,57217;26136,38878;1,27419;0,14552;326,70486;14,55174;4,78000;4,14504;-0,42497
193,28001;11,59639;26122,46633;1,27414;0,14611;326,53083;14,61130;4,79956;4,16996;-0,42753
193,68001;11,62055;26107,65696;1,27413;0,14675;326,34571;14,67545;4,82063;4,19860;-0,43046
194,08001;11,64422;26085,25157;1,27435;0,14743;326,06564;14,74313;4,84287;4,22719;-0,43339
194,48001;11,66839;26070,63711;1,27393;0,14812;325,88296;14,81159;4,86536;4,25404;-0,43615
194,88001;11,69244;26052,19781;1,27438;0,14881;325,65247;14,88091;4,88813;4,27865;-0,43867
195,28001;11,71633;26026,85273;1,27434;0,14954;325,33566;14,95441;4,91227;4,30114;-0,44098
195,68001;11,74033;26008,30793;1,27450;0,15028;325,10385;15,02781;4,93638;4,28546;-0,43937
196,08001;11,76439;25987,50472;1,27454;0,15091;324,84381;15,09088;4,95710;4,30627;-0,44150
196,48001;11,78839;25958,83191;1,27410;0,15164;324,48540;15,16401;4,98112;4,33577;-0,44453
196,88001;11,81249;25936,01346;1,27452;0,15234;324,20017;15,23438;5,00423;4,35370;-0,44636
197,28001;11,83628;25909,59013;1,27439;0,15310;323,86988;15,30993;5,02905;4,37728;-0,44878
197,68001;11,86038;25877,97225;1,27440;0,15384;323,47465;15,38382;5,05332;4,40121;-0,45124
198,08001;11,88444;25851,99952;1,27459;0,15454;323,14999;15,45424;5,07646;4,42769;-0,45395
198,48001;11,90828;25819,75937;1,27455;0,15544;322,74699;15,54374;5,10586;4,45174;-0,45642
198,88001;11,93244;25785,77757;1,27469;0,15621;322,32222;15,62111;5,13127;4,46534;-0,45781
199,28001;11,95655;25753,40152;1,27449;0,15688;321,91752;15,68766;5,15313;4,49897;-0,46126
199,68001;11,98017;25716,42458;1,27439;0,15756;321,45531;15,75649;5,17574;4,51457;-0,46286
200,08001;12,00444;25676,91386;1,27436;0,15836;320,96142;15,83586;5,20181;4,53406;-0,46486
200,48001;12,02855;25637,24756;1,27470;0,15914;320,46559;15,91384;5,22743;4,55189;-0,46668
200,88001;12,05217;25589,20562;1,27459;0,15985;319,86507;15,98535;5,25092;4,57073;-0,46861
201,28001;12,07649;25543,23792;1,27443;0,16080;319,29047;16,07960;5,28188;4,58597;-0,47018
201,68001;12,10039;25481,88329;1,27453;0,16162;318,52354;16,16184;5,30889;4,59279;-0,47088
202,08001;12,12433;25393,71729;1,27458;0,16250;317,42147;16,25010;5,33788;4,60963;-0,47260
202,34601;12,14051;25117,95044;1,27453;0,16332;313,97438;16,33203;5,36480;4,60906;-0,47254
202,37601;12,14308;23749,87543;1,27595;0,16354;296,87344;16,35784;5,37191;4,58076;-0,46964
202,38401;12,14560;19104,58624;1,30100;0,16358;238,80733;16,35784;5,37328;4,55669;-0,46718
202,39001;12,14742;14839,38307;1,35706;0,16361;185,49229;16,35784;5,37428;4,53503;-0,46495