File: Data_Alu 6082 für NiGü/6082Alu_Zugprüfung.is_tens_RawData.csv/Specimen_RawData_4.csv
Prüflosbezeichnung;"Redux 312_quer+längs_alte Proben"
Proben-Nr;"4"
Prüfer;"JuBr"
Werkstoff;"6082"
Prüfnorm;"DIN EN ISO 527                                                   "
Prüfgeschwindigkeit;3,6;mm/min
Prüfklima;"23 °C / 50 % rF"
Bemerkungen;""

Zeit;Traversenweg;Last;Dehnung 1;Zugdehnung;Zugspannung;Axiale Dehnung (Video);Zugverformung;Transversale Dehnung (Video);Transversale Verformung 1
(sec);(mm);(N);(%);(mm/mm);(MPa);(%);(mm);(%);(mm)
0,00000;-0,00021;248,90182;1,28185;0,00002;3,11127;0,00171;0,00059;-0,00268;0,00027
0,27600;0,01639;509,47102;1,28039;0,00007;6,36839;0,00723;0,00248;0,00627;-0,00063
0,55400;0,03295;815,28207;1,28277;0,00015;10,19103;0,01526;0,00524;0,01787;-0,00180
0,85600;0,05095;1119,76650;1,28259;0,00016;13,99708;0,01562;0,00536;0,03334;-0,00336
1,21000;0,07227;1423,52588;1,28282;0,00021;17,79407;0,02122;0,00728;0,03423;-0,00345
1,56800;0,09380;1726,16489;1,28284;0,00024;21,57706;0,02410;0,00827;0,04263;-0,00430
1,95200;0,11695;2028,54998;1,28316;0,00023;25,35687;0,02284;0,00783;0,04476;-0,00451
2,33400;0,13982;2330,81929;1,28275;0,00024;29,13524;0,02379;0,00816;0,02557;-0,00258
2,73200;0,16355;2623,67897;1,28303;0,00030;32,79599;0,02988;0,01025;0,01002;-0,00101
3,13200;0,18766;2904,19713;1,28303;0,00032;36,30246;0,03178;0,01090;0,00281;-0,00028
3,53200;0,21171;3178,92171;1,28295;0,00034;39,73652;0,03393;0,01164;0,00844;-0,00085
3,93200;0,23561;3437,11026;1,28317;0,00038;42,96388;0,03783;0,01297;0,01460;-0,00147
4,33200;0,25971;3694,62490;1,28318;0,00039;46,18281;0,03907;0,01340;0,04348;-0,00438
4,73200;0,28361;3941,41227;1,28313;0,00045;49,26765;0,04490;0,01540;0,03828;-0,00386
5,13200;0,30766;4176,26828;1,28354;0,00052;52,20335;0,05189;0,01780;0,04739;-0,00478
5,53200;0,33177;4409,97854;1,28352;0,00059;55,12473;0,05854;0,02008;0,05555;-0,00560
5,93200;0,35555;4634,17277;1,28366;0,00059;57,92716;0,05870;0,02013;0,07184;-0,00724
6,33200;0,37966;4847,63861;1,28371;0,00062;60,59548;0,06223;0,02134;0,08975;-0,00905
6,73200;0,40382;5059,47948;1,28376;0,00064;63,24349;0,06374;0,02186;0,07822;-0,00788
7,13200;0,42750;5261,20752;1,28355;0,00066;65,76509;0,06649;0,02281;0,07915;-0,00798
7,53200;0,45166;5455,50048;1,28330;0,00067;68,19376;0,06712;0,02302;0,08246;-0,00831
7,93200;0,47582;5647,79475;1,28364;0,00065;70,59743;0,06453;0,02213;0,08483;-0,00855
8,33200;0,49950;5829,73659;1,28395;0,00059;72,87171;0,05904;0,02025;0,08169;-0,00823
8,73200;0,52366;6011,50140;1,28385;0,00059;75,14377;0,05932;0,02035;0,06280;-0,00633
9,13200;0,54771;6190,87905;1,28409;0,00059;77,38599;0,05946;0,02039;0,03716;-0,00374
9,53200;0,57150;6358,46078;1,28352;0,00067;79,48076;0,06717;0,02304;0,04709;-0,00475
9,93200;0,59571;6532,97871;1,28414;0,00073;81,66223;0,07330;0,02514;0,05306;-0,00535
10,33200;0,61971;6708,42245;1,28391;0,00074;83,85528;0,07386;0,02533;0,07387;-0,00744
10,73200;0,64355;6878,94657;1,28415;0,00078;85,98683;0,07776;0,02667;0,06621;-0,00667
11,13200;0,66771;7056,13241;1,28439;0,00085;88,20166;0,08489;0,02911;0,07619;-0,00768
11,53200;0,69166;7233,50108;1,28414;0,00091;90,41876;0,09088;0,03117;0,08313;-0,00838
11,93200;0,71561;7408,96046;1,28439;0,00089;92,61201;0,08930;0,03063;0,08634;-0,00870
12,33200;0,73977;7592,95821;1,28466;0,00091;94,91198;0,09107;0,03124;0,10310;-0,01039
12,73200;0,76355;7776,10391;1,28469;0,00092;97,20130;0,09173;0,03146;0,11315;-0,01140
13,13200;0,78766;7959,40608;1,28470;0,00093;99,49258;0,09311;0,03194;0,12702;-0,01280
13,53200;0,81182;8148,71460;1,28451;0,00098;101,85893;0,09776;0,03353;0,11907;-0,01200
13,93200;0,83555;8337,02087;1,28389;0,00100;104,21276;0,10000;0,03430;0,12157;-0,01225
14,33200;0,85966;8525,87432;1,28448;0,00103;106,57343;0,10286;0,03528;0,11441;-0,01153
14,73200;0,88377;8719,27947;1,28507;0,00103;108,99099;0,10275;0,03524;0,06153;-0,00620
15,13200;0,90750;8910,67296;1,28501;0,00110;111,38341;0,11047;0,03789;0,05513;-0,00556
15,53200;0,93166;9105,39240;1,28492;0,00115;113,81740;0,11484;0,03939;0,06099;-0,00615
15,93200;0,95577;9310,89342;1,28531;0,00119;116,38617;0,11947;0,04098;0,07401;-0,00746
16,33200;0,97955;9522,00472;1,28513;0,00122;119,02506;0,12222;0,04192;0,07912;-0,00797
16,73200;1,00366;9739,22700;1,28557;0,00124;121,74034;0,12449;0,04270;0,10351;-0,01043
17,13200;1,02771;9957,36033;1,28561;0,00134;124,46700;0,13398;0,04595;0,09556;-0,00963
17,53200;1,05161;10170,24547;1,28574;0,00140;127,12807;0,14014;0,04807;0,09992;-0,01007
17,93200;1,07571;10389,85223;1,28569;0,00145;129,87315;0,14487;0,04969;0,08927;-0,00900
18,33200;1,09961;10609,18272;1,28564;0,00147;132,61478;0,14700;0,05042;0,08429;-0,00850
18,73200;1,12361;10825,03885;1,28603;0,00155;135,31299;0,15465;0,05304;0,09555;-0,00963
19,13200;1,14777;11048,07436;1,28644;0,00156;138,10093;0,15598;0,05350;0,10965;-0,01105
19,53200;1,17155;11270,59311;1,28641;0,00160;140,88241;0,15969;0,05477;0,11731;-0,01182
19,93200;1,19566;11491,84853;1,28660;0,00151;143,64811;0,15134;0,05191;0,12932;-0,01303
20,33200;1,21982;11717,12726;1,28616;0,00147;146,46409;0,14725;0,05051;0,14010;-0,01412
20,73200;1,24355;11941,79356;1,28637;0,00145;149,27242;0,14518;0,04979;0,15516;-0,01564
21,13200;1,26761;12165,76874;1,28652;0,00151;152,07211;0,15051;0,05162;0,09538;-0,00961
21,53200;1,29187;12395,78426;1,28657;0,00156;154,94730;0,15627;0,05360;0,08831;-0,00890
21,93200;1,31550;12620,37545;1,28647;0,00166;157,75469;0,16589;0,05690;0,08604;-0,00867
22,33200;1,33966;12849,11335;1,28656;0,00170;160,61392;0,16980;0,05824;0,09792;-0,00987
22,73200;1,36382;13081,70915;1,28684;0,00173;163,52136;0,17317;0,05940;0,11254;-0,01134
23,13200;1,38750;13308,94232;1,28691;0,00178;166,36178;0,17760;0,06092;0,11598;-0,01169
23,53200;1,41166;13544,22390;1,28691;0,00184;169,30280;0,18407;0,06313;0,12286;-0,01238
23,93200;1,43566;13779,67894;1,28695;0,00189;172,24599;0,18925;0,06491;0,12106;-0,01220
24,33200;1,45961;14012,67439;1,28680;0,00197;175,15843;0,19681;0,06750;0,12753;-0,01285
24,73200;1,48366;14251,49202;1,28713;0,00202;178,14365;0,20244;0,06944;0,14530;-0,01464
25,13200;1,50766;14492,60026;1,28715;0,00207;181,15750;0,20662;0,07087;0,14983;-0,01510
25,53200;1,53166;14725,77095;1,28725;0,00215;184,07214;0,21470;0,07364;0,14608;-0,01472
25,93200;1,55571;14967,53901;1,28727;0,00222;187,09424;0,22201;0,07615;0,14759;-0,01487
26,33200;1,57955;15208,48274;1,28727;0,00226;190,10603;0,22649;0,07768;0,14427;-0,01454
26,73200;1,60371;15446,68794;1,28748;0,00229;193,08360;0,22876;0,07846;0,15925;-0,01605
27,13200;1,62771;15686,70988;1,28813;0,00235;196,08387;0,23527;0,08070;0,13329;-0,01343
27,53200;1,65150;15930,43864;1,28816;0,00240;199,13048;0,23993;0,08229;0,07684;-0,00774
27,93200;1,67566;16169,92056;1,28807;0,00239;202,12401;0,23887;0,08193;0,09317;-0,00939
28,33200;1,69982;16416,11159;1,28810;0,00241;205,20139;0,24105;0,08268;0,10256;-0,01034
28,73200;1,72350;16658,71739;1,28805;0,00239;208,23397;0,23914;0,08202;0,11526;-0,01162
29,13200;1,74766;16902,28343;1,28804;0,00242;211,27854;0,24176;0,08292;0,12378;-0,01247
29,53200;1,77182;17147,49634;1,28808;0,00247;214,34370;0,24738;0,08485;0,13336;-0,01344
29,93200;1,79545;17390,85853;1,28827;0,00252;217,38573;0,25248;0,08660;0,14222;-0,01433
30,33200;1,81966;17638,90922;1,28832;0,00258;220,48637;0,25825;0,08858;0,14633;-0,01475
30,73200;1,84371;17884,95541;1,28814;0,00266;223,56194;0,26605;0,09125;0,15406;-0,01553
31,13200;1,86755;18128,31223;1,28838;0,00269;226,60390;0,26885;0,09221;0,15890;-0,01601
31,53200;1,89161;18377,62713;1,28850;0,00273;229,72034;0,27329;0,09374;0,16213;-0,01634
31,93200;1,91571;18626,13022;1,28854;0,00279;232,82663;0,27898;0,09569;0,17404;-0,01754
32,33200;1,93961;18868,70027;1,28810;0,00285;235,85875;0,28529;0,09785;0,18042;-0,01818
32,73200;1,96371;19118,95216;1,28842;0,00289;238,98690;0,28868;0,09901;0,18637;-0,01878
33,13200;1,98761;19366,35375;1,28837;0,00290;242,07942;0,29036;0,09959;0,20034;-0,02019
33,53200;2,01161;19607,50759;1,28859;0,00298;245,09384;0,29803;0,10222;0,20029;-0,02019
33,93200;2,03571;19856,23419;1,28834;0,00305;248,20293;0,30532;0,10472;0,18182;-0,01832
34,33200;2,05955;20101,34876;1,28842;0,00307;251,26686;0,30732;0,10541;0,13337;-0,01344
34,73200;2,08371;20341,42077;1,28841;0,00312;254,26776;0,31165;0,10689;0,13022;-0,01312
35,13200;2,10771;20581,10833;1,28802;0,00315;257,26385;0,31482;0,10798;0,13978;-0,01409
35,53200;2,13150;20819,19372;1,28845;0,00314;260,23992;0,31423;0,10778;0,14863;-0,01498
35,93200;2,15566;21048,19715;1,28829;0,00324;263,10246;0,32371;0,11103;0,15582;-0,01570
36,33200;2,17982;21275,83444;1,28869;0,00329;265,94793;0,32926;0,11293;0,16998;-0,01713
36,73200;2,20345;21493,51001;1,28864;0,00332;268,66888;0,33224;0,11396;0,17979;-0,01812
37,13200;2,22771;21706,23422;1,28871;0,00343;271,32793;0,34321;0,11772;0,18532;-0,01868
37,53200;2,25177;21911,70752;1,28889;0,00357;273,89634;0,35716;0,12250;0,18523;-0,01867
37,93200;2,27555;22102,33748;1,28885;0,00371;276,27922;0,37052;0,12709;0,19009;-0,01916
38,33200;2,29977;22290,70187;1,28879;0,00393;278,63377;0,39326;0,13489;0,19563;-0,01972
38,73200;2,32371;22465,18135;1,28887;0,00409;280,81477;0,40885;0,14023;0,20691;-0,02085
39,13200;2,34755;22625,50414;1,28883;0,00430;282,81880;0,43046;0,14764;0,20949;-0,02111
39,53200;2,37166;22783,55241;1,28872;0,00446;284,79441;0,44638;0,15310;0,21141;-0,02131
39,93200;2,39571;22930,39441;1,28844;0,00460;286,62993;0,45987;0,15773;0,17693;-0,01783
40,33200;2,41961;23058,71844;1,28888;0,00478;288,23398;0,47787;0,16390;0,16154;-0,01628
40,73200;2,44371;23186,65266;1,28899;0,00493;289,83316;0,49288;0,16905;0,16495;-0,01662
41,13200;2,46761;23300,48382;1,28920;0,00508;291,25605;0,50808;0,17427;0,18205;-0,01835
41,53200;2,49166;23402,20392;1,28871;0,00524;292,52755;0,52365;0,17961;0,19205;-0,01936
41,93200;2,51577;23500,54622;1,28949;0,00539;293,75683;0,53930;0,18498;0,20005;-0,02016
42,33200;2,53955;23586,01928;1,28949;0,00561;294,82524;0,56079;0,19235;0,23395;-0,02358
42,73200;2,56371;23663,70320;1,28868;0,00585;295,79629;0,58464;0,20053;0,23075;-0,02326
43,13200;2,58782;23737,16891;1,28932;0,00613;296,71461;0,61313;0,21030;0,22963;-0,02314
43,53200;2,61155;23801,79048;1,28957;0,00639;297,52238;0,63934;0,21929;0,24107;-0,02430
43,93200;2,63566;23861,70387;1,28943;0,00672;298,27130;0,67158;0,23035;0,25421;-0,02562
44,33200;2,65982;23919,01374;1,28953;0,00700;298,98767;0,70006;0,24012;0,26377;-0,02658
44,73200;2,68355;23966,07220;1,28960;0,00725;299,57590;0,72516;0,24872;0,27541;-0,02776
45,13200;2,70761;24013,68320;1,28916;0,00749;300,17104;0,74923;0,25698;0,29452;-0,02968
45,53200;2,73161;24057,87349;1,28953;0,00775;300,72342;0,77494;0,26580;0,27033;-0,02725
45,93200;2,75566;24093,97244;1,28930;0,00806;301,17466;0,80642;0,27660;0,24593;-0,02479
46,33200;2,77971;24133,13091;1,28955;0,00842;301,66414;0,84211;0,28883;0,26037;-0,02624
46,73200;2,80361;24167,13774;1,28956;0,00880;302,08922;0,87992;0,30180;0,26984;-0,02720
47,13200;2,82766;24195,12928;1,28958;0,00918;302,43912;0,91840;0,31500;0,27688;-0,02791
47,53200;2,85177;24227,36049;1,28935;0,00955;302,84201;0,95499;0,32755;0,29647;-0,02988
47,93200;2,87561;24256,27649;1,28901;0,00987;303,20346;0,98666;0,33841;0,30547;-0,03079
48,33200;2,89971;24279,11818;1,28943;0,01015;303,48898;1,01482;0,34807;0,34002;-0,03427
48,73200;2,92382;24305,78828;1,28938;0,01044;303,82235;1,04398;0,35808;0,34642;-0,03491
49,13200;2,94750;24327,73054;1,28950;0,01067;304,09663;1,06726;0,36606;0,36087;-0,03637
49,53200;2,97171;24349,74968;1,28929;0,01098;304,37187;1,09826;0,37669;0,37526;-0,03782
49,93200;2,99587;24372,13898;1,28919;0,01131;304,65174;1,13081;0,38786;0,38848;-0,03915
50,33200;3,01950;24389,73606;1,28935;0,01168;304,87170;1,16756;0,40046;0,40193;-0,04051
50,73200;3,04361;24409,08194;1,28915;0,01203;305,11352;1,20251;0,41245;0,38692;-0,03900
51,13200;3,06787;24430,00674;1,28926;0,01238;305,37508;1,23823;0,42470;0,39513;-0,03982
51,53200;3,09155;24444,24570;1,28925;0,01270;305,55307;1,27029;0,43570;0,38793;-0,03910
51,93200;3,11571;24463,47713;1,28928;0,01304;305,79346;1,30360;0,44712;0,36910;-0,03720
52,33200;3,13971;24481,68576;1,28917;0,01336;306,02107;1,33614;0,45828;0,37799;-0,03810
52,73200;3,16366;24493,55721;1,28894;0,01368;306,16947;1,36842;0,46936;0,39072;-0,03938
53,13200;3,18766;24513,27503;1,28912;0,01400;306,41594;1,40031;0,48029;0,40642;-0,04096
53,53200;3,21166;24529,94764;1,28888;0,01438;306,62435;1,43797;0,49321;0,42837;-0,04317
53,93200;3,23566;24539,93261;1,28886;0,01478;306,74916;1,47786;0,50689;0,45281;-0,04564
54,33200;3,25966;24556,87523;1,28922;0,01516;306,96094;1,51559;0,51984;0,46495;-0,04686
54,73200;3,28361;24573,54069;1,28892;0,01552;307,16926;1,55237;0,53245;0,49375;-0,04976
55,13200;3,30771;24584,81848;1,28908;0,01587;307,31023;1,58745;0,54448;0,49267;-0,04965
55,53200;3,33177;24601,44639;1,28929;0,01623;307,51808;1,62311;0,55671;0,52259;-0,05267
55,93200;3,35550;24614,93790;1,28910;0,01657;307,68672;1,65703;0,56835;0,51181;-0,05158
56,33200;3,37977;24628,07536;1,28925;0,01687;307,85094;1,68728;0,57872;0,50741;-0,05114
56,73200;3,40382;24642,89010;1,28914;0,01719;308,03613;1,71932;0,58971;0,51373;-0,05178
57,13200;3,42750;24654,10352;1,28888;0,01753;308,17629;1,75270;0,60116;0,50799;-0,05120
57,53200;3,45166;24667,82928;1,28894;0,01791;308,34787;1,79127;0,61439;0,49437;-0,04983
57,93200;3,47587;24682,33466;1,28941;0,01826;308,52918;1,82561;0,62617;0,50643;-0,05104
58,33200;3,49950;24693,12429;1,28908;0,01860;308,66405;1,85979;0,63789;0,52096;-0,05251
58,73200;3,52366;24708,40573;1,28919;0,01895;308,85507;1,89474;0,64988;0,53797;-0,05422
59,13200;3,54771;24721,77386;1,28917;0,01931;309,02217;1,93123;0,66239;0,57669;-0,05812
59,53200;3,57155;24731,59969;1,28896;0,01959;309,14500;1,95894;0,67190;0,59309;-0,05978
59,93200;3,59571;24748,92855;1,28906;0,01990;309,36161;1,98985;0,68250;0,60370;-0,06084
60,33200;3,61977;24760,49423;1,28893;0,02023;309,50618;2,02265;0,69375;0,62873;-0,06337
60,73200;3,64366;24768,73219;1,28920;0,02057;309,60915;2,05730;0,70563;0,62281;-0,06277
61,13200;3,66766;24785,39228;1,28913;0,02096;309,81740;2,09643;0,71906;0,62965;-0,06346
61,53200;3,69171;24799,77608;1,28896;0,02133;309,99720;2,13309;0,73163;0,62366;-0,06286
61,93200;3,71560;24806,59783;1,28904;0,02172;310,08247;2,17162;0,74485;0,63495;-0,06399
62,33200;3,73971;24823,17030;1,28896;0,02206;310,28963;2,20616;0,75669;0,62311;-0,06280
62,73200;3,76355;24836,28094;1,28901;0,02237;310,45351;2,23717;0,76733;0,61513;-0,06200
63,13200;3,78777;24847,42105;1,28913;0,02271;310,59276;2,27137;0,77906;0,61194;-0,06167
63,53200;3,81171;24861,69934;1,28899;0,02302;310,77124;2,30215;0,78962;0,62670;-0,06316
63,93200;3,83555;24873,72100;1,28894;0,02336;310,92151;2,33576;0,80114;0,64111;-0,06462
64,33200;3,85977;24885,11860;1,28878;0,02368;311,06398;2,36819;0,81227;0,65588;-0,06610
64,73200;3,88377;24897,94493;1,28894;0,02402;311,22431;2,40170;0,82376;0,70283;-0,07083
65,13200;3,90750;24909,55710;1,28869;0,02445;311,36946;2,44484;0,83856;0,72016;-0,07258
65,53200;3,93171;24922,64092;1,28895;0,02476;311,53301;2,47573;0,84915;0,73779;-0,07436
65,93200;3,95577;24936,57410;1,28897;0,02507;311,70718;2,50695;0,85986;0,72111;-0,07268
66,33200;3,97955;24945,46652;1,28870;0,02542;311,81833;2,54195;0,87186;0,72924;-0,07350
66,73200;4,00377;24962,47888;1,28863;0,02575;312,03099;2,57507;0,88323;0,73528;-0,07411
67,13200;4,02766;24972,76247;1,28876;0,02609;312,15953;2,60900;0,89486;0,73943;-0,07452
67,53200;4,05160;24982,60260;1,28873;0,02643;312,28253;2,64310;0,90656;0,74471;-0,07506
67,93200;4,07577;24998,99626;1,28879;0,02674;312,48745;2,67389;0,91712;0,74097;-0,07468
68,33200;4,09971;25011,36661;1,28885;0,02714;312,64208;2,71353;0,93072;0,72315;-0,07288
68,73200;4,12366;25019,12892;1,28883;0,02753;312,73911;2,75280;0,94419;0,74291;-0,07488
69,13200;4,14777;25034,45506;1,28891;0,02788;312,93069;2,78817;0,95632;0,76117;-0,07672
69,53200;4,17160;25047,88935;1,28883;0,02821;313,09862;2,82101;0,96758;0,77596;-0,07821
69,93200;4,19571;25056,67984;1,28892;0,02853;313,20850;2,85312;0,97859;0,79728;-0,08035
70,33200;4,21982;25072,78562;1,28877;0,02886;313,40982;2,88616;0,98993;0,83301;-0,08396
70,73200;4,24355;25082,41653;1,28879;0,02916;313,53021;2,91601;1,00017;0,82685;-0,08333
71,13200;4,26766;25093,97507;1,28861;0,02946;313,67469;2,94647;1,01061;0,82308;-0,08295
71,53200;4,29182;25109,44247;1,28864;0,02983;313,86803;2,98344;1,02329;0,84325;-0,08499
71,93200;4,31560;25118,38138;1,28866;0,03016;313,97977;3,01590;1,03443;0,84303;-0,08497
72,33200;4,33966;25129,24969;1,28869;0,03051;314,11562;3,05082;1,04640;0,84816;-0,08548
72,73200;4,36382;25144,94956;1,28854;0,03082;314,31187;3,08184;1,05704;0,85520;-0,08619
73,13200;4,38755;25153,46825;1,28862;0,03111;314,41835;3,11149;1,06721;0,85965;-0,08664
73,53200;4,41166;25168,09881;1,28867;0,03147;314,60124;3,14684;1,07934;0,85675;-0,08635
73,93200;4,43571;25181,04494;1,28852;0,03176;314,76306;3,17601;1,08934;0,84341;-0,08500
74,33200;4,45966;25188,54439;1,28827;0,03206;314,85680;3,20553;1,09947;0,86372;-0,08705
74,73200;4,48371;25203,57907;1,28827;0,03242;315,04474;3,24150;1,11181;0,88835;-0,08953
75,13200;4,50766;25215,60967;1,28852;0,03277;315,19512;3,27707;1,12401;0,91259;-0,09198
75,53200;4,53171;25224,55037;1,28814;0,03310;315,30688;3,30968;1,13519;0,92841;-0,09357
75,93200;4,55571;25237,33735;1,28851;0,03348;315,46672;3,34819;1,14840;0,92813;-0,09354
76,33200;4,57955;25250,48196;1,28824;0,03383;315,63102;3,38322;1,16042;0,93364;-0,09410
76,73200;4,60371;25259,82499;1,28822;0,03421;315,74781;3,42123;1,17345;0,94382;-0,09512
77,13200;4,62776;25272,87841;1,28838;0,03454;315,91098;3,45351;1,18452;0,93898;-0,09464
77,53200;4,65144;25284,55496;1,28844;0,03488;316,05694;3,48780;1,19629;0,94728;-0,09547
77,93200;4,67566;25295,38751;1,28830;0,03521;316,19234;3,52058;1,20753;0,96713;-0,09747
78,33200;4,69976;25307,65414;1,28820;0,03555;316,34568;3,55496;1,21932;0,97298;-0,09806
78,73200;4,72350;25317,58547;1,28817;0,03583;316,46982;3,58288;1,22890;0,97912;-0,09868
79,13200;4,74760;25329,43547;1,28825;0,03616;316,61794;3,61566;1,24014;0,99199;-0,09998
79,53200;4,77187;25342,69631;1,28809;0,03649;316,78370;3,64869;1,25147;0,97902;-0,09867
79,93200;4,79555;25350,73578;1,28843;0,03679;316,88420;3,67884;1,26181;0,99414;-0,10019
80,33200;4,81966;25364,78341;1,28823;0,03711;317,05979;3,71135;1,27296;1,01450;-0,10225
80,73200;4,84377;25377,44880;1,28834;0,03742;317,21811;3,74196;1,28346;1,00929;-0,10172
81,13200;4,86755;25383,16369;1,28807;0,03773;317,28955;3,77331;1,29421;1,02649;-0,10346
81,53200;4,89166;25397,56000;1,28826;0,03803;317,46950;3,80344;1,30455;1,02557;-0,10336
81,93200;4,91571;25411,17847;1,28816;0,03831;317,63973;3,83127;1,31409;1,03911;-0,10473
82,33200;4,93966;25417,24026;1,28840;0,03864;317,71550;3,86408;1,32535;1,04302;-0,10512
82,73200;4,96366;25429,69286;1,28828;0,03899;317,87116;3,89874;1,33723;1,05892;-0,10672
83,13200;4,98766;25443,00377;1,28819;0,03937;318,03755;3,93675;1,35027;1,07689;-0,10853
83,53200;5,01166;25449,49651;1,28823;0,03968;318,11871;3,96763;1,36086;1,08364;-0,10922
83,93200;5,03571;25462,69298;1,28796;0,04006;318,28366;4,00642;1,37417;1,10065;-0,11093
84,33200;5,05950;25474,45714;1,28826;0,04045;318,43071;4,04460;1,38726;1,10862;-0,11173
84,73200;5,08376;25483,88779;1,28799;0,04077;318,54860;4,07704;1,39839;1,09074;-0,10993
85,13200;5,10776;25495,36765;1,28810;0,04114;318,69210;4,11434;1,41118;1,10990;-0,11186
85,53200;5,13144;25504,96101;1,28820;0,04152;318,81201;4,15212;1,42414;1,11456;-0,11233
85,93200;5,15571;25515,56826;1,28780;0,04183;318,94460;4,18342;1,43487;1,10398;-0,11127
86,33200;5,17982;25526,77274;1,28827;0,04214;319,08466;4,21404;1,44538;1,11325;-0,11220
86,73200;5,20350;25536,16762;1,28796;0,04250;319,20210;4,25025;1,45780;1,13217;-0,11411
87,13200;5,22766;25546,57817;1,28811;0,04282;319,33223;4,28216;1,46874;1,14089;-0,11499
87,53200;5,25176;25558,04551;1,28821;0,04314;319,47557;4,31352;1,47950;1,15146;-0,11605
87,93200;5,27555;25566,60891;1,28843;0,04344;319,58261;4,34422;1,49003;1,16280;-0,11719
88,33200;5,29971;25579,08297;1,28824;0,04372;319,73854;4,37244;1,49971;1,18056;-0,11898
88,73200;5,32371;25589,11622;1,28831;0,04404;319,86395;4,40374;1,51044;1,19959;-0,12090
89,13200;5,34766;25595,54994;1,28821;0,04432;319,94437;4,43242;1,52028;1,21224;-0,12218
89,53200;5,37166;25608,78932;1,28792;0,04464;320,10987;4,46420;1,53118;1,21391;-0,12234
89,93200;5,39576;25619,41624;1,28812;0,04493;320,24270;4,49305;1,54108;1,22380;-0,12334
90,33200;5,41966;25624,36938;1,28830;0,04527;320,30462;4,52687;1,55267;1,21528;-0,12248
90,73200;5,44371;25637,40134;1,28812;0,04563;320,46752;4,56325;1,56516;1,20261;-0,12121
91,13200;5,46760;25647,31300;1,28824;0,04593;320,59141;4,59307;1,57538;1,19236;-0,12017
91,53200;5,49171;25655,01630;1,28823;0,04631;320,68770;4,63143;1,58854;1,20599;-0,12155
91,93200;5,51576;25668,22886;1,28823;0,04664;320,85286;4,66414;1,59976;1,20969;-0,12192
92,33200;5,53955;25676,46503;1,28798;0,04697;320,95581;4,69710;1,61106;1,24391;-0,12537
92,73200;5,56376;25685,26983;1,28833;0,04736;321,06587;4,73632;1,62452;1,25573;-0,12656
93,13200;5,58776;25695,34600;1,28829;0,04774;321,19182;4,77396;1,63743;1,26575;-0,12757
93,53200;5,61160;25704,37253;1,28820;0,04811;321,30466;4,81087;1,65008;1,28262;-0,12927
93,93200;5,63566;25712,80718;1,28828;0,04848;321,41009;4,84824;1,66290;1,30528;-0,13155
94,33200;5,65982;25723,75417;1,28823;0,04876;321,54693;4,87630;1,67253;1,31372;-0,13240
94,73200;5,68355;25730,75116;1,28825;0,04912;321,63439;4,91242;1,68491;1,32234;-0,13327
95,13200;5,70766;25742,33115;1,28849;0,04942;321,77914;4,94241;1,69520;1,32800;-0,13384
95,53200;5,73171;25752,62725;1,28849;0,04973;321,90784;4,97296;1,70568;1,31464;-0,13250
95,93200;5,75566;25756,67024;1,28844;0,05004;321,95838;5,00415;1,71638;1,28549;-0,12956
96,33200;5,77976;25769,01019;1,28859;0,05039;322,11263;5,03926;1,72842;1,29375;-0,13039
96,73200;5,80360;25777,28212;1,28855;0,05069;322,21603;5,06894;1,73860;1,30008;-0,13103
97,13200;5,82766;25784,06811;1,28842;0,05104;322,30085;5,10394;1,75061;1,31793;-0,13283
97,53200;5,85171;25794,77191;1,28865;0,05131;322,43465;5,13121;1,75996;1,34082;-0,13514
97,93200;5,87560;25804,84807;1,28851;0,05163;322,56060;5,16278;1,77079;1,36236;-0,13731
98,33200;5,89966;25810,75609;1,28860;0,05196;322,63445;5,19560;1,78204;1,36987;-0,13806
98,73200;5,92382;25820,52827;1,28865;0,05224;322,75660;5,22408;1,79181;1,38659;-0,13975
99,13200;5,94750;25828,65000;1,28849;0,05258;322,85812;5,25764;1,80332;1,40369;-0,14147
99,53200;5,97171;25836,82001;1,28844;0,05289;322,96025;5,28868;1,81397;1,41936;-0,14305
99,93200;5,99576;25846,30787;1,28854;0,05324;323,07885;5,32378;1,82601;1,42782;-0,14390
100,33200;6,01955;25852,40364;1,28839;0,05361;323,15505;5,36064;1,83865;1,43506;-0,14463
100,73200;6,04366;25861,27996;1,28869;0,05401;323,26600;5,40147;1,85266;1,41695;-0,14281
101,13200;6,06787;25871,17910;1,28850;0,05439;323,38974;5,43876;1,86545;1,41471;-0,14258
101,53200;6,09160;25877,29633;1,28868;0,05471;323,46620;5,47149;1,87667;1,38543;-0,13963
101,93200;6,11571;25886,67691;1,28869;0,05507;323,58346;5,50668;1,88874;1,40458;-0,14156
102,33200;6,13976;25896,78526;1,28863;0,05542;323,70982;5,54190;1,90082;1,41541;-0,14265
102,73200;6,16360;25897,36819;1,28846;0,05572;323,71710;5,57185;1,91109;1,42858;-0,14398
103,13200;6,18766;25910,45558;1,28859;0,05611;323,88069;5,61061;1,92439;1,46151;-0,14730
103,53200;6,21166;25920,25995;1,28860;0,05644;324,00325;5,64406;1,93586;1,47736;-0,14890
103,93200;6,23571;25923,28012;1,28855;0,05678;324,04100;5,67835;1,94762;1,49655;-0,15083
104,33200;6,25960;25932,55520;1,28873;0,05713;324,15694;5,71288;1,95947;1,51018;-0,15220
104,73200;6,28366;25942,44361;1,28850;0,05742;324,28055;5,74177;1,96938;1,51776;-0,15297
105,13200;6,30771;25946,12181;1,28855;0,05769;324,32652;5,76872;1,97862;1,52660;-0,15386
105,53201;6,33176;25956,61819;1,28848;0,05799;324,45773;5,79890;1,98897;1,51667;-0,15286
105,93201;6,35544;25963,74929;1,28829;0,05828;324,54687;5,82841;1,99909;1,51599;-0,15279
106,33201;6,37976;25969,28358;1,28855;0,05860;324,61604;5,86041;2,01007;1,51158;-0,15235
106,73201;6,40382;25978,47998;1,28863;0,05891;324,73100;5,89127;2,02065;1,49138;-0,15031
107,13201;6,42744;25983,60837;1,28864;0,05929;324,79510;5,92919;2,03366;1,50377;-0,15156
107,53201;6,45171;25991,86957;1,28824;0,05966;324,89837;5,96592;2,04626;1,52077;-0,15327
107,93201;6,47582;25998,84868;1,28850;0,05999;324,98561;5,99900;2,05760;1,53987;-0,15520
108,33201;6,49950;26003,40128;1,28840;0,06037;325,04252;6,03708;2,07066;1,54902;-0,15612
108,73201;6,52360;26013,32009;1,28815;0,06067;325,16650;6,06705;2,08095;1,57648;-0,15889
109,13201;6,54776;26020,60497;1,28850;0,06103;325,25756;6,10298;2,09327;1,59471;-0,16072
109,53201;6,57155;26023,20671;1,28821;0,06136;325,29008;6,13614;2,10464;1,61647;-0,16292
109,93201;6,59571;26034,25026;1,28853;0,06167;325,42813;6,16725;2,11531;1,62208;-0,16348
110,33201;6,61971;26040,31205;1,28840;0,06202;325,50390;6,20240;2,12737;1,61155;-0,16242
110,73201;6,64366;26042,69028;1,28815;0,06242;325,53363;6,24181;2,14088;1,61536;-0,16280
111,13201;6,66766;26052,99711;1,28797;0,06281;325,66246;6,28093;2,15430;1,62380;-0,16366
111,53201;6,69171;26060,54485;1,28833;0,06318;325,75681;6,31842;2,16716;1,62403;-0,16368
111,93201;6,71566;26062,80148;1,28844;0,06354;325,78502;6,35433;2,17948;1,62458;-0,16373
112,33201;6,73971;26071,32018;1,28846;0,06385;325,89150;6,38543;2,19014;1,60420;-0,16168
112,73201;6,76355;26079,13077;1,28789;0,06414;325,98913;6,41421;2,20002;1,61431;-0,16270
113,13201;6,78776;26082,67128;1,28850;0,06444;326,03339;6,44367;2,21012;1,64089;-0,16538
113,53201;6,81176;26091,00759;1,28838;0,06476;326,13759;6,47557;2,22106;1,65467;-0,16677
113,93201;6,83550;26095,70146;1,28841;0,06510;326,19627;6,50974;2,23278;1,67111;-0,16842
114,33201;6,85976;26101,87948;1,28817;0,06543;326,27349;6,54320;2,24426;1,71236;-0,17258
114,73201;6,88376;26108,74593;1,28810;0,06582;326,35932;6,58212;2,25761;1,71124;-0,17247
115,13201;6,90755;26113,87789;1,28838;0,06621;326,42347;6,62113;2,27099;1,72514;-0,17387
115,53201;6,93166;26118,46805;1,28793;0,06650;326,48085;6,65027;2,28099;1,71232;-0,17258
115,93201;6,95582;26126,03724;1,28825;0,06685;326,57547;6,68544;2,29305;1,72907;-0,17427
116,33201;6,97950;26128,52812;1,28824;0,06716;326,60660;6,71613;2,30357;1,72384;-0,17374
116,73201;7,00376;26138,53097;1,28827;0,06746;326,73164;6,74605;2,31383;1,72195;-0,17355
117,13201;7,02771;26143,18550;1,28840;0,06779;326,78982;6,77929;2,32524;1,73226;-0,17459
117,53201;7,05166;26145,13993;1,28834;0,06813;326,81425;6,81339;2,33693;1,73059;-0,17442
117,93201;7,07582;26155,37882;1,28812;0,06852;326,94224;6,85190;2,35014;1,72733;-0,17409
118,33201;7,09966;26159,09636;1,28835;0,06892;326,98870;6,89181;2,36383;1,75598;-0,17698
118,73201;7,12366;26162,21130;1,28838;0,06930;327,02764;6,93003;2,37694;1,76138;-0,17752
119,13201;7,14776;26169,77870;1,28845;0,06966;327,12223;6,96612;2,38932;1,78445;-0,17985
119,53201;7,17160;26175,29333;1,28826;0,07000;327,19117;7,00014;2,40099;1,81737;-0,18316
119,93201;7,19571;26178,20978;1,28829;0,07032;327,22762;7,03232;2,41202;1,82410;-0,18384
120,33201;7,21982;26186,44238;1,28836;0,07064;327,33053;7,06352;2,42272;1,80926;-0,18235
120,73201;7,24350;26189,28552;1,28834;0,07097;327,36607;7,09662;2,43408;1,81231;-0,18266
121,13201;7,26771;26193,44652;1,28843;0,07133;327,41808;7,13316;2,44661;1,81858;-0,18329
121,53201;7,29176;26201,11585;1,28795;0,07167;327,51395;7,16679;2,45815;1,82991;-0,18443
121,93201;7,31555;26202,94154;1,28819;0,07203;327,53677;7,20308;2,47059;1,84740;-0,18619
122,33201;7,33971;26208,43649;1,28835;0,07244;327,60546;7,24402;2,48463;1,85957;-0,18742
122,73201;7,36382;26213,69541;1,28827;0,07279;327,67119;7,27859;2,49649;1,86524;-0,18799
123,13201;7,38760;26216,73524;1,28840;0,07313;327,70919;7,31273;2,50820;1,84482;-0,18593
123,53201;7,41166;26223,24228;1,28820;0,07342;327,79053;7,34240;2,51838;1,86923;-0,18839
123,93201;7,43571;26230,52716;1,28847;0,07375;327,88159;7,37482;2,52950;1,88059;-0,18954
124,33201;7,45971;26230,04436;1,28830;0,07405;327,87555;7,40466;2,53973;1,89620;-0,19111
124,73201;7,48376;26237,08963;1,28824;0,07443;327,96362;7,44270;2,55278;1,91644;-0,19315
125,13201;7,50760;26240,91804;1,28837;0,07480;328,01148;7,48018;2,56564;1,93248;-0,19477
125,53201;7,53171;26242,69724;1,28828;0,07517;328,03372;7,51697;2,57826;1,91140;-0,19264
125,93201;7,55566;26247,69330;1,28843;0,07556;328,09617;7,55635;2,59176;1,92462;-0,19397
126,33201;7,57955;26252,88606;1,28827;0,07589;328,16108;7,58935;2,60308;1,94221;-0,19575
126,73201;7,60371;26256,02961;1,28844;0,07625;328,20037;7,62539;2,61544;1,94876;-0,19641
127,13201;7,62776;26261,24918;1,28819;0,07655;328,26561;7,65481;2,62553;1,96788;-0,19833
127,53201;7,65144;26264,61804;1,28824;0,07686;328,30773;7,68615;2,63628;1,97789;-0,19934
127,93201;7,67571;26268,68069;1,28842;0,07720;328,35851;7,72029;2,64799;1,99508;-0,20108
128,33201;7,69987;26274,53327;1,28814;0,07755;328,43167;7,75527;2,65999;2,00109;-0,20168
128,73201;7,72350;26273,84305;1,28833;0,07794;328,42304;7,79376;2,67319;1,98330;-0,19989
129,13201;7,74766;26279,72782;1,28821;0,07831;328,49660;7,83137;2,68609;1,99118;-0,20068
129,53201;7,77187;26283,86199;1,28852;0,07869;328,54827;7,86946;2,69915;2,00394;-0,20197
129,93201;7,79555;26285,90584;1,28845;0,07908;328,57382;7,90774;2,71228;2,02372;-0,20396
130,33201;7,81960;26292,56666;1,28830;0,07942;328,65708;7,94190;2,72400;2,03185;-0,20478
130,73201;7,84382;26296,45586;1,28857;0,07974;328,70570;7,97396;2,73500;2,03067;-0,20466
131,13201;7,86755;26293,96856;1,28853;0,08007;328,67461;8,00721;2,74640;2,05254;-0,20687
131,53201;7,89171;26301,55206;1,28844;0,08041;328,76940;8,04112;2,75803;2,05460;-0,20707
131,93201;7,91571;26305,50563;1,28812;0,08081;328,81882;8,08117;2,77177;2,06031;-0,20765
132,33201;7,93971;26304,22533;1,28855;0,08116;328,80282;8,11609;2,78375;2,07704;-0,20934
132,73201;7,96366;26310,15122;1,28861;0,08157;328,87689;8,15732;2,79789;2,09592;-0,21124
133,13201;7,98771;26316,45083;1,28828;0,08197;328,95564;8,19719;2,81156;2,10960;-0,21262
133,53201;8,01166;26314,67879;1,28839;0,08229;328,93348;8,22866;2,82236;2,11537;-0,21320
133,93201;8,03571;26319,99671;1,28859;0,08261;328,99996;8,26107;2,83347;2,12953;-0,21463
134,33201;8,05960;26324,74601;1,28858;0,08296;329,05933;8,29594;2,84543;2,10493;-0,21215
134,73201;8,08376;26323,79293;1,28873;0,08326;329,04741;8,32645;2,85590;2,11755;-0,21342
135,13201;8,10782;26329,77247;1,28837;0,08363;329,12216;8,36318;2,86850;2,12894;-0,21457
135,53201;8,13144;26331,65896;1,28833;0,08399;329,14574;8,39860;2,88065;2,12408;-0,21408
135,93201;8,15576;26334,73814;1,28818;0,08438;329,18423;8,43764;2,89404;2,15248;-0,21694
136,33201;8,17976;26337,13782;1,28846;0,08473;329,21422;8,47264;2,90604;2,15778;-0,21747
136,73201;8,20349;26338,65058;1,28877;0,08508;329,23313;8,50784;2,91811;2,17262;-0,21897
137,13201;8,22765;26342,81337;1,28867;0,08541;329,28517;8,54119;2,92955;2,18217;-0,21993
137,53201;8,25182;26346,65608;1,28892;0,08576;329,33320;8,57644;2,94164;2,19361;-0,22108
137,93201;8,27555;26346,39144;1,28873;0,08610;329,32989;8,61040;2,95329;2,21550;-0,22329
138,33201;8,29971;26351,37141;1,28876;0,08644;329,39214;8,64434;2,96493;2,22400;-0,22415
138,73201;8,32371;26354,59721;1,28856;0,08680;329,43247;8,67991;2,97713;2,23677;-0,22543
139,13201;8,34760;26351,52161;1,28869;0,08721;329,39402;8,72079;2,99115;2,24412;-0,22618
139,53201;8,37171;26358,09481;1,28874;0,08763;329,47619;8,76261;3,00550;2,24807;-0,22657
139,93201;8,39566;26360,58390;1,28867;0,08804;329,50730;8,80387;3,01965;2,23430;-0,22519
140,33201;8,41966;26358,56330;1,28865;0,08840;329,48204;8,84007;3,03206;2,23221;-0,22497
140,73201;8,44366;26363,47353;1,28844;0,08877;329,54342;8,87654;3,04457;2,24109;-0,22587
141,13201;8,46760;26367,28406;1,28867;0,08913;329,59105;8,91334;3,05720;2,26826;-0,22861
141,53201;8,49165;26366,01985;1,28865;0,08947;329,57525;8,94679;3,06867;2,27472;-0,22926
141,93201;8,51582;26371,23406;1,28873;0,08984;329,64043;8,98394;3,08141;2,28763;-0,23056
142,33201;8,53949;26371,73295;1,28861;0,09020;329,64666;9,01952;3,09362;2,30537;-0,23235
142,73201;8,56371;26372,02442;1,28867;0,09057;329,65031;9,05688;3,10643;2,31495;-0,23331
143,13201;8,58776;26375,59354;1,28850;0,09095;329,69492;9,09496;3,11949;2,33342;-0,23518
143,53201;8,61160;26376,29092;1,28856;0,09131;329,70364;9,13087;3,13181;2,34788;-0,23663
143,93201;8,63571;26378,18992;1,28853;0,09166;329,72737;9,16633;3,14397;2,35077;-0,23692
144,33201;8,65976;26381,06883;1,28841;0,09201;329,76336;9,20112;3,15590;2,35671;-0,23752
144,73201;8,68360;26381,20115;1,28841;0,09233;329,76501;9,23314;3,16689;2,36678;-0,23854
145,13201;8,70760;26383,61335;1,28854;0,09265;329,79517;9,26481;3,17775;2,36083;-0,23794
145,53201;8,73171;26388,54504;1,28867;0,09300;329,85681;9,30014;3,18986;2,33971;-0,23581
145,93201;8,75560;26383,94415;1,28861;0,09333;329,79930;9,33337;3,20126;2,34601;-0,23644
146,33201;8,77976;26389,51421;1,28848;0,09371;329,86893;9,37062;3,21404;2,36712;-0,23857
146,73201;8,80360;26390,38861;1,28846;0,09412;329,87986;9,41219;3,22830;2,38264;-0,24014
147,13201;8,82765;26389,01889;1,28842;0,09452;329,86274;9,45246;3,24211;2,41200;-0,24310
147,53201;8,85171;26393,03148;1,28852;0,09492;329,91289;9,49189;3,25563;2,41542;-0,24344
147,93201;8,87565;26395,43653;1,28850;0,09530;329,94296;9,52993;3,26868;2,43121;-0,24503
148,33201;8,89971;26394,22596;1,28843;0,09570;329,92782;9,57035;3,28254;2,44725;-0,24665
148,73201;8,92387;26396,84737;1,28822;0,09608;329,96059;9,60770;3,29536;2,46046;-0,24798
149,13201;8,94755;26397,62878;1,28825;0,09647;329,97036;9,64690;3,30880;2,46031;-0,24796
149,53201;8,97171;26397,79687;1,28841;0,09685;329,97246;9,68481;3,32180;2,47833;-0,24978
149,93201;8,99587;26401,40355;1,28852;0,09725;330,01754;9,72457;3,33544;2,48667;-0,25062
150,33201;9,01949;26399,47414;1,28844;0,09764;329,99343;9,76357;3,34882;2,47682;-0,24963
150,73201;9,04365;26401,26944;1,28843;0,09805;330,01587;9,80540;3,36316;2,48199;-0,25015
151,13201;9,06782;26401,85773;1,28836;0,09840;330,02322;9,84015;3,37509;2,45507;-0,24744
151,53201;9,09165;26402,53365;1,28856;0,09875;330,03167;9,87524;3,38712;2,47857;-0,24980
151,93201;9,11565;26403,74064;1,28825;0,09911;330,04676;9,91149;3,39955;2,49119;-0,25108
152,33201;9,13976;26408,20920;1,28841;0,09948;330,10262;9,94757;3,41193;2,51997;-0,25398
152,73201;9,16360;26403,00930;1,28837;0,09983;330,03762;9,98268;3,42397;2,53159;-0,25515
153,13201;9,18765;26406,34060;1,28817;0,10019;330,07926;10,01853;3,43627;2,55081;-0,25709
153,53201;9,21160;26408,84399;1,28830;0,10056;330,11055;10,05565;3,44900;2,55564;-0,25757
153,93201;9,23571;26404,49882;1,28800;0,10091;330,05624;10,09100;3,46112;2,57819;-0,25984
154,33201;9,25965;26406,90565;1,28815;0,10125;330,08632;10,12478;3,47271;2,57605;-0,25963
154,73201;9,28360;26408,84399;1,28802;0,10162;330,11055;10,16161;3,48534;2,59556;-0,26160
155,13201;9,30776;26408,62942;1,28801;0,10200;330,10787;10,20009;3,49854;2,60459;-0,26251
155,53201;9,33176;26409,38222;1,28814;0,10238;330,11728;10,23846;3,51170;2,59737;-0,26178
155,93201;9,35549;26411,51726;1,28812;0,10279;330,14397;10,27913;3,52565;2,60739;-0,26279
156,33201;9,37976;26408,97632;1,28808;0,10320;330,11220;10,32030;3,53977;2,60054;-0,26210
156,73201;9,40376;26410,70724;1,28796;0,10361;330,13384;10,36058;3,55359;2,59623;-0,26166
157,13201;9,42744;26409,77383;1,28778;0,10402;330,12217;10,40241;3,56793;2,60262;-0,26231
157,53201;9,45176;26410,45868;1,28765;0,10443;330,13073;10,44289;3,58182;2,62296;-0,26436
157,93201;9,47576;26409,52885;1,28797;0,10483;330,11911;10,48343;3,59572;2,64702;-0,26678
158,33201;9,49955;26409,08718;1,28788;0,10520;330,11359;10,52013;3,60831;2,66204;-0,26830
158,73201;9,52365;26410,36034;1,28776;0,10561;330,12950;10,56130;3,62243;2,67299;-0,26940
159,13201;9,54776;26412,22000;1,28789;0,10603;330,15275;10,60319;3,63680;2,68059;-0,27017
159,53201;9,57155;26408,40769;1,28768;0,10644;330,10510;10,64422;3,65087;2,70308;-0,27243
159,93201;9,59571;26411,60667;1,28790;0,10683;330,14508;10,68272;3,66408;2,71004;-0,27313
160,33201;9,61976;26412,53114;1,28790;0,10721;330,15664;10,72139;3,67734;2,72071;-0,27421
160,73201;9,64365;26406,42464;1,28747;0,10759;330,08031;10,75924;3,69032;2,70559;-0,27268
161,13201;9,66765;26410,81989;1,28735;0,10794;330,13525;10,79379;3,70217;2,72321;-0,27446
161,53201;9,69165;26410,41577;1,28772;0,10831;330,13020;10,83117;3,71500;2,72367;-0,27451
161,93201;9,71571;26407,27580;1,28776;0,10867;330,09095;10,86747;3,72745;2,74078;-0,27623
162,33201;9,73960;26407,89449;1,28785;0,10900;330,09868;10,90018;3,73866;2,74015;-0,27617
162,73201;9,76355;26409,74343;1,28778;0,10938;330,12179;10,93830;3,75174;2,73617;-0,27577
163,13201;9,78771;26406,61955;1,28788;0,10978;330,08274;10,97814;3,76540;2,74224;-0,27638
163,53201;9,81176;26408,17344;1,28782;0,11020;330,10217;11,02019;3,77983;2,75830;-0,27800
163,93201;9,83549;26407,13632;1,28781;0,11058;330,08920;11,05823;3,79287;2,77919;-0,28010
164,33201;9,85976;26405,72011;1,28773;0,11096;330,07150;11,09637;3,80596;2,79546;-0,28174
164,73201;9,88376;26405,98297;1,28777;0,11136;330,07479;11,13595;3,81953;2,79879;-0,28208
165,13201;9,90755;26404,33431;1,28765;0,11177;330,05418;11,17655;3,83346;2,81496;-0,28371
165,53201;9,93171;26404,01781;1,28763;0,11217;330,05022;11,21716;3,84739;2,82491;-0,28471
165,93201;9,95576;26403,78535;1,28778;0,11258;330,04732;11,25841;3,86153;2,81543;-0,28376
166,33201;9,97960;26401,87204;1,28744;0,11302;330,02340;11,30225;3,87657;2,83058;-0,28528
166,73201;10,00371;26403,13268;1,28757;0,11344;330,03916;11,34430;3,89099;2,84483;-0,28672
167,13201;10,02776;26402,63736;1,28768;0,11388;330,03297;11,38795;3,90597;2,84343;-0,28658
167,53201;10,05160;26397,00472;1,28753;0,11428;329,96256;11,42799;3,91970;2,87127;-0,28938
167,93201;10,07581;26400,12503;1,28747;0,11468;330,00156;11,46767;3,93331;2,87154;-0,28941
168,33201;10,09960;26397,98999;1,28767;0,11510;329,97487;11,50968;3,94772;2,86332;-0,28858
168,73201;10,12365;26394,18125;1,28755;0,11551;329,92727;11,55089;3,96185;2,86372;-0,28862
169,13201;10,14765;26395,27917;1,28755;0,11590;329,94099;11,58996;3,97525;2,87482;-0,28974
169,53201;10,17160;26394,62829;1,28756;0,11633;329,93285;11,63347;3,99018;2,89158;-0,29143
169,93201;10,19571;26391,98899;1,28752;0,11674;329,89986;11,67418;4,00414;2,91732;-0,29402
170,33201;10,21981;26392,64703;1,28758;0,11717;329,90809;11,71651;4,01866;2,92260;-0,29456
170,73201;10,24355;26390,00595;1,28766;0,11753;329,87507;11,75323;4,03125;2,93019;-0,29532
171,13201;10,26771;26386,69968;1,28769;0,11792;329,83375;11,79190;4,04452;2,95117;-0,29744
171,53201;10,29181;26388,93127;1,28771;0,11834;329,86164;11,83403;4,05897;2,93885;-0,29619
171,93201;10,31555;26384,89366;1,28777;0,11868;329,81117;11,86800;4,07062;2,95431;-0,29775
172,33201;10,33971;26383,01969;1,28766;0,11911;329,78775;11,91138;4,08550;2,95677;-0,29800
172,73201;10,36376;26384,10687;1,28789;0,11954;329,80134;11,95445;4,10027;2,95917;-0,29824
173,13201;10,38765;26379,31287;1,28779;0,12000;329,74141;12,00015;4,11594;2,97777;-0,30012
173,53201;10,41160;26378,41344;1,28779;0,12044;329,73017;12,04449;4,13115;2,99049;-0,30140
173,93201;10,43571;26379,40049;1,28800;0,12083;329,74251;12,08336;4,14448;3,01105;-0,30347
174,33201;10,45960;26372,59305;1,28803;0,12128;329,65741;12,12798;4,15979;3,01031;-0,30340
174,73201;10,48376;26373,55506;1,28798;0,12171;329,66944;12,17123;4,17462;3,01645;-0,30402
175,13201;10,50765;26372,34986;1,28707;0,12211;329,65437;12,21087;4,18822;2,99624;-0,30198
175,53201;10,53171;26366,30237;1,28791;0,12255;329,57878;12,25450;4,20319;3,00305;-0,30266
175,93201;10,55571;26367,24830;1,28748;0,12300;329,59060;12,30049;4,21896;3,02051;-0,30442
176,33201;10,57955;26364,58576;1,28795;0,12344;329,55732;12,34399;4,23388;3,03484;-0,30587
176,73201;10,60371;26360,76629;1,28815;0,12394;329,50958;12,39354;4,25087;3,05741;-0,30814
177,13201;10,62771;26359,05325;1,28774;0,12436;329,48817;12,43602;4,26544;3,06023;-0,30843
177,53201;10,65149;26357,19359;1,28796;0,12483;329,46492;12,48311;4,28160;3,05644;-0,30804
177,93201;10,67571;26354,10547;1,28799;0,12526;329,42632;12,52601;4,29631;3,07052;-0,30946
178,33201;10,69987;26352,21541;1,28786;0,12569;329,40269;12,56881;4,31099;3,07674;-0,31009
178,73201;10,72349;26348,05620;1,28802;0,12611;329,35070;12,61104;4,32548;3,08323;-0,31075
179,13201;10,74765;26344,32971;1,28810;0,12660;329,30412;12,65990;4,34223;3,08601;-0,31103
179,53201;10,77181;26341,85672;1,28808;0,12707;329,27321;12,70686;4,35834;3,09268;-0,31170
179,93201;10,79555;26336,85708;1,28827;0,12756;329,21071;12,75646;4,37535;3,11405;-0,31385
180,33201;10,81965;26336,32064;1,28814;0,12801;329,20401;12,80115;4,39068;3,11585;-0,31403
180,73201;10,84376;26332,02374;1,28809;0,12848;329,15030;12,84799;4,40674;3,12198;-0,31465
181,13201;10,86760;26324,93198;1,28781;0,12893;329,06165;12,89332;4,42229;3,13981;-0,31645
181,53201;10,89165;26323,66061;1,28831;0,12936;329,04576;12,93650;4,43710;3,14508;-0,31698
181,93201;10,91571;26322,20328;1,28821;0,12984;329,02754;12,98367;4,45328;3,14821;-0,31729
182,33201;10,93965;26311,29742;1,28808;0,13027;328,89122;13,02715;4,46820;3,14756;-0,31723
182,73201;10,96365;26310,66442;1,28811;0,13080;328,88331;13,07992;4,48630;3,12768;-0,31523
183,13201;10,98765;26307,90353;1,28822;0,13132;328,84879;13,13249;4,50433;3,13921;-0,31639
183,53201;11,01171;26298,23864;1,28826;0,13178;328,72798;13,17787;4,51989;3,14492;-0,31696
183,93201;11,03565;26294,99137;1,28818;0,13229;328,68739;13,22938;4,53756;3,15976;-0,31846
184,33201;11,05960;26292,43970;1,28836;0,13279;328,65550;13,27907;4,55460;3,17310;-0,31980
184,73201;11,08371;26282,39751;1,28848;0,13330;328,52997;13,32955;4,57192;3,17555;-0,32005
185,13201;11,10781;26278,29373;1,28830;0,13378;328,47867;13,37797;4,58852;3,17488;-0,31998
185,53201;11,13144;26271,51132;1,28814;0,13430;328,39389;13,42951;4,60620;3,19553;-0,32206
185,93201;11,15576;26263,69536;1,28827;0,13483;328,29619;13,48318;4,62461;3,19861;-0,32237
186,33201;11,17976;26256,94156;1,28784;0,13539;328,21177;13,53948;4,64392;3,20799;-0,32332
186,73201;11,20349;26250,08941;1,28799;0,13591;328,12612;13,59096;4,66158;3,19688;-0,32220
187,13201;11,22771;26243,45899;1,28815;0,13644;328,04324;13,64406;4,67979;3,20806;-0,32333
187,53201;11,25176;26234,16603;1,28842;0,13696;327,92708;13,69601;4,69761;3,21274;-0,32380
187,93201;11,27555;26223,57309;1,28826;0,13753;327,79466;13,75347;4,71732;3,22550;-0,32508
188,33201;11,29971;26216,94267;1,28811;0,13806;327,71178;13,80633;4,73545;3,22365;-0,32490
188,73201;11,32376;26208,00734;1,28811;0,13866;327,60009;13,86629;4,75602;3,22763;-0,32530
189,13201;11,34760;26191,13266;1,28847;0,13921;327,38916;13,92145;4,77493;3,24115;-0,32666
189,53201;11,37171;26184,06594;1,28830;0,13980;327,30082;13,97977;4,79494;3,22880;-0,32542
189,93201;11,39565;26173,47479;1,28839;0,14038;327,16843;14,03758;4,81477;3,23785;-0,32633
190,33201;11,41971;26157,78029;1,28812;0,14095;326,97225;14,09509;4,83449;3,24494;-0,32704
190,73201;11,44365;26146,77787;1,28831;0,14154;326,83472;14,15449;4,85486;3,24773;-0,32733
191,13201;11,46765;26134,55057;1,28832;0,14214;326,68188;14,21369;4,87517;3,25172;-0,32773
191,53201;11,49171;26117,87260;1,28831;0,14271;326,47341;14,27125;4,89491;3,25801;-0,32836
191,93201;11,51581;26104,84064;1,28826;0,14336;326,31051;14,33604;4,91713;3,25574;-0,32813
192,33201;11,53955;26088,77957;1,28840;0,14400;326,10974;14,40035;4,93919;3,25113;-0,32767
192,73201;11,56371;26069,83423;1,28840;0,14464;325,87293;14,46387;4,96098;3,25993;-0,32855
193,13201;11,58781;26055,16613;1,28778;0,14526;325,68958;14,52600;4,98229;3,25773;-0,32833
193,53201;11,61155;26034,87790;1,28825;0,14589;325,43597;14,58942;5,00404;3,26469;-0,32903
193,93201;11,63571;26016,03091;1,28799;0,14653;325,20039;14,65293;5,02582;3,27108;-0,32968
194,33201;11,65976;25997,24114;1,28826;0,14717;324,96551;14,71665;5,04768;3,26399;-0,32896
194,73201;11,68365;25973,87016;1,28812;0,14781;324,67338;14,78144;5,06990;3,26503;-0,32907
195,13201;11,70760;25952,06201;1,28787;0,14851;324,40078;14,85149;5,09393;3,26788;-0,32936
195,53201;11,73171;25931,15687;1,28843;0,14916;324,13946;14,91631;5,11616;3,26330;-0,32889
195,93201;11,75560;25902,07994;1,28847;0,14985;323,77600;14,98482;5,13966;3,27421;-0,32999
196,33201;11,77971;25878,98970;1,28809;0,15050;323,48737;15,04967;5,16190;3,27042;-0,32961
196,73201;11,80365;25853,32990;1,28819;0,15115;323,16662;15,11510;5,18435;3,27676;-0,33025
197,13201;11,82771;25821,59579;1,28838;0,15186;322,76995;15,18584;5,20861;3,27090;-0,32966
197,53201;11,85176;25796,03255;1,28828;0,15255;322,45041;15,25489;5,23229;3,27550;-0,33012
197,93201;11,87560;25765,45358;1,28838;0,15321;322,06817;15,32088;5,25493;3,27880;-0,33046
198,33201;11,89976;25733,10792;1,28834;0,15397;321,66385;15,39724;5,28112;3,27861;-0,33044
198,73201;11,92376;25698,13013;1,28847;0,15469;321,22663;15,46879;5,30566;3,27794;-0,33037
199,13201;11,94755;25663,52427;1,28787;0,15536;320,79405;15,53636;5,32883;3,28009;-0,33059
199,53201;11,97165;25623,92592;1,28802;0,15609;320,29907;15,60868;5,35364;3,28168;-0,33075
199,93201;11,99587;25588,67276;1,28824;0,15679;319,85841;15,67943;5,37791;3,28825;-0,33141
200,33201;12,01949;25544,01934;1,28837;0,15751;319,30024;15,75147;5,40262;3,28205;-0,33078
200,73201;12,04371;25500,09549;1,28832;0,15827;318,75119;15,82721;5,42859;3,27841;-0,33042
201,13201;12,06776;25452,78311;1,28816;0,15903;318,15979;15,90275;5,45450;3,28206;-0,33078
201,53201;12,09165;25396,70169;1,28796;0,15982;317,45877;15,98174;5,48159;3,28035;-0,33061
201,93201;12,11571;25334,61034;1,28800;0,16059;316,68263;16,05943;5,50824;3,28400;-0,33098
202,33201;12,13976;25254,93622;1,28794;0,16139;315,68670;16,13867;5,53542;3,27659;-0,33023
202,65601;12,15926;25038,29777;1,28832;0,16219;312,97872;16,21893;5,56295;3,28687;-0,33127
202,71401;12,16264;24630,81479;1,28822;0,16252;307,88518;16,26346;5,57427;3,27957;-0,33053
202,72201;12,16488;21852,86343;1,29399;0,16256;273,16079;16,26346;5,57556;3,27957;-0,33053
202,73001;12,16746;16589,98847;1,33610;0,16260;207,37486;16,26346;5,57703;3,27957;-0,33053
202,73401;12,16869;13765,73771;1,37491;0,16262;172,07172;16,26346;5,57773;3,27957;-0,33053