File: Data_Alu 6082 für NiGü/6082Alu_Zugprüfung.is_tens_RawData.csv/Specimen_RawData_5.csv
Prüflosbezeichnung;Redux 312_quer+längs_alte Proben;;;;;;;;
Proben-Nr;5;;;;Bmerkung;;;;
Prüfer;JuBr;;;;Falsche Probenbreite und Probendicke vorgegeben;;;;
Werkstoff;6082;;;;Spannungswerte daher nicht korrekt;;;;
Prüfnorm;DIN EN ISO 527                                                   ;;;;über Kraft/Fläche neu brechenen;;;;
Prüfgeschwindigkeit;3,6;mm/min;;;breite;16 mm;;;
Prüfklima;23 °C / 50 % rF;;;;dicke ;5 mm;;;
Bemerkungen;;;;;;;;;
;;;;;;;;;
Zeit;Traversenweg;Last;Dehnung 1;Zugdehnung;Zugspannung;Axiale Dehnung (Video);Zugverformung;Transversale Dehnung (Video);Transversale Verformung 1
(sec);(mm);(N);(%);(mm/mm);(MPa);(%);(mm);(%);(mm)
0;-0,00054;248,93476;1,26572;0,00001;3,1116845;0,00097;0,00032;-0,00558;0,00056
0,254;0,01452;508,83707;1,26577;0,00005;6,360463375;0,00459;0,00152;-0,00418;0,00042
0,548;0,03252;815,53711;1,26615;0,00005;10,19421388;0,00517;0,00171;-0,00273;0,00027
0,874;0,05202;1120,37368;1,26632;0,00006;14,004671;0,0061;0,00202;-0,01319;0,00132
1,214;0,07243;1422,06632;1,26663;0,0001;17,775829;0,00956;0,00317;-0,02139;0,00213
1,57;0,09386;1724,62318;1,26701;0,00009;21,55778975;0,00921;0,00305;-0,03398;0,00339
1,936;0,11566;2026,7795;1,26722;0,00008;25,33474375;0,00775;0,00257;-0,04109;0,0041
2,33;0,13918;2326,52374;1,26705;-0,00008;29,08154675;-0,0078;-0,00258;-0,03581;0,00357
2,728;0,16318;2613,50177;1,26715;0,00005;32,66877213;0,00534;0,00177;-0,03493;0,00348
3,128;0,18718;2889,41592;1,26732;0,00004;36,117699;0,00368;0,00122;-0,03505;0,00349
3,528;0,21112;3156,74745;1,26736;-0,00001;39,45934313;-0,00099;-0,00033;-0,04382;0,00437
3,928;0,23523;3428,96685;1,26731;-0,00002;42,86208563;-0,00188;-0,00062;-0,06084;0,00606
4,328;0,25912;3693,72994;1,26734;-0,00004;46,17162425;-0,00429;-0,00142;-0,06356;0,00634
4,728;0,28312;3948,95956;1,26758;-0,00004;49,3619945;-0,00418;-0,00138;-0,06759;0,00674
5,128;0,30729;4203,75109;1,26756;-0,00009;52,54688863;-0,0085;-0,00282;-0,05842;0,00582
5,528;0,33107;4451,03332;1,26792;-0,00005;55,6379165;-0,00502;-0,00166;0,01839;-0,00183
5,928;0,35518;4689,10754;1,26826;0,00001;58,61384425;0,00079;0,00026;0,09127;-0,0091
6,328;0,37934;4926,43163;1,26799;0,00026;61,58039538;0,02572;0,00852;0,08945;-0,00892
6,728;0,40302;5154,55842;1,26798;0,00022;64,43198025;0,02205;0,00731;0,10263;-0,01023
7,128;0,42718;5376,39409;1,26785;0,00028;67,20492613;0,02777;0,0092;0,08776;-0,00875
7,528;0,45134;5597,43449;1,26791;0,00037;69,96793113;0,03702;0,01227;0,06509;-0,00649
7,928;0,47502;5806,65886;1,26791;0,00036;72,58323575;0,03632;0,01204;0,04768;-0,00475
8,328;0,49918;6016,39062;1,2681;0,00031;75,20488275;0,03069;0,01017;0,04483;-0,00447
8,728;0,52329;6222,67753;1,26841;0,00032;77,78346913;0,03151;0,01044;0,02166;-0,00216
9,128;0,54707;6421,5222;1,2687;0,00026;80,2690275;0,02608;0,00864;0,00939;-0,00094
9,528;0,57118;6623,80189;1,26873;0,00026;82,79752363;0,02613;0,00866;-0,00932;0,00093
9,928;0,59523;6825,43606;1,26868;0,00029;85,31795075;0,02908;0,00963;-0,02764;0,00276
10,328;0,61912;7018,4876;1,26842;0,00031;87,731095;0,03146;0,01042;-0,04129;0,00412
10,728;0,64318;7214,37514;1,26846;0,00036;90,17968925;0,03574;0,01184;-0,04413;0,0044
11,128;0,66712;7404,08733;1,26839;0,00037;92,55109163;0,0365;0,0121;-0,02288;0,00228
11,528;0,69118;7586,32421;1,26872;0,00042;94,82905263;0,04159;0,01378;0,05248;-0,00523
11,928;0,71523;7774,37121;1,26892;0,00046;97,17964013;0,04584;0,01519;0,09276;-0,00925
12,328;0,73907;7961,66092;1,26905;0,0005;99,5207615;0,05013;0,01661;0,07892;-0,00787
12,728;0,76318;8147,2984;1,26929;0,00059;101,84123;0,05872;0,01946;0,0876;-0,00873
13,128;0,78729;8334,7401;1,26933;0,00061;104,1842513;0,06088;0,02017;0,07787;-0,00776
13,528;0,81102;8523,44871;1,26941;0,00061;106,5431089;0,06054;0,02006;0,07641;-0,00762
13,928;0,83518;8711,03168;1,2694;0,0006;108,887896;0,05951;0,01972;0,07497;-0,00747
14,328;0,85934;8903,75733;1,26935;0,00079;111,2969666;0,07869;0,02608;0,07236;-0,00721
14,728;0,88302;9094,57684;1,26951;0,0007;113,6822105;0,07015;0,02325;0,06256;-0,00624
15,128;0,90718;9287,62794;1,26967;0,00076;116,0953493;0,076;0,02518;0,05333;-0,00532
15,528;0,93134;9484,66212;1,27005;0,00072;118,5582765;0,07204;0,02387;0,02638;-0,00263
15,928;0,95502;9677,80352;1,27002;0,00066;120,972544;0,06623;0,02195;0,03212;-0,0032
16,328;0,97918;9878,43364;1,27006;0,0008;123,4804205;0,0802;0,02657;0,0275;-0,00274
16,728;1,00318;10078,59081;1,27049;0,00088;125,9823851;0,08759;0,02903;0,00641;-0,00064
17,128;1,02712;10275,20835;1,27046;0,00095;128,4401044;0,09491;0,03145;0,01506;-0,0015
17,528;1,05118;10483,88511;1,27034;0,00104;131,0485639;0,10449;0,03462;0,08726;-0,0087
17,928;1,07518;10707,34352;1,27032;0,0011;133,841794;0,10979;0,03638;0,13156;-0,01311
18,328;1,09912;10927,06025;1,27042;0,00116;136,5882531;0,11609;0,03847;0,13876;-0,01383
18,728;1,12323;11153,79721;1,27042;0,00119;139,4224651;0,11874;0,03935;0,11548;-0,01151
19,128;1,14707;11377,66778;1,27052;0,0012;142,2208473;0,11985;0,03971;0,11586;-0,01155
19,528;1,17118;11598,4869;1,27097;0,0012;144,9810863;0,11956;0,03962;0,10449;-0,01042
19,928;1,19528;11825,57702;1,27085;0,00119;147,8197128;0,11906;0,03945;0,09019;-0,00899
20,328;1,21907;12051,43869;1,27097;0,00121;150,6429836;0,12067;0,03999;0,07795;-0,00777
20,728;1,24318;12275,47824;1,27097;0,00123;153,443478;0,12257;0,04062;0,07712;-0,00769
21,128;1,26728;12504,75883;1,27072;0,00126;156,3094854;0,12572;0,04166;0,07231;-0,00721
21,528;1,29102;12732,55795;1,27083;0,00128;159,1569744;0,12825;0,0425;0,05533;-0,00551
21,928;1,31523;12961,29316;1,27073;0,00126;162,0161645;0,12598;0,04174;0,06211;-0,00619
22,328;1,33934;13193,66723;1,2713;0,00127;164,9208404;0,12679;0,04201;0,04941;-0,00493
22,728;1,36302;13420,95852;1,27122;0,00125;167,7619815;0,12457;0,04128;0,03798;-0,00379
23,128;1,38718;13652,63432;1,27139;0,00126;170,657929;0,12575;0,04167;0,03212;-0,0032
23,528;1,41123;13885,06204;1,27145;0,0013;173,5632755;0,13001;0,04308;0,0239;-0,00238
23,928;1,43512;14112,98722;1,27163;0,00135;176,4123403;0,13452;0,04458;0,08554;-0,00853
24,328;1,45918;14346,29381;1,27158;0,00168;179,3286726;0,16756;0,05553;0,09873;-0,00984
24,728;1,48323;14582,53562;1,27152;0,00172;182,2816953;0,17166;0,05688;0,1615;-0,0161
25,128;1,50712;14814,02993;1,27144;0,00177;185,1753741;0,17694;0,05863;0,16438;-0,01638
25,528;1,53128;15054,82793;1,27184;0,0018;188,1853491;0,18015;0,0597;0,16496;-0,01644
25,928;1,55512;15292,97054;1,27174;0,00189;191,1621318;0,18898;0,06262;0,1436;-0,01431
26,328;1,57918;15526,85022;1,27196;0,0019;194,0856278;0,19047;0,06311;0,14101;-0,01405
26,728;1,60328;15768,52083;1,27222;0,00196;197,1065104;0,19646;0,0651;0,13077;-0,01303
27,128;1,62707;16007,64334;1,27244;0,00193;200,0955418;0,19258;0,06382;0,11915;-0,01188
27,528;1,65118;16243,99424;1,2726;0,00207;203,049928;0,20706;0,06861;0,11228;-0,01119
27,928;1,67528;16486,68766;1,27251;0,00206;206,0835958;0,20561;0,06813;0,10076;-0,01004
28,328;1,69907;16727,14949;1,27222;0,00208;209,0893686;0,20801;0,06893;0,07374;-0,00735
28,728;1,72312;16966,71903;1,27243;0,00206;212,0839879;0,20563;0,06814;0,06204;-0,00618
29,128;1,74734;17211,31504;1,27238;0,00212;215,141438;0,21232;0,07035;0,0585;-0,00583
29,528;1,77107;17451,84839;1,27255;0,00216;218,1481049;0,21599;0,07157;0,03851;-0,00384
29,928;1,79518;17695,07825;1,27295;0,00223;221,1884781;0,22307;0,07392;0,03216;-0,00321
30,328;1,81923;17938,30991;1,27329;0,00227;224,2288739;0,22671;0,07512;0,08689;-0,00866
30,728;1,84312;18179,84819;1,27332;0,0023;227,2481024;0,22986;0,07617;0,08522;-0,00849
31,128;1,86707;18425,15767;1,27335;0,00238;230,3144709;0,23756;0,07872;0,15274;-0,01522
31,528;1,89123;18671,94057;1,27346;0,00234;233,3992571;0,23414;0,07759;0,15904;-0,01585
31,928;1,91518;18911,49402;1,27335;0,00238;236,3936753;0,23817;0,07892;0,14958;-0,01491
32,328;1,93918;19155,77888;1,27344;0,00242;239,447236;0,24158;0,08005;0,13463;-0,01342
32,728;1,96312;19399,94752;1,2735;0,00244;242,499344;0,24422;0,08093;0,12827;-0,01279
33,128;1,98718;19638,71419;1,27379;0,0025;245,4839274;0,24989;0,08281;0,12862;-0,01282
33,528;2,01123;19881,53815;1,27379;0,0026;248,5192269;0,25971;0,08606;0,1156;-0,01152
33,928;2,03507;20122,14839;1,27384;0,00265;251,5268549;0,26481;0,08775;0,11979;-0,01194
34,328;2,05918;20358,09338;1,27401;0,00272;254,4761673;0,27185;0,09008;0,12137;-0,0121
34,728;2,08328;20593,07098;1,2739;0,00273;257,4133873;0,27306;0,09048;0,12111;-0,01207
35,128;2,10702;20825,11961;1,274;0,00279;260,3139951;0,27924;0,09253;0,11174;-0,01114
35,528;2,13118;21051,98264;1,27398;0,00305;263,149783;0,3053;0,10117;0,11324;-0,01129
35,928;2,15534;21275,71642;1,27404;0,00302;265,9464553;0,30173;0,09998;0,10652;-0,01062
36,328;2,17902;21491,50372;1,27424;0,00298;268,6437965;0,29815;0,0988;0,09421;-0,00939
36,728;2,20318;21702,16084;1,27432;0,00299;271,2770105;0,29937;0,0992;0,13245;-0,0132
37,128;2,22728;21905,4848;1,27454;0,00319;273,81856;0,31894;0,10569;0,149;-0,01485
37,528;2,25112;22095,74461;1,27405;0,00333;276,1968076;0,33346;0,1105;0,15062;-0,01501
37,928;2,27518;22281,36599;1,27421;0,00347;278,5170749;0,34742;0,11512;0,2041;-0,02034
38,328;2,29918;22454,50437;1,27428;0,00362;280,6813046;0,36173;0,11987;0,22302;-0,02223
38,728;2,32318;22611,24909;1,2743;0,00374;282,6406136;0,37395;0,12392;0,18844;-0,01878
39,128;2,34712;22763,65221;1,27431;0,00387;284,5456526;0,38723;0,12831;0,1861;-0,01855
39,528;2,37118;22902,90177;1,27442;0,00403;286,2862721;0,4032;0,13361;0,17933;-0,01787
39,928;2,39523;23023,27573;1,2745;0,00426;287,7909466;0,42586;0,14112;0,16707;-0,01665
40,328;2,41923;23138,64112;1,27445;0,00453;289,233014;0,45343;0,15025;0,15089;-0,01504
40,728;2,44312;23240,92627;1,2746;0,00477;290,5115784;0,47746;0,15821;0,13305;-0,01326
41,128;2,46723;23329,83255;1,27479;0,00502;291,6229069;0,50175;0,16626;0,12948;-0,01291
41,528;2,49123;23410,91573;1,27495;0,00527;292,6364466;0,52704;0,17464;0,12398;-0,01236
41,928;2,51502;23483,59644;1,2748;0,00552;293,5449555;0,55221;0,18298;0,11027;-0,01099
42,328;2,53928;23548,77591;1,27452;0,00576;294,3596989;0,5764;0,191;0,1047;-0,01044
42,728;2,56328;23606,71878;1,27445;0,00605;295,0839848;0,6046;0,20035;0,1515;-0,0151
43,128;2,58702;23659,22391;1,27465;0,00627;295,7402989;0,62719;0,20783;0,14952;-0,0149
43,528;2,61123;23707,99541;1,27464;0,00647;296,3499426;0,64729;0,21449;0,17029;-0,01697
43,928;2,63534;23752,66314;1,27476;0,00674;296,9082893;0,6745;0,22351;0,17512;-0,01745
44,328;2,65902;23789,77954;1,27476;0,00705;297,3722443;0,70541;0,23375;0,2026;-0,02019
44,728;2,68318;23831,07662;1,27471;0,00736;297,8884578;0,7361;0,24392;0,22987;-0,02291
45,128;2,70723;23864,14111;1,27469;0,00766;298,3017639;0,76633;0,25394;0,22913;-0,02284
45,528;2,73112;23892,48312;1,27466;0,00796;298,656039;0,79643;0,26391;0,21413;-0,02134
45,928;2,75518;23926,22352;1,27461;0,00826;299,077794;0,82566;0,2736;0,2153;-0,02146
46,328;2,77923;23952,38757;1,27467;0,00857;299,4048446;0,85727;0,28407;0,21127;-0,02106
46,728;2,80318;23973,39821;1,27482;0,00888;299,6674776;0,88786;0,29421;0,20224;-0,02016
47,128;2,82718;24000,72634;1,27486;0,00911;300,0090793;0,91148;0,30203;0,19404;-0,01934
47,528;2,85118;24024,81079;1,2748;0,00944;300,3101349;0,94363;0,31269;0,19543;-0,01948
47,928;2,87518;24041,63182;1,27502;0,00978;300,5203978;0,97794;0,32406;0,22933;-0,02286
48,328;2,89923;24064,11588;1,27524;0,01014;300,8014485;1,01385;0,33596;0,23575;-0,0235
48,728;2,92302;24082,54981;1,27543;0,01054;301,0318726;1,05351;0,3491;0,22469;-0,0224
49,128;2,94728;24101,18043;1,27544;0,01096;301,2647554;1,09609;0,36321;0,23381;-0,0233
49,528;2,97123;24117,99967;1,2753;0,01129;301,4749959;1,12858;0,37397;0,22852;-0,02278
49,928;2,99507;24135,87213;1,27516;0,01169;301,6984016;1,169;0,38737;0,23005;-0,02293
50,328;3,01923;24150,8317;1,27502;0,01202;301,8853963;1,20218;0,39836;0,29731;-0,02963
50,728;3,04328;24167,02688;1,27517;0,01233;302,087836;1,23287;0,40853;0,29417;-0,02932
51,128;3,06707;24181,64134;1,27533;0,01262;302,2705168;1,26215;0,41824;0,29312;-0,02922
51,528;3,09123;24196,23792;1,27524;0,01292;302,452974;1,29205;0,42814;0,28782;-0,02869
51,928;3,11528;24211,74467;1,27539;0,01325;302,6468084;1,32549;0,43922;0,28186;-0,02809
52,328;3,13912;24222,0068;1,27519;0,0136;302,775085;1,36013;0,4507;0,28547;-0,02845
52,728;3,16323;24240,21721;1,27497;0,01398;303,0027151;1,398;0,46325;0,2762;-0,02753
53,128;3,18723;24252,57683;1,27542;0,01432;303,1572104;1,43207;0,47454;0,32705;-0,0326
53,528;3,21118;24262,79068;1,2751;0,01469;303,2848835;1,46925;0,48686;0,32322;-0,03222
53,928;3,23528;24279,00016;1,27534;0,01501;303,487502;1,50107;0,4974;0,31742;-0,03164
54,328;3,25918;24291,21494;1,27534;0,01532;303,6401868;1,53208;0,50768;0,31241;-0,03114
54,728;3,28312;24299,47615;1,27543;0,0156;303,7434519;1,55992;0,51691;0,30586;-0,03049
55,128;3,30728;24316,63513;1,27565;0,01588;303,9579391;1,58816;0,52627;0,30513;-0,03041
55,528;3,33107;24327,4945;1,27572;0,01624;304,0936813;1,62361;0,53801;0,32278;-0,03217
55,928;3,35523;24338,86707;1,27585;0,01662;304,2358384;1,66239;0,55086;0,32049;-0,03194
56,328;3,37928;24352,24771;1,27571;0,017;304,4030964;1,69961;0,56319;0,38106;-0,03798
56,728;3,40312;24363,57737;1,27575;0,01737;304,5447171;1,73704;0,5756;0,38214;-0,03809
57,128;3,42723;24375,08583;1,27574;0,01776;304,6885729;1,77616;0,58856;0,37746;-0,03762
57,528;3,45134;24388,80444;1,27544;0,01818;304,8600555;1,81781;0,60236;0,37964;-0,03784
57,928;3,47512;24397,28558;1,27549;0,01854;304,9660698;1,8542;0,61442;0,38647;-0,03852
58,328;3,49918;24409,38413;1,27544;0,01881;305,1173016;1,88129;0,6234;0,42379;-0,04224
58,728;3,52323;24424,14701;1,27555;0,01914;305,3018376;1,91431;0,63434;0,42933;-0,04279
59,128;3,54718;24432,07741;1,27597;0,01947;305,4009676;1,94735;0,64529;0,43106;-0,04296
59,528;3,57118;24447,22116;1,27582;0,01985;305,5902645;1,98499;0,65776;0,42789;-0,04265
59,928;3,59518;24458,74572;1,2757;0,02023;305,7343215;2,02304;0,67037;0,41948;-0,04181
60,328;3,61923;24466,92109;1,27553;0,02058;305,8365136;2,05808;0,68198;0,4136;-0,04122
60,728;3,64318;24481,10461;1,27566;0,02094;306,0138076;2,09416;0,69394;0,41577;-0,04144
61,128;3,66712;24493,52682;1,27557;0,02132;306,1690853;2,13201;0,70648;0,41966;-0,04183
61,528;3,69118;24501,07276;1,27556;0,02168;306,2634095;2,16813;0,71845;0,42751;-0,04261
61,928;3,71523;24515,08105;1,27615;0,02199;306,4385131;2,19899;0,72867;0,49891;-0,04973
62,328;3,73907;24527,27795;1,27583;0,02231;306,5909744;2,23067;0,73917;0,49709;-0,04955
62,728;3,76323;24537,57226;1,27586;0,02261;306,7196533;2,26096;0,74921;0,49009;-0,04885
63,128;3,78728;24549,45445;1,27578;0,02306;306,8681806;2,30567;0,76402;0,48772;-0,04861
63,528;3,81102;24561,36525;1,27562;0,02346;307,0170656;2,34555;0,77724;0,48487;-0,04833
63,928;3,83518;24572,44098;1,2755;0,02387;307,1555123;2,38736;0,79109;0,53793;-0,05362
64,328;3,85934;24584,13541;1,2755;0,02425;307,3016926;2,42509;0,8036;0,53177;-0,053
64,728;3,88302;24593,42122;1,27565;0,02439;307,4177653;2,43882;0,80815;0,54569;-0,05439
65,128;3,90723;24607,05042;1,27545;0,02477;307,5881303;2,47735;0,82091;0,53451;-0,05328
65,528;3,93139;24620,28801;1,27567;0,02507;307,7536001;2,50719;0,8308;0,52253;-0,05208
65,928;3,95501;24627,60687;1,27557;0,0254;307,8450859;2,54012;0,84171;0,51976;-0,05181
66,328;3,97918;24643,04388;1,27543;0,02568;308,0380485;2,56761;0,85082;0,51513;-0,05134
66,728;4,00323;24654,30558;1,27539;0,026;308,1788198;2,60014;0,8616;0,51152;-0,05098
67,128;4,02718;24661,19707;1,27535;0,02635;308,2649634;2,63511;0,87319;0,52865;-0,05269
67,528;4,05112;24676,5393;1,27524;0,02668;308,4567413;2,66845;0,88424;0,53222;-0,05305
67,928;4,07518;24689,28337;1,27533;0,02708;308,6160421;2,70772;0,89725;0,59403;-0,05921
68,328;4,09918;24696,1695;1,27538;0,02743;308,7021188;2,74324;0,90902;0,58802;-0,05861
68,728;4,12318;24708,71866;1,2753;0,02793;308,8589833;2,79285;0,92546;0,59177;-0,05898
69,128;4,14712;24723,19007;1,27533;0,02819;309,0398759;2,81859;0,93399;0,64542;-0,06433
69,528;4,17123;24730,38912;1,27558;0,02873;309,129864;2,87344;0,95216;0,65256;-0,06504
69,928;4,19523;24743,43538;1,27526;0,02908;309,2929423;2,90781;0,96355;0,64025;-0,06381
70,328;4,21907;24755,36942;1,27547;0,02937;309,4421178;2,93698;0,97322;0,65904;-0,06569
70,728;4,24328;24766,28959;1,27514;0,0297;309,5786199;2,96998;0,98415;0,6401;-0,0638
71,128;4,26723;24776,34966;1,27511;0,03004;309,7043708;3,00414;0,99547;0,63976;-0,06377
71,528;4,29102;24788,77902;1,27515;0,0304;309,8597378;3,04034;1,00747;0,62691;-0,06249
71,928;4,31523;24799,36481;1,27499;0,03074;309,9920601;3,0744;1,01875;0,62084;-0,06188
72,328;4,33934;24811,64396;1,27521;0,03109;310,1455495;3,10897;1,03021;0,62142;-0,06194
72,728;4,36296;24819,99636;1,27547;0,03145;310,2499545;3,14524;1,04223;0,61321;-0,06112
73,128;4,38718;24833,78649;1,27546;0,03179;310,4223311;3,17948;1,05358;0,63263;-0,06306
73,528;4,41128;24846,012;1,2753;0,03209;310,57515;3,20932;1,06346;0,64765;-0,06455
73,928;4,43512;24853,63483;1,27515;0,03243;310,6704354;3,24267;1,07451;0,6948;-0,06925
74,328;4,45918;24867,85769;1,27487;0,03274;310,8482211;3,27369;1,08479;0,75374;-0,07513
74,728;4,48318;24877,73359;1,2749;0,03311;310,9716699;3,31076;1,09708;0,75079;-0,07483
75,128;4,50718;24886,356;1,27492;0,03337;311,07945;3,33701;1,10578;0,76621;-0,07637
75,528;4,53118;24899,8028;1,2748;0,03373;311,247535;3,37347;1,11786;0,76183;-0,07593
75,928;4,55523;24912,82225;1,275;0,03407;311,4102781;3,40711;1,129;0,74977;-0,07473
76,328;4,57918;24917,90593;1,27502;0,03442;311,4738241;3,44177;1,14049;0,75094;-0,07485
76,728;4,60328;24931,55658;1,27512;0,03472;311,6444573;3,47208;1,15053;0,73124;-0,07288
77,128;4,62707;24943,11154;1,27494;0,03503;311,7888943;3,5034;1,16091;0,73086;-0,07285
77,528;4,65123;24951,91813;1,275;0,03534;311,8989766;3,53425;1,17114;0,71857;-0,07162
77,928;4,67534;24965,34348;1,27494;0,03563;312,0667935;3,56252;1,1805;0,70756;-0,07052
78,328;4,69907;24973,41871;1,27483;0,03596;312,1677339;3,59572;1,1915;0,72009;-0,07177
78,728;4,72323;24984,7126;1,27472;0,03629;312,3089075;3,62868;1,20243;0,718;-0,07156
79,128;4,74728;24996,2765;1,27465;0,03663;312,4534563;3,66278;1,21373;0,74561;-0,07432
79,528;4,77112;25005,73039;1,27471;0,037;312,5716299;3,69953;1,2259;0,8453;-0,08425
79,928;4,79518;25015,39707;1,27471;0,03733;312,6924634;3,73302;1,237;0,85312;-0,08503
80,328;4,81928;25028,13756;1,27457;0,03769;312,8517195;3,76949;1,24909;0,86993;-0,08671
80,728;4,84312;25035,01475;1,27469;0,03806;312,9376844;3,80597;1,26117;0,87025;-0,08674
81,128;4,86718;25048,00558;1,27464;0,03842;313,1000698;3,84232;1,27322;0,866;-0,08632
81,528;4,89118;25059,47471;1,27454;0,03876;313,2434339;3,87557;1,28424;0,85011;-0,08473
81,928;4,91523;25066,11764;1,27444;0,0391;313,3264705;3,90973;1,29556;0,85195;-0,08492
82,328;4,93923;25078,10354;1,27442;0,03943;313,4762943;3,94298;1,30657;0,83816;-0,08354
82,728;4,96318;25088,93073;1,27436;0,03973;313,6116341;3,97333;1,31663;0,84127;-0,08385
83,128;4,98712;25096,16017;1,27462;0,04005;313,7020021;4,00516;1,32718;0,8314;-0,08287
83,528;5,01128;25107,65076;1,27465;0,04038;313,8456345;4,03821;1,33813;0,82031;-0,08176
83,928;5,03512;25118,07024;1,27458;0,04074;313,975878;4,07407;1,35001;0,81023;-0,08076
84,328;5,05923;25126,92511;1,27447;0,04107;314,0865639;4,10723;1,361;0,83102;-0,08283
84,728;5,08334;25137,70401;1,27435;0,04139;314,2213001;4,13882;1,37147;0,82938;-0,08267
85,128;5,10701;25146,4355;1,27447;0,04167;314,3304438;4,16712;1,38085;0,9386;-0,09355
85,528;5,13118;25156,4312;1,27436;0,04201;314,45539;4,20104;1,39209;0,96497;-0,09618
85,928;5,15539;25168,05232;1,27442;0,04229;314,600654;4,22872;1,40126;0,97131;-0,09681
86,328;5,17907;25174,89374;1,27439;0,04263;314,6861718;4,26325;1,4127;0,96731;-0,09641
86,728;5,20318;25184,66234;1,27423;0,0429;314,8082793;4,29046;1,42172;0,97004;-0,09669
87,128;5,22734;25195,02103;1,27448;0,04318;314,9377629;4,31798;1,43084;0,96349;-0,09603
87,528;5,25112;25201,66218;1,27448;0,04352;315,0207773;4,3518;1,44204;0,95449;-0,09514
87,928;5,27518;25213,64272;1,27463;0,04386;315,170534;4,3861;1,45341;0,94495;-0,09418
88,328;5,29917;25224,18559;1,27478;0,04423;315,3023199;4,42306;1,46566;0,94489;-0,09418
88,728;5,32323;25229,9577;1,27469;0,04452;315,3744713;4,45227;1,47534;0,93445;-0,09314
89,128;5,34718;25241,31954;1,27479;0,04491;315,5164943;4,49107;1,48819;0,92218;-0,09192
89,528;5,37118;25250,96655;1,27467;0,04529;315,6370819;4,52915;1,50081;0,90976;-0,09068
89,928;5,39523;25257,19106;1,27469;0,04566;315,7148883;4,56566;1,51291;0,91754;-0,09145
90,328;5,41918;25266,45899;1,27468;0,04604;315,8307374;4,60432;1,52572;0,98154;-0,09783
90,728;5,44307;25277,30942;1,27465;0,04637;315,9663678;4,63722;1,53662;0,99971;-0,09964
91,128;5,46723;25284,37078;1,27476;0,04669;316,0546348;4,66868;1,54705;1,06963;-0,10661
91,528;5,49134;25294,6347;1,27463;0,04706;316,1829338;4,70593;1,55939;1,07742;-0,10739
91,928;5,51501;25303,24638;1,27497;0,04737;316,2905798;4,73703;1,5697;1,07268;-0,10692
92,328;5,53928;25312,19602;1,27484;0,04771;316,4024503;4,77106;1,58097;1,06853;-0,1065
92,728;5,56323;25319,54706;1,27494;0,04803;316,4943383;4,8028;1,59149;1,05758;-0,10541
93,128;5,58701;25327,94952;1,27494;0,04841;316,599369;4,84142;1,60429;1,05384;-0,10504
93,528;5,61117;25336,46286;1,27503;0,04875;316,7057858;4,87484;1,61536;1,03901;-0,10356
93,928;5,63534;25345,24083;1,27518;0,04904;316,8155104;4,90424;1,62511;1,03554;-0,10321
94,328;5,65901;25351,39203;1,27535;0,04935;316,8924004;4,93457;1,63515;1,02046;-0,10171
94,728;5,68312;25362,18524;1,27538;0,04963;317,0273155;4,9635;1,64474;1,01899;-0,10157
95,128;5,70723;25371,49072;1,27544;0,04992;317,143634;4,99167;1,65407;1,00408;-0,10008
95,528;5,73112;25374,40181;1,27528;0,05022;317,1800226;5,02245;1,66428;1,05292;-0,10495
95,928;5,75517;25387,66801;1,27523;0,05051;317,3458501;5,05081;1,67367;1,06738;-0,10639
96,328;5,77923;25395,18893;1,27524;0,05087;317,4398616;5,08668;1,68556;1,08995;-0,10864
96,728;5,80323;25399,14966;1,27536;0,05119;317,4893708;5,11925;1,69635;1,1143;-0,11106
97,128;5,82717;25410,13241;1,27531;0,05154;317,6266551;5,15441;1,708;1,16066;-0,11569
97,528;5,85117;25418,84959;1,27519;0,05191;317,7356199;5,19107;1,72015;1,16;-0,11562
97,928;5,87512;25422,31858;1,27525;0,05229;317,7789823;5,2289;1,73268;1,15576;-0,1152
98,328;5,89928;25432,81674;1,27535;0,05263;317,9102093;5,26274;1,7439;1,15012;-0,11464
98,728;5,92301;25440,11056;1,27548;0,05294;318,001382;5,29384;1,7542;1,15373;-0,11499
99,128;5,94734;25446,85364;1,27556;0,05326;318,0856705;5,32555;1,76471;1,13364;-0,11299
99,528;5,97123;25454,99861;1,27556;0,05367;318,1874826;5,36747;1,7786;1,13267;-0,1129
99,928;5,99507;25461,79175;1,27544;0,05399;318,2723969;5,39912;1,78909;1,12703;-0,11233
100,328;6,01934;25470,02971;1,27546;0,05435;318,3753714;5,43542;1,80112;1,12119;-0,11175
100,728;6,04328;25475,82328;1,27557;0,05475;318,447791;5,47534;1,81435;1,1485;-0,11447
101,128;6,06707;25482,73265;1,27572;0,05512;318,5341581;5,51179;1,82643;1,15943;-0,11556
101,528;6,09123;25490,50927;1,27596;0,05546;318,6313659;5,54639;1,83789;1,17357;-0,11697
101,928;6,11528;25500,0025;1,27591;0,05583;318,7500313;5,58252;1,84986;1,18837;-0,11845
102,328;6,13917;25503,61276;1,27593;0,05612;318,7951595;5,61171;1,85954;1,20149;-0,11975
102,728;6,16323;25513,80336;1,2759;0,05642;318,922542;5,64154;1,86942;1,26159;-0,12575
103,128;6,18717;25518,74042;1,27589;0,05668;318,9842553;5,66845;1,87834;1,25582;-0,12517
103,528;6,21123;25524,06371;1,27595;0,057;319,0507964;5,69985;1,88874;1,25075;-0,12466
103,928;6,23523;25532,9901;1,27582;0,0573;319,1623763;5,73034;1,89885;1,24749;-0,12434
104,328;6,25912;25539,19494;1,2758;0,05763;319,2399368;5,7633;1,90977;1,2422;-0,12381
104,728;6,28317;25543,52939;1,27585;0,05801;319,2941174;5,80119;1,92233;1,23487;-0,12308
105,128;6,30728;25552,00517;1,27592;0,05835;319,4000646;5,83521;1,9336;1,23542;-0,12314
105,52801;6,33107;25558,90203;1,27596;0,05873;319,4862754;5,87298;1,94611;1,22794;-0,12239
105,92801;6,35523;25563,11846;1,27591;0,05903;319,5389808;5,90336;1,95618;1,23672;-0,12327
106,32801;6,37933;25572,7905;1,27591;0,05935;319,6598813;5,93524;1,96674;1,27307;-0,12689
106,72801;6,40301;25575,33324;1,276;0,05962;319,6916655;5,96223;1,97569;1,26012;-0,1256
107,12801;6,42723;25583,74643;1,27597;0,05994;319,7968304;5,99359;1,98608;1,27039;-0,12662
107,52801;6,45133;25591,76981;1,27609;0,06027;319,8971226;6,02697;1,99714;1,28352;-0,12793
107,92801;6,47512;25594,84899;1,276;0,06066;319,9356124;6,06561;2,00994;1,29575;-0,12915
108,32801;6,49912;25599,87903;1,27607;0,06104;319,9984879;6,10382;2,02261;1,35656;-0,13521
108,72801;6,52328;25609,17914;1,27621;0,06144;320,1147393;6,14359;2,03578;1,35588;-0,13514
109,12801;6,54712;25611,37676;1,27608;0,06181;320,1422095;6,18089;2,04814;1,34888;-0,13445
109,52801;6,57112;25619,46452;1,27629;0,06217;320,2433065;6,21678;2,06004;1,34054;-0,13361
109,92801;6,59517;25626,03951;1,2763;0,06254;320,3254939;6,25403;2,07238;1,3296;-0,13252
110,32801;6,61923;25627,95103;1,27614;0,06286;320,3493879;6,28634;2,08309;1,33383;-0,13295
110,72801;6,64323;25636,39283;1,27599;0,06315;320,4549104;6,31521;2,09265;1,33066;-0,13263
111,12801;6,66712;25642,0058;1,27585;0,06348;320,5250725;6,34753;2,10336;1,3344;-0,133
111,52801;6,69123;25645,12074;1,2761;0,0638;320,5640093;6,38001;2,11413;1,35757;-0,13531
111,92801;6,71528;25651,03054;1,27615;0,06413;320,6378818;6,41271;2,12496;1,36188;-0,13574
112,32801;6,73907;25656,25012;1,27608;0,06447;320,7031265;6,44702;2,13633;1,36636;-0,13619
112,72801;6,76323;25662,66954;1,27592;0,06487;320,7833693;6,48706;2,1496;1,35492;-0,13505
113,12801;6,78733;25668,85114;1,27597;0,0652;320,8606393;6,51964;2,16039;1,36222;-0,13578
113,52801;6,81101;25672,66166;1,276;0,06554;320,9082708;6,55378;2,17171;1,38851;-0,1384
113,92801;6,83523;25677,57189;1,27567;0,06584;320,9696486;6,58384;2,18167;1,41583;-0,14112
114,32801;6,85928;25682,71816;1,27587;0,06617;321,033977;6,61681;2,19259;1,43556;-0,14309
114,72801;6,88307;25686,6771;1,2757;0,06643;321,0834638;6,64271;2,20118;1,43483;-0,14301
115,12801;6,90717;25692,43491;1,27571;0,0668;321,1554364;6,67976;2,21345;1,44444;-0,14397
115,52801;6,93139;25698,60041;1,27597;0,06715;321,2325051;6,71527;2,22522;1,42557;-0,14209
115,92801;6,95507;25699,24593;1,27584;0,06751;321,2405741;6,75063;2,23694;1,42424;-0,14196
116,32801;6,97917;25707,29256;1,27567;0,06787;321,341157;6,78726;2,24908;1,40561;-0,1401
116,72801;7,00328;25713,72271;1,27573;0,06821;321,4215339;6,82119;2,26032;1,45684;-0,14521
117,12801;7,02717;25713,41515;1,27575;0,06861;321,4176894;6,86089;2,27348;1,45932;-0,14545
117,52801;7,05117;25720,54803;1,27585;0,06892;321,5068504;6,89153;2,28363;1,46053;-0,14557
117,92801;7,07512;25724,20835;1,27579;0,06927;321,5526044;6,92699;2,29538;1,4662;-0,14614
118,32801;7,09923;25727,5933;1,27572;0,06957;321,5949163;6,95697;2,30531;1,45231;-0,14475
118,72801;7,12317;25733,34754;1,27582;0,0699;321,6668443;6,99031;2,31636;1,45995;-0,14552
119,12801;7,14717;25739,59172;1,2756;0,07026;321,7448965;7,02601;2,32819;1,47248;-0,14677
119,52801;7,17117;25739,08389;1,27581;0,07065;321,7385486;7,06518;2,34117;1,48839;-0,14835
119,92801;7,19528;25745,78762;1,27598;0,071;321,8223453;7,09976;2,35263;1,52922;-0,15242
120,32801;7,21901;25750,42427;1,27593;0,07144;321,8803034;7,14357;2,36714;1,53355;-0,15285
120,72801;7,24333;25754,62997;1,276;0,07174;321,9328746;7,17445;2,37738;1,52072;-0,15157
121,12801;7,26728;25758,58176;1,27557;0,07215;321,982272;7,21504;2,39083;1,51345;-0,15085
121,52801;7,29101;25760,93853;1,2758;0,07248;322,0117316;7,24775;2,40167;1,52791;-0,15229
121,92801;7,31523;25765,2086;1,27568;0,07278;322,0651075;7,27834;2,4118;1,5508;-0,15457
122,32801;7,33933;25769,04237;1,27584;0,0731;322,1130296;7,30965;2,42218;1,55686;-0,15518
122,72801;7,36307;25771,86227;1,27606;0,07346;322,1482784;7,34606;2,43424;1,55594;-0,15508
123,12801;7,38717;25776,20387;1,27609;0,07381;322,2025484;7,38127;2,44591;1,55521;-0,15501
123,52801;7,41128;25780,70462;1,2762;0,07416;322,2588078;7,4165;2,45758;1,54586;-0,15408
123,92801;7,43507;25781,29292;1,27602;0,07454;322,2661615;7,45421;2,47008;1,54193;-0,15369
124,32801;7,45923;25790,17997;1,2761;0,07489;322,3772496;7,48897;2,4816;1,55243;-0,15473
124,72801;7,48317;25791,05616;1,27584;0,07525;322,388202;7,52498;2,49353;1,55882;-0,15537
125,12801;7,50723;25791,58008;1,276;0,0756;322,394751;7,56012;2,50518;1,58222;-0,1577
125,52801;7,53117;25796,61906;1,27609;0,07591;322,4577383;7,59104;2,51542;1,62719;-0,16219
125,92801;7,55523;25801,81897;1,27602;0,0762;322,5227371;7,62019;2,52508;1,62114;-0,16158
126,32801;7,57917;25801,1198;1,27606;0,07654;322,5139975;7,65382;2,53623;1,61351;-0,16082
126,72801;7,60328;25806,76138;1,27603;0,07687;322,5845173;7,68721;2,54729;1,64073;-0,16354
127,12801;7,62712;25810,63807;1,27616;0,07724;322,6329759;7,72361;2,55935;1,64151;-0,16361
127,52801;7,65123;25811,02431;1,27626;0,07762;322,6378039;7,76229;2,57217;1,64931;-0,16439
127,92801;7,67533;25817,52777;1,27624;0,07799;322,7190971;7,79935;2,58445;1,6508;-0,16454
128,32801;7,69907;25817,58857;1,27613;0,07833;322,7198571;7,83305;2,59561;1,65505;-0,16496
128,72801;7,72323;25820,48178;1,27617;0,0787;322,7560223;7,87004;2,60787;1,65332;-0,16479
129,12801;7,74728;25823,06385;1,27605;0,07906;322,7882981;7,90555;2,61964;1,64195;-0,16366
129,52801;7,77112;25825,2883;1,27616;0,07941;322,8161038;7,94114;2,63143;1,64925;-0,16438
129,92801;7,79512;25827,66294;1,27601;0,07978;322,8457868;7,9782;2,64371;1,63749;-0,16321
130,32801;7,81928;25832,60536;1,27629;0,08012;322,907567;8,0122;2,65498;1,64362;-0,16382
130,72801;7,84312;25832,60357;1,27614;0,08052;322,9075446;8,05152;2,66801;1,70692;-0,17013
131,12801;7,86717;25836,23528;1,2762;0,0809;322,952941;8,08979;2,68069;1,71089;-0,17053
131,52801;7,89117;25840,3641;1,27616;0,08128;323,0045513;8,12815;2,6934;1,70237;-0,16968
131,92801;7,91517;25838,77623;1,27619;0,08163;322,9847029;8,16284;2,7049;1,74423;-0,17385
132,32801;7,93923;25844,59305;1,27623;0,08199;323,0574131;8,19858;2,71674;1,74438;-0,17387
132,72801;7,96317;25846,38119;1,27613;0,08235;323,0797649;8,2347;2,72871;1,74597;-0,17403
133,12801;7,98717;25847,09287;1,27628;0,08269;323,0886609;8,26936;2,7402;1,75033;-0,17446
133,52801;8,01128;25849,45679;1,27633;0,08302;323,1182099;8,30174;2,75092;1,74975;-0,1744
133,92801;8,03512;25853,95932;1,27642;0,08338;323,1744915;8,3376;2,76281;1,7433;-0,17376
134,32801;8,05917;25853,62494;1,27643;0,08371;323,1703118;8,37139;2,77401;1,74118;-0,17355
134,72801;8,08339;25857,36215;1,27624;0,0841;323,2170269;8,41047;2,78696;1,74218;-0,17365
135,12801;8,10696;25857,44262;1,27628;0,08443;323,2180328;8,44317;2,79779;1,72952;-0,17239
135,52801;8,13123;25860,17489;1,27612;0,08474;323,2521861;8,47399;2,808;1,7448;-0,17391
135,92801;8,15528;25863,22725;1,2763;0,0851;323,2903406;8,51028;2,82003;1,74339;-0,17377
136,32801;8,17912;25862,88214;1,27628;0,08542;323,2860268;8,54167;2,83043;1,78187;-0,1776
136,72801;8,20312;25864,07661;1,27629;0,08574;323,3009576;8,57422;2,84121;1,80408;-0,17982
137,12801;8,22733;25868,06595;1,27626;0,0861;323,3508244;8,60967;2,85296;1,85001;-0,18439
137,52801;8,25117;25867,62249;1,27619;0,08647;323,3452811;8,64723;2,86541;1,85182;-0,18457
137,92801;8,27517;25870,64087;1,2763;0,08681;323,3830109;8,68102;2,87661;1,84029;-0,18343
138,32801;8,29917;25874,50325;1,2761;0,08719;323,4312906;8,71947;2,88935;1,85188;-0,18458
138,72801;8,32323;25870,90015;1,27638;0,0876;323,3862519;8,75959;2,90264;1,83924;-0,18332
139,12801;8,34723;25875,78356;1,27628;0,08799;323,4472945;8,79928;2,91579;1,84272;-0,18367
139,52801;8,37112;25877,79522;1,27616;0,08838;323,4724403;8,83773;2,92853;1,84066;-0,18346
139,92801;8,39528;25875,89443;1,27637;0,08877;323,4486804;8,87712;2,94159;1,8387;-0,18327
140,32801;8,41917;25877,12288;1,2762;0,08914;323,464036;8,91398;2,9538;1,83983;-0,18338
140,72801;8,44312;25880,77068;1,27627;0,08953;323,5096335;8,95251;2,96657;1,83865;-0,18326
141,12801;8,46723;25879,81045;1,27642;0,08986;323,4976306;8,98618;2,97772;1,8399;-0,18339
141,52801;8,49133;25881,99556;1,27643;0,09023;323,5249445;9,02321;2,99;1,84115;-0,18351
141,92801;8,51501;25883,04698;1,2764;0,09059;323,5380873;9,05945;3,002;1,94819;-0,19418
142,32801;8,53928;25883,16858;1,2764;0,09096;323,5396073;9,09631;3,01422;1,94778;-0,19414
142,72801;8,56333;25885,70058;1,27623;0,09132;323,5712573;9,13235;3,02616;1,95541;-0,1949
143,12801;8,58701;25883,72111;1,27632;0,09168;323,5465139;9,16843;3,03812;1,94688;-0,19405
143,52801;8,61128;25886,81281;1,27634;0,09203;323,5851601;9,20301;3,04958;1,95332;-0,19469
143,92801;8,63528;25885,25355;1,2765;0,09239;323,5656694;9,23906;3,06152;1,94594;-0,19396
144,32801;8,65912;25886,22808;1,27651;0,09274;323,577851;9,27445;3,07325;1,94691;-0,19405
144,72801;8,68312;25888,38458;1,27646;0,09306;323,6048073;9,30617;3,08376;1,94357;-0,19372
145,12801;8,70728;25891,80887;1,27643;0,09341;323,6476109;9,34122;3,09537;1,94956;-0,19432
145,52801;8,73107;25887,04884;1,27637;0,09374;323,5881105;9,37408;3,10626;1,92569;-0,19194
145,92801;8,75523;25892,27557;1,27643;0,09407;323,6534446;9,40683;3,11711;1,93565;-0,19293
146,32801;8,77917;25892,1808;1,27619;0,09442;323,65226;9,44235;3,12889;1,93458;-0,19282
146,72801;8,80323;25888,70466;1,27647;0,09478;323,6088083;9,47824;3,14078;1,92993;-0,19236
147,12801;8,82717;25891,30819;1,27648;0,0952;323,6413524;9,5196;3,15448;1,98425;-0,19777
147,52801;8,85117;25893,84913;1,2764;0,09559;323,6731141;9,55909;3,16757;2,0374;-0,20307
147,92801;8,87523;25890,8236;1,27654;0,09596;323,635295;9,59557;3,17966;2,05422;-0,20475
148,32801;8,89923;25891,85357;1,27645;0,09632;323,6481696;9,63158;3,19159;2,04968;-0,2043
148,72801;8,92301;25892,44366;1,27625;0,09668;323,6555458;9,66788;3,20362;2,04969;-0,2043
149,12801;8,94728;25892,44008;1,27658;0,0971;323,655501;9,71005;3,21759;2,04791;-0,20412
149,52801;8,97128;25894,47498;1,2764;0,09746;323,6809373;9,7461;3,22954;2,04036;-0,20337
149,92801;8,99501;25892,83526;1,27648;0,09787;323,6604408;9,7866;3,24296;2,04605;-0,20393
150,32801;9,01933;25892,6779;1,27642;0,09825;323,6584738;9,82451;3,25552;2,03799;-0,20313
150,72801;9,04323;25893,00692;1,27653;0,09866;323,6625865;9,86641;3,2694;2,03992;-0,20332
151,12801;9,06712;25892,99798;1,27651;0,09901;323,6624748;9,90097;3,28086;2,02944;-0,20228
151,52801;9,09117;25891,67476;1,27638;0,09941;323,6459345;9,94075;3,29404;2,02264;-0,2016
151,92801;9,11528;25893,58091;1,27654;0,09979;323,6697614;9,97853;3,30656;2,07336;-0,20666
152,32801;9,13907;25890,30862;1,27652;0,10008;323,6288578;10,00769;3,31622;2,08059;-0,20738
152,72801;9,16323;25894,04762;1,2765;0,10043;323,6755953;10,04287;3,32788;2,09739;-0,20905
153,12801;9,18717;25892,84241;1,27672;0,10077;323,6605301;10,07745;3,33934;2,14803;-0,2141
153,52801;9,21117;25889,45746;1,27664;0,1011;323,6182183;10,10951;3,34996;2,14112;-0,21341
153,92801;9,23528;25893,21613;1,27647;0,10147;323,6652016;10,14691;3,36235;2,14335;-0,21363
154,32801;9,25912;25890,15841;1,27652;0,10188;323,6269801;10,18823;3,37604;2,14387;-0,21368
154,72801;9,28323;25888,42571;1,27669;0,10227;323,6053214;10,22654;3,38874;2,14159;-0,21346
155,12801;9,30723;25889,166;1,27656;0,10265;323,614575;10,26486;3,40144;2,13016;-0,21232
155,52801;9,33112;25889,51826;1,27669;0,10298;323,6189783;10,29753;3,41226;2,13526;-0,21283
155,92801;9,35517;25886,21914;1,27695;0,1033;323,5777393;10,3303;3,42312;2,1235;-0,21165
156,32801;9,37939;25889,61661;1,2766;0,10368;323,6202076;10,36782;3,43556;2,12133;-0,21144
156,72801;9,40301;25886,28173;1,27669;0,10403;323,5785216;10,40288;3,44717;2,15931;-0,21522
157,12801;9,42723;25886,29246;1,27665;0,10444;323,5786558;10,44436;3,46092;2,16425;-0,21572
157,52801;9,45128;25886,39081;1,27652;0,10483;323,5798851;10,48314;3,47377;2,17788;-0,21707
157,92801;9,47512;25882,79486;1,27665;0,10523;323,5349358;10,52347;3,48713;2,18719;-0,218
158,32801;9,49923;25882,63571;1,27668;0,10566;323,5329464;10,56616;3,50128;2,23632;-0,2229
158,72801;9,52328;25882,89857;1,27662;0,10607;323,5362321;10,60679;3,51474;2,22885;-0,22215
159,12801;9,54717;25880,70095;1,27655;0,1064;323,5087619;10,63964;3,52563;2,22548;-0,22182
159,52801;9,57112;25880,70989;1,27666;0,10675;323,5088736;10,67475;3,53726;2,22435;-0,22171
159,92801;9,59517;25880,71883;1,27656;0,10711;323,5089854;10,71088;3,54923;2,23274;-0,22254
160,32801;9,61917;25875,02539;1,27651;0,10747;323,4378174;10,7468;3,56114;2,21949;-0,22122
160,72801;9,64328;25878,45504;1,27663;0,10786;323,480688;10,78573;3,57404;2,21827;-0,2211
161,12801;9,66712;25876,92797;1,27669;0,10821;323,4615996;10,82111;3,58576;2,21716;-0,22099
161,52801;9,69128;25872,92075;1,27652;0,10861;323,4115094;10,86083;3,59892;2,25085;-0,22435
161,92801;9,71523;25872,63286;1,27665;0,10898;323,4079108;10,89764;3,61112;2,2484;-0,2241
162,32801;9,73907;25871,86933;1,27679;0,10937;323,3983666;10,93728;3,62426;2,24529;-0,22379
162,72801;9,76323;25868,40212;1,27683;0,10974;323,3550265;10,97354;3,63627;2,26198;-0,22546
163,12801;9,78733;25868,40749;1,27692;0,11005;323,3550936;11,00482;3,64664;2,32839;-0,23208
163,52801;9,81101;25867,04493;1,27693;0,11039;323,3380616;11,03852;3,6578;2,31927;-0,23117
163,92801;9,83523;25864,99929;1,27678;0,11074;323,3124911;11,07383;3,6695;2,30957;-0,2302
164,32801;9,85939;25864,26258;1,27663;0,11111;323,3032823;11,11143;3,68196;2,31876;-0,23112
164,72801;9,88301;25859,5258;1,27682;0,11147;323,2440725;11,14669;3,69365;2,30562;-0,22981
165,12801;9,90723;25860,8222;1,2767;0,11187;323,2602775;11,18738;3,70713;2,30797;-0,23004
165,52801;9,93133;25858,73544;1,27697;0,11225;323,234193;11,22498;3,71959;2,28722;-0,22797
165,92801;9,95512;25853,46043;1,27686;0,11263;323,1682554;11,26335;3,7323;2,32381;-0,23162
166,32801;9,97912;25855,02326;1,27701;0,11296;323,1877908;11,29629;3,74322;2,33829;-0,23306
166,72801;10,00323;25853,77157;1,27686;0,11328;323,1721446;11,32837;3,75385;2,33022;-0,23226
167,12801;10,02712;25847,29135;1,27712;0,11367;323,0911419;11,36702;3,76666;2,3329;-0,23253
167,52801;10,05117;25848,28198;1,27684;0,11403;323,1035248;11,40312;3,77862;2,33111;-0,23235
167,92801;10,07512;25846,65477;1,27683;0,11445;323,0831846;11,44511;3,79253;2,36712;-0,23594
168,32801;10,09923;25839,0981;1,27696;0,11484;322,9887263;11,48385;3,80537;2,39017;-0,23823
168,72801;10,12323;25840,63232;1,27699;0,11521;323,007904;11,52146;3,81783;2,39196;-0,23841
169,12801;10,14712;25839,74183;1,27686;0,11561;322,9967729;11,56101;3,83094;2,38262;-0,23748
169,52801;10,17123;25833,3385;1,27693;0,11596;322,9167313;11,59581;3,84247;2,37428;-0,23665
169,92801;10,19523;25831,56645;1,27699;0,11626;322,8945806;11,62636;3,85259;2,35868;-0,2351
170,32801;10,21906;25830,19495;1,27684;0,1166;322,8774369;11,66028;3,86383;2,41051;-0,24026
170,72801;10,24328;25826,599;1,27683;0,11693;322,8324875;11,69261;3,87455;2,40047;-0,23926
171,12801;10,26733;25824,84484;1,27704;0,11734;322,8105605;11,73357;3,88812;2,40077;-0,23929
171,52801;10,29101;25820,52648;1,27709;0,11772;322,756581;11,77183;3,9008;2,40066;-0,23928
171,92801;10,31528;25817,58857;1,27689;0,11804;322,7198571;11,80382;3,9114;2,39251;-0,23847
172,32801;10,33933;25816,34045;1,27714;0,11836;322,7042556;11,83639;3,92219;2,4053;-0,23974
172,72801;10,36306;25809,9103;1,2771;0,11874;322,6238788;11,87353;3,9345;2,44325;-0,24352
173,12801;10,38717;25809,28802;1,27698;0,11897;322,6161003;11,89698;3,94227;2,44667;-0,24386
173,52801;10,41128;25806,24461;1,27717;0,11924;322,5780576;11,92371;3,95113;2,44247;-0,24345
173,92801;10,43506;25799,97182;1,27719;0,1196;322,4996478;11,96012;3,96319;2,4215;-0,24136
174,32801;10,45917;25799,64995;1,27706;0,11996;322,4956244;11,99618;3,97514;2,45898;-0,24509
174,72801;10,48323;25796,46885;1,27689;0,12035;322,4558606;12,03458;3,98786;2,45798;-0,24499
175,12801;10,50717;25787,41372;1,2767;0,12071;322,3426715;12,07122;4,00001;2,45835;-0,24503
175,52801;10,53122;25787,49597;1,27696;0,12107;322,3436996;12,10705;4,01188;2,46163;-0,24536
175,92801;10,55512;25782,21738;1,27672;0,12143;322,2777173;12,14294;4,02377;2,44249;-0,24345
176,32801;10,57917;25775,78723;1,27705;0,12171;322,1973404;12,17108;4,0331;2,44363;-0,24356
176,72801;10,60328;25774,88959;1,27711;0,12197;322,1861199;12,19667;4,04158;2,50409;-0,24959
177,12801;10,62712;25770,51759;1,27698;0,1223;322,1314699;12,22966;4,05251;2,48664;-0,24785
177,52801;10,65117;25763,24344;1,27697;0,12264;322,040543;12,26438;4,06401;2,48894;-0,24808
177,92801;10,67533;25760,80978;1,27699;0,12291;322,0101223;12,29127;4,07292;2,47158;-0,24635
178,32801;10,69906;25753,93438;1,27702;0,12322;321,9241798;12,32239;4,08324;2,50611;-0,24979
178,72801;10,72323;25747,2235;1,27683;0,12346;321,8402938;12,3456;4,09093;2,50391;-0,24957
179,12801;10,74728;25743,74557;1,27698;0,12367;321,7968196;12,36723;4,0981;2,48557;-0,24774
179,52801;10,77106;25735,08918;1,27673;0,12389;321,6886148;12,38928;4,1054;2,48648;-0,24783
179,92801;10,79517;25729,4333;1,27698;0,12413;321,6179163;12,41303;4,11327;2,46406;-0,2456
180,32801;10,81928;25724,75374;1,27695;0,12442;321,5594218;12,44202;4,12288;2,47713;-0,2469
180,72801;10,84317;25716,60161;1,27705;0,12476;321,4575201;12,47633;4,13425;2,5321;-0,25238
181,12801;10,86717;25710,27517;1,27691;0,12504;321,3784396;12,50351;4,14325;2,51896;-0,25107
181,52801;10,89122;25703,32646;1,27696;0,12537;321,2915808;12,53676;4,15427;2,50416;-0,2496
181,92801;10,91517;25692,98029;1,27711;0,12557;321,1622536;12,55678;4,1609;2,5436;-0,25353
182,32801;10,93928;25687,26182;1,27705;0,12585;321,0907728;12,58491;4,17023;2,53332;-0,2525
182,72801;10,96312;25677,76859;1,27688;0,12603;320,9721074;12,60306;4,17624;2,5262;-0,25179
183,12801;10,98717;25667,08267;1,27702;0,12616;320,8385334;12,61577;4,18045;2,52899;-0,25207
183,52801;11,01128;25659,4187;1,27699;0,12633;320,7427338;12,63281;4,1861;2,5118;-0,25036
183,92801;11,03512;25650,1919;1,27715;0,12647;320,6273988;12,6473;4,1909;2,50196;-0,24938
184,32801;11,05917;25636,61098;1,27717;0,12667;320,4576373;12,66658;4,19729;2,54926;-0,25409
184,72801;11,08339;25626,47045;1,27723;0,12688;320,3308806;12,68795;4,20437;2,536;-0,25277
185,12801;11,10701;25614,8994;1,27711;0,12705;320,1862425;12,70473;4,20993;2,52975;-0,25215
185,52801;11,13122;25602,06592;1,27693;0,1273;320,025824;12,72967;4,2182;2,55988;-0,25515
185,92801;11,15539;25590,91866;1,27695;0,12739;319,8864833;12,7389;4,22125;2,56199;-0,25536
186,32801;11,17901;25573,34125;1,27686;0,12755;319,6667656;12,75485;4,22654;2,5389;-0,25306
186,72801;11,20317;25559,93736;1,27697;0,12771;319,499217;12,77114;4,23194;2,52037;-0,25121
187,12801;11,22728;25546,0149;1,27733;0,12781;319,3251863;12,78064;4,23508;2,51375;-0,25055
187,52801;11,25117;25528,13351;1,2771;0,12793;319,1016689;12,79321;4,23925;2,52178;-0,25135
187,92801;11,27512;25511,9276;1,27699;0,12799;318,899095;12,79917;4,24122;2,55837;-0,255
188,32801;11,29923;25495,90051;1,27689;0,12807;318,6987564;12,80667;4,24371;2,53865;-0,25303
188,72801;11,32317;25471,41194;1,27705;0,12821;318,3926493;12,82076;4,24838;2,57088;-0,25625
189,12801;11,34722;25454,29587;1,27705;0,1283;318,1786984;12,82988;4,2514;2,56292;-0,25545
189,52801;11,37112;25434,2097;1,27699;0,12839;317,9276213;12,83881;4,25436;2,54169;-0,25334
189,92801;11,39528;25409,43325;1,27693;0,12852;317,6179156;12,85236;4,25885;2,52686;-0,25186
190,32801;11,41917;25386,70242;1,27703;0,12861;317,3337803;12,86073;4,26162;2,50898;-0,25008
190,72801;11,44306;25363,45124;1,27696;0,12864;317,0431405;12,86444;4,26285;2,52307;-0,25148
191,12801;11,46728;25335,01089;1,27713;0,12862;316,6876361;12,86214;4,26209;2,54085;-0,25325
191,52801;11,49128;25298,00177;1,27707;0,12868;316,2250221;12,86798;4,26403;2,56778;-0,25594
191,92801;11,51506;25231,87816;1,27718;0,12866;315,398477;12,86617;4,26343;2,5715;-0,25631
192,32801;11,53928;25133,72004;1,27719;0,12872;314,1715005;12,87186;4,26531;2,55387;-0,25455
192,72801;11,56333;25015,53476;1,27676;0,12878;312,6941845;12,87809;4,26738;2,53379;-0,25255
193,08801;11,58487;24731,5675;1,27668;0,12885;309,1445938;12,88526;4,26975;2,53213;-0,25238
193,34401;11,60024;24427,194;1,27668;0,12886;305,339925;12,88553;4,26984;2,58114;-0,25727
193,45001;11,60662;23971,76743;1,27675;0,12849;299,6470929;12,8487;4,25764;2,5706;-0,25622
193,45801;11,60892;20990,32938;1,28294;0,12796;262,3791173;12,79602;4,24018;2,54529;-0,25369
193,46601;11,61139;15778,76151;1,32429;0,12741;197,2345189;12,74106;4,22197;2,51924;-0,2511
193,46801;11,61197;14396,89726;1,34225;0,12703;179,9612158;12,7032;4,20942;2,50444;-0,24962